Workbook

Sheet Notes on Changes
B2: S/N | C2: Item | D2: Previously | E2: Updated | F2: Adjustment | G2: Notes/Remarks | I2: Rational
B3: 1 | C3: 13th Month | D3: 12263000 | E3: 9396240 | F3: =E3/D3-1 -> -0.23377314 | G3: Now 10% of Annual Basic Salary vs. 1 month Gross Pay. | I3: We benchmarked practices among similar-sized startups and assessed what could be sustain financially.
B4: =B3+1 -> 2 | C4: Annual Bonus | D4: 30270000 | E4: 0 | F4: -100% | G4: Removed, given the startup phase of the organization. | I4: Given the startup phase, the organization needs to conserve funds and ensure financial stability first. We felt it was prudent to suspend the bonus until the IIH is more established.
B5: =B4+1 -> 3 | C5: Airtime | D5: 840000 | E5: 1866000 | F5: =E5/D5-1 -> 1.2214286 | G5: Combined Airtime & Data into one line item. | I5: Adopted IHS approach
B6: =B5+1 -> 4 | C6: Mobile Data Plan | D6: 2040000 | E6: 0 | F6: -100% | G6: Eliminated; merged into Airtime above.
B7: =B6+1 -> 5 | C7: Total Cafeteria Subsidy | D7: 5760000 | E7: 4680000 | F7: =E7/D7-1 -> -0.1875 | G7: Standardized to 1,200/day per employee. | I7: This figure ensures that all employees still receive a reasonable meal subsidy.
B8: =B7+1 -> 6 | C8: ITF Cost | D8: 1785420 | E8: 1530244.8 | F8: =E8/D8-1 -> -0.14292167 | G8: Adjusted to reflect 1% of payroll cost. | I8: Yes, the revised figures reflect 1% of the current payroll costs, which aligns with statutory obligations
B9: =B8+1 -> 7 | C9: NSITF (ECS) | D9: 1785420 | E9: 1530244.8 | F9: =E9/D9-1 -> -0.14292167 | G9: Adjusted to reflect 1% of payroll cost.
B10: =B9+1 -> 8 | C10: Employer Cost | D10: 2.3501734e+08 | E10: ='Month on Month HC Cost'!O19 -> 1.462322e+08 | F10: =E10/D10-1 -> -0.37778122 | G10: Headcount phased in over 12 months rather than all at once. | I10: The largest driver is that we’re no longer budgeting for all employees from the start of the year. We phased in new hires throughout the year, which reduces the total annual payroll and associated costs.

Sheet Month on Month HC Cost
E1: Employer Cost - aligned with the Headcount Phasing
A2: S/N | B2: Grade | C2: Jan | D2: Feb | E2: Mar | F2: Apr | G2: May | H2: Jun | I2: Jul | J2: Aug | K2: Sep | L2: Oct | M2: Nov | N2: Dec | O2: Total Cost for the year 2025
A3: 1 | B3: Managing Director | C3: =(_xlfn.XLOOKUP(B3,'Annual Employer Cost per Grade'!$C$2:$C$17,'Annual Employer Cost per Grade'!$U$2:$U$17,0,0))*(INDEX('Headcount Phasing'!$B$3:$M$18,MATCH(B3,'Headcount Phasing'!$A$3:$A$18,0),MATCH($C$2,'Headcount Phasing'!$B$2:$M$2,0))) -> 0 | D3: =(_xlfn.XLOOKUP(B3,'Annual Employer Cost per Grade'!$C$2:$C$17,'Annual Employer Cost per Grade'!$U$2:$U$17,0,0))*(INDEX('Headcount Phasing'!$B$3:$M$18,MATCH(B3,'Headcount Phasing'!$A$3:$A$18,0),MATCH($D$2,'Headcount Phasing'!$B$2:$M$2,0))) -> 0 | E3: =(_xlfn.XLOOKUP(B3,'Annual Employer Cost per Grade'!$C$2:$C$17,'Annual Employer Cost per Grade'!$U$2:$U$17,0,0))*(INDEX('Headcount Phasing'!$B$3:$M$18,MATCH(B3,'Headcount Phasing'!$A$3:$A$18,0),MATCH($E$2,'Headcount Phasing'!$B$2:$M$2,0))) -> 6187666.7 | F3: =(_xlfn.XLOOKUP(B3,'Annual Employer Cost per Grade'!$C$2:$C$17,'Annual Employer Cost per Grade'!$U$2:$U$17,0,0))*(INDEX('Headcount Phasing'!$B$3:$M$18,MATCH(B3,'Headcount Phasing'!$A$3:$A$18,0),MATCH($F$2,'Headcount Phasing'!$B$2:$M$2,0))) -> 6187666.7 | G3: =(_xlfn.XLOOKUP(B3,'Annual Employer Cost per Grade'!$C$2:$C$17,'Annual Employer Cost per Grade'!$U$2:$U$17,0,0))*(INDEX('Headcount Phasing'!$B$3:$M$18,MATCH(B3,'Headcount Phasing'!$A$3:$A$18,0),MATCH($G$2,'Headcount Phasing'!$B$2:$M$2,0))) -> 6187666.7 | H3: =(_xlfn.XLOOKUP(B3,'Annual Employer Cost per Grade'!$C$2:$C$17,'Annual Employer Cost per Grade'!$U$2:$U$17,0,0))*(INDEX('Headcount Phasing'!$B$3:$M$18,MATCH(B3,'Headcount Phasing'!$A$3:$A$18,0),MATCH($H$2,'Headcount Phasing'!$B$2:$M$2,0))) -> 6187666.7 | I3: =(_xlfn.XLOOKUP(B3,'Annual Employer Cost per Grade'!$C$2:$C$17,'Annual Employer Cost per Grade'!$U$2:$U$17,0,0))*(INDEX('Headcount Phasing'!$B$3:$M$18,MATCH(B3,'Headcount Phasing'!$A$3:$A$18,0),MATCH($I$2,'Headcount Phasing'!$B$2:$M$2,0))) -> 6187666.7 | J3: =(_xlfn.XLOOKUP(B3,'Annual Employer Cost per Grade'!$C$2:$C$17,'Annual Employer Cost per Grade'!$U$2:$U$17,0,0))*(INDEX('Headcount Phasing'!$B$3:$M$18,MATCH(B3,'Headcount Phasing'!$A$3:$A$18,0),MATCH($J$2,'Headcount Phasing'!$B$2:$M$2,0))) -> 6187666.7 | K3: =(_xlfn.XLOOKUP(B3,'Annual Employer Cost per Grade'!$C$2:$C$17,'Annual Employer Cost per Grade'!$U$2:$U$17,0,0))*(INDEX('Headcount Phasing'!$B$3:$M$18,MATCH(B3,'Headcount Phasing'!$A$3:$A$18,0),MATCH($K$2,'Headcount Phasing'!$B$2:$M$2,0))) -> 6187666.7 | L3: =(_xlfn.XLOOKUP(B3,'Annual Employer Cost per Grade'!$C$2:$C$17,'Annual Employer Cost per Grade'!$U$2:$U$17,0,0))*(INDEX('Headcount Phasing'!$B$3:$M$18,MATCH(B3,'Headcount Phasing'!$A$3:$A$18,0),MATCH($L$2,'Headcount Phasing'!$B$2:$M$2,0))) -> 6187666.7 | M3: =(_xlfn.XLOOKUP(B3,'Annual Employer Cost per Grade'!$C$2:$C$17,'Annual Employer Cost per Grade'!$U$2:$U$17,0,0))*(INDEX('Headcount Phasing'!$B$3:$M$18,MATCH(B3,'Headcount Phasing'!$A$3:$A$18,0),MATCH($M$2,'Headcount Phasing'!$B$2:$M$2,0))) -> 6187666.7 | N3: =(_xlfn.XLOOKUP(B3,'Annual Employer Cost per Grade'!$C$2:$C$17,'Annual Employer Cost per Grade'!$U$2:$U$17,0,0))*(INDEX('Headcount Phasing'!$B$3:$M$18,MATCH(B3,'Headcount Phasing'!$A$3:$A$18,0),MATCH($N$2,'Headcount Phasing'!$B$2:$M$2,0))) -> 6187666.7 | O3: =SUM(C3:N3) -> 61876667
A4: =A3+1 -> 2 | B4: Director of Programs | C4: =(_xlfn.XLOOKUP(B4,'Annual Employer Cost per Grade'!$C$2:$C$17,'Annual Employer Cost per Grade'!$U$2:$U$17,0,0))*(INDEX('Headcount Phasing'!$B$3:$M$18,MATCH(B4,'Headcount Phasing'!$A$3:$A$18,0),MATCH($C$2,'Headcount Phasing'!$B$2:$M$2,0))) -> 0 | D4: =(_xlfn.XLOOKUP(B4,'Annual Employer Cost per Grade'!$C$2:$C$17,'Annual Employer Cost per Grade'!$U$2:$U$17,0,0))*(INDEX('Headcount Phasing'!$B$3:$M$18,MATCH(B4,'Headcount Phasing'!$A$3:$A$18,0),MATCH($D$2,'Headcount Phasing'!$B$2:$M$2,0))) -> 0 | E4: =(_xlfn.XLOOKUP(B4,'Annual Employer Cost per Grade'!$C$2:$C$17,'Annual Employer Cost per Grade'!$U$2:$U$17,0,0))*(INDEX('Headcount Phasing'!$B$3:$M$18,MATCH(B4,'Headcount Phasing'!$A$3:$A$18,0),MATCH($E$2,'Headcount Phasing'!$B$2:$M$2,0))) -> 0 | F4: =(_xlfn.XLOOKUP(B4,'Annual Employer Cost per Grade'!$C$2:$C$17,'Annual Employer Cost per Grade'!$U$2:$U$17,0,0))*(INDEX('Headcount Phasing'!$B$3:$M$18,MATCH(B4,'Headcount Phasing'!$A$3:$A$18,0),MATCH($F$2,'Headcount Phasing'!$B$2:$M$2,0))) -> 3555487.9 | G4: =(_xlfn.XLOOKUP(B4,'Annual Employer Cost per Grade'!$C$2:$C$17,'Annual Employer Cost per Grade'!$U$2:$U$17,0,0))*(INDEX('Headcount Phasing'!$B$3:$M$18,MATCH(B4,'Headcount Phasing'!$A$3:$A$18,0),MATCH($G$2,'Headcount Phasing'!$B$2:$M$2,0))) -> 3555487.9 | H4: =(_xlfn.XLOOKUP(B4,'Annual Employer Cost per Grade'!$C$2:$C$17,'Annual Employer Cost per Grade'!$U$2:$U$17,0,0))*(INDEX('Headcount Phasing'!$B$3:$M$18,MATCH(B4,'Headcount Phasing'!$A$3:$A$18,0),MATCH($H$2,'Headcount Phasing'!$B$2:$M$2,0))) -> 3555487.9 | I4: =(_xlfn.XLOOKUP(B4,'Annual Employer Cost per Grade'!$C$2:$C$17,'Annual Employer Cost per Grade'!$U$2:$U$17,0,0))*(INDEX('Headcount Phasing'!$B$3:$M$18,MATCH(B4,'Headcount Phasing'!$A$3:$A$18,0),MATCH($I$2,'Headcount Phasing'!$B$2:$M$2,0))) -> 3555487.9 | J4: =(_xlfn.XLOOKUP(B4,'Annual Employer Cost per Grade'!$C$2:$C$17,'Annual Employer Cost per Grade'!$U$2:$U$17,0,0))*(INDEX('Headcount Phasing'!$B$3:$M$18,MATCH(B4,'Headcount Phasing'!$A$3:$A$18,0),MATCH($J$2,'Headcount Phasing'!$B$2:$M$2,0))) -> 3555487.9 | K4: =(_xlfn.XLOOKUP(B4,'Annual Employer Cost per Grade'!$C$2:$C$17,'Annual Employer Cost per Grade'!$U$2:$U$17,0,0))*(INDEX('Headcount Phasing'!$B$3:$M$18,MATCH(B4,'Headcount Phasing'!$A$3:$A$18,0),MATCH($K$2,'Headcount Phasing'!$B$2:$M$2,0))) -> 3555487.9 | L4: =(_xlfn.XLOOKUP(B4,'Annual Employer Cost per Grade'!$C$2:$C$17,'Annual Employer Cost per Grade'!$U$2:$U$17,0,0))*(INDEX('Headcount Phasing'!$B$3:$M$18,MATCH(B4,'Headcount Phasing'!$A$3:$A$18,0),MATCH($L$2,'Headcount Phasing'!$B$2:$M$2,0))) -> 3555487.9 | M4: =(_xlfn.XLOOKUP(B4,'Annual Employer Cost per Grade'!$C$2:$C$17,'Annual Employer Cost per Grade'!$U$2:$U$17,0,0))*(INDEX('Headcount Phasing'!$B$3:$M$18,MATCH(B4,'Headcount Phasing'!$A$3:$A$18,0),MATCH($M$2,'Headcount Phasing'!$B$2:$M$2,0))) -> 3555487.9 | N4: =(_xlfn.XLOOKUP(B4,'Annual Employer Cost per Grade'!$C$2:$C$17,'Annual Employer Cost per Grade'!$U$2:$U$17,0,0))*(INDEX('Headcount Phasing'!$B$3:$M$18,MATCH(B4,'Headcount Phasing'!$A$3:$A$18,0),MATCH($N$2,'Headcount Phasing'!$B$2:$M$2,0))) -> 3555487.9 | O4: =SUM(C4:N4) -> 31999391
A5: =A4+1 -> 3 | B5: IT Manager | C5: =(_xlfn.XLOOKUP(B5,'Annual Employer Cost per Grade'!$C$2:$C$17,'Annual Employer Cost per Grade'!$U$2:$U$17,0,0))*(INDEX('Headcount Phasing'!$B$3:$M$18,MATCH(B5,'Headcount Phasing'!$A$3:$A$18,0),MATCH($C$2,'Headcount Phasing'!$B$2:$M$2,0))) -> 0 | D5: =(_xlfn.XLOOKUP(B5,'Annual Employer Cost per Grade'!$C$2:$C$17,'Annual Employer Cost per Grade'!$U$2:$U$17,0,0))*(INDEX('Headcount Phasing'!$B$3:$M$18,MATCH(B5,'Headcount Phasing'!$A$3:$A$18,0),MATCH($D$2,'Headcount Phasing'!$B$2:$M$2,0))) -> 0 | E5: =(_xlfn.XLOOKUP(B5,'Annual Employer Cost per Grade'!$C$2:$C$17,'Annual Employer Cost per Grade'!$U$2:$U$17,0,0))*(INDEX('Headcount Phasing'!$B$3:$M$18,MATCH(B5,'Headcount Phasing'!$A$3:$A$18,0),MATCH($E$2,'Headcount Phasing'!$B$2:$M$2,0))) -> 0 | F5: =(_xlfn.XLOOKUP(B5,'Annual Employer Cost per Grade'!$C$2:$C$17,'Annual Employer Cost per Grade'!$U$2:$U$17,0,0))*(INDEX('Headcount Phasing'!$B$3:$M$18,MATCH(B5,'Headcount Phasing'!$A$3:$A$18,0),MATCH($F$2,'Headcount Phasing'!$B$2:$M$2,0))) -> 779030.5 | G5: =(_xlfn.XLOOKUP(B5,'Annual Employer Cost per Grade'!$C$2:$C$17,'Annual Employer Cost per Grade'!$U$2:$U$17,0,0))*(INDEX('Headcount Phasing'!$B$3:$M$18,MATCH(B5,'Headcount Phasing'!$A$3:$A$18,0),MATCH($G$2,'Headcount Phasing'!$B$2:$M$2,0))) -> 779030.5 | H5: =(_xlfn.XLOOKUP(B5,'Annual Employer Cost per Grade'!$C$2:$C$17,'Annual Employer Cost per Grade'!$U$2:$U$17,0,0))*(INDEX('Headcount Phasing'!$B$3:$M$18,MATCH(B5,'Headcount Phasing'!$A$3:$A$18,0),MATCH($H$2,'Headcount Phasing'!$B$2:$M$2,0))) -> 779030.5 | I5: =(_xlfn.XLOOKUP(B5,'Annual Employer Cost per Grade'!$C$2:$C$17,'Annual Employer Cost per Grade'!$U$2:$U$17,0,0))*(INDEX('Headcount Phasing'!$B$3:$M$18,MATCH(B5,'Headcount Phasing'!$A$3:$A$18,0),MATCH($I$2,'Headcount Phasing'!$B$2:$M$2,0))) -> 779030.5 | J5: =(_xlfn.XLOOKUP(B5,'Annual Employer Cost per Grade'!$C$2:$C$17,'Annual Employer Cost per Grade'!$U$2:$U$17,0,0))*(INDEX('Headcount Phasing'!$B$3:$M$18,MATCH(B5,'Headcount Phasing'!$A$3:$A$18,0),MATCH($J$2,'Headcount Phasing'!$B$2:$M$2,0))) -> 779030.5 | K5: =(_xlfn.XLOOKUP(B5,'Annual Employer Cost per Grade'!$C$2:$C$17,'Annual Employer Cost per Grade'!$U$2:$U$17,0,0))*(INDEX('Headcount Phasing'!$B$3:$M$18,MATCH(B5,'Headcount Phasing'!$A$3:$A$18,0),MATCH($K$2,'Headcount Phasing'!$B$2:$M$2,0))) -> 779030.5 | L5: =(_xlfn.XLOOKUP(B5,'Annual Employer Cost per Grade'!$C$2:$C$17,'Annual Employer Cost per Grade'!$U$2:$U$17,0,0))*(INDEX('Headcount Phasing'!$B$3:$M$18,MATCH(B5,'Headcount Phasing'!$A$3:$A$18,0),MATCH($L$2,'Headcount Phasing'!$B$2:$M$2,0))) -> 779030.5 | M5: =(_xlfn.XLOOKUP(B5,'Annual Employer Cost per Grade'!$C$2:$C$17,'Annual Employer Cost per Grade'!$U$2:$U$17,0,0))*(INDEX('Headcount Phasing'!$B$3:$M$18,MATCH(B5,'Headcount Phasing'!$A$3:$A$18,0),MATCH($M$2,'Headcount Phasing'!$B$2:$M$2,0))) -> 779030.5 | N5: =(_xlfn.XLOOKUP(B5,'Annual Employer Cost per Grade'!$C$2:$C$17,'Annual Employer Cost per Grade'!$U$2:$U$17,0,0))*(INDEX('Headcount Phasing'!$B$3:$M$18,MATCH(B5,'Headcount Phasing'!$A$3:$A$18,0),MATCH($N$2,'Headcount Phasing'!$B$2:$M$2,0))) -> 779030.5 | O5: =SUM(C5:N5) -> 7011274.5
A6: =A5+1 -> 4 | B6: Community Manager | C6: =(_xlfn.XLOOKUP(B6,'Annual Employer Cost per Grade'!$C$2:$C$17,'Annual Employer Cost per Grade'!$U$2:$U$17,0,0))*(INDEX('Headcount Phasing'!$B$3:$M$18,MATCH(B6,'Headcount Phasing'!$A$3:$A$18,0),MATCH($C$2,'Headcount Phasing'!$B$2:$M$2,0))) -> 0 | D6: =(_xlfn.XLOOKUP(B6,'Annual Employer Cost per Grade'!$C$2:$C$17,'Annual Employer Cost per Grade'!$U$2:$U$17,0,0))*(INDEX('Headcount Phasing'!$B$3:$M$18,MATCH(B6,'Headcount Phasing'!$A$3:$A$18,0),MATCH($D$2,'Headcount Phasing'!$B$2:$M$2,0))) -> 0 | E6: =(_xlfn.XLOOKUP(B6,'Annual Employer Cost per Grade'!$C$2:$C$17,'Annual Employer Cost per Grade'!$U$2:$U$17,0,0))*(INDEX('Headcount Phasing'!$B$3:$M$18,MATCH(B6,'Headcount Phasing'!$A$3:$A$18,0),MATCH($E$2,'Headcount Phasing'!$B$2:$M$2,0))) -> 0 | F6: =(_xlfn.XLOOKUP(B6,'Annual Employer Cost per Grade'!$C$2:$C$17,'Annual Employer Cost per Grade'!$U$2:$U$17,0,0))*(INDEX('Headcount Phasing'!$B$3:$M$18,MATCH(B6,'Headcount Phasing'!$A$3:$A$18,0),MATCH($F$2,'Headcount Phasing'!$B$2:$M$2,0))) -> 474470.5 | G6: =(_xlfn.XLOOKUP(B6,'Annual Employer Cost per Grade'!$C$2:$C$17,'Annual Employer Cost per Grade'!$U$2:$U$17,0,0))*(INDEX('Headcount Phasing'!$B$3:$M$18,MATCH(B6,'Headcount Phasing'!$A$3:$A$18,0),MATCH($G$2,'Headcount Phasing'!$B$2:$M$2,0))) -> 474470.5 | H6: =(_xlfn.XLOOKUP(B6,'Annual Employer Cost per Grade'!$C$2:$C$17,'Annual Employer Cost per Grade'!$U$2:$U$17,0,0))*(INDEX('Headcount Phasing'!$B$3:$M$18,MATCH(B6,'Headcount Phasing'!$A$3:$A$18,0),MATCH($H$2,'Headcount Phasing'!$B$2:$M$2,0))) -> 474470.5 | I6: =(_xlfn.XLOOKUP(B6,'Annual Employer Cost per Grade'!$C$2:$C$17,'Annual Employer Cost per Grade'!$U$2:$U$17,0,0))*(INDEX('Headcount Phasing'!$B$3:$M$18,MATCH(B6,'Headcount Phasing'!$A$3:$A$18,0),MATCH($I$2,'Headcount Phasing'!$B$2:$M$2,0))) -> 474470.5 | J6: =(_xlfn.XLOOKUP(B6,'Annual Employer Cost per Grade'!$C$2:$C$17,'Annual Employer Cost per Grade'!$U$2:$U$17,0,0))*(INDEX('Headcount Phasing'!$B$3:$M$18,MATCH(B6,'Headcount Phasing'!$A$3:$A$18,0),MATCH($J$2,'Headcount Phasing'!$B$2:$M$2,0))) -> 474470.5 | K6: =(_xlfn.XLOOKUP(B6,'Annual Employer Cost per Grade'!$C$2:$C$17,'Annual Employer Cost per Grade'!$U$2:$U$17,0,0))*(INDEX('Headcount Phasing'!$B$3:$M$18,MATCH(B6,'Headcount Phasing'!$A$3:$A$18,0),MATCH($K$2,'Headcount Phasing'!$B$2:$M$2,0))) -> 474470.5 | L6: =(_xlfn.XLOOKUP(B6,'Annual Employer Cost per Grade'!$C$2:$C$17,'Annual Employer Cost per Grade'!$U$2:$U$17,0,0))*(INDEX('Headcount Phasing'!$B$3:$M$18,MATCH(B6,'Headcount Phasing'!$A$3:$A$18,0),MATCH($L$2,'Headcount Phasing'!$B$2:$M$2,0))) -> 474470.5 | M6: =(_xlfn.XLOOKUP(B6,'Annual Employer Cost per Grade'!$C$2:$C$17,'Annual Employer Cost per Grade'!$U$2:$U$17,0,0))*(INDEX('Headcount Phasing'!$B$3:$M$18,MATCH(B6,'Headcount Phasing'!$A$3:$A$18,0),MATCH($M$2,'Headcount Phasing'!$B$2:$M$2,0))) -> 474470.5 | N6: =(_xlfn.XLOOKUP(B6,'Annual Employer Cost per Grade'!$C$2:$C$17,'Annual Employer Cost per Grade'!$U$2:$U$17,0,0))*(INDEX('Headcount Phasing'!$B$3:$M$18,MATCH(B6,'Headcount Phasing'!$A$3:$A$18,0),MATCH($N$2,'Headcount Phasing'!$B$2:$M$2,0))) -> 474470.5 | O6: =SUM(C6:N6) -> 4270234.5
A7: =A6+1 -> 5 | B7: Facility Associate | C7: =(_xlfn.XLOOKUP(B7,'Annual Employer Cost per Grade'!$C$2:$C$17,'Annual Employer Cost per Grade'!$U$2:$U$17,0,0))*(INDEX('Headcount Phasing'!$B$3:$M$18,MATCH(B7,'Headcount Phasing'!$A$3:$A$18,0),MATCH($C$2,'Headcount Phasing'!$B$2:$M$2,0))) -> 0 | D7: =(_xlfn.XLOOKUP(B7,'Annual Employer Cost per Grade'!$C$2:$C$17,'Annual Employer Cost per Grade'!$U$2:$U$17,0,0))*(INDEX('Headcount Phasing'!$B$3:$M$18,MATCH(B7,'Headcount Phasing'!$A$3:$A$18,0),MATCH($D$2,'Headcount Phasing'!$B$2:$M$2,0))) -> 0 | E7: =(_xlfn.XLOOKUP(B7,'Annual Employer Cost per Grade'!$C$2:$C$17,'Annual Employer Cost per Grade'!$U$2:$U$17,0,0))*(INDEX('Headcount Phasing'!$B$3:$M$18,MATCH(B7,'Headcount Phasing'!$A$3:$A$18,0),MATCH($E$2,'Headcount Phasing'!$B$2:$M$2,0))) -> 0 | F7: =(_xlfn.XLOOKUP(B7,'Annual Employer Cost per Grade'!$C$2:$C$17,'Annual Employer Cost per Grade'!$U$2:$U$17,0,0))*(INDEX('Headcount Phasing'!$B$3:$M$18,MATCH(B7,'Headcount Phasing'!$A$3:$A$18,0),MATCH($F$2,'Headcount Phasing'!$B$2:$M$2,0))) -> 458050.88 | G7: =(_xlfn.XLOOKUP(B7,'Annual Employer Cost per Grade'!$C$2:$C$17,'Annual Employer Cost per Grade'!$U$2:$U$17,0,0))*(INDEX('Headcount Phasing'!$B$3:$M$18,MATCH(B7,'Headcount Phasing'!$A$3:$A$18,0),MATCH($G$2,'Headcount Phasing'!$B$2:$M$2,0))) -> 458050.88 | H7: =(_xlfn.XLOOKUP(B7,'Annual Employer Cost per Grade'!$C$2:$C$17,'Annual Employer Cost per Grade'!$U$2:$U$17,0,0))*(INDEX('Headcount Phasing'!$B$3:$M$18,MATCH(B7,'Headcount Phasing'!$A$3:$A$18,0),MATCH($H$2,'Headcount Phasing'!$B$2:$M$2,0))) -> 458050.88 | I7: =(_xlfn.XLOOKUP(B7,'Annual Employer Cost per Grade'!$C$2:$C$17,'Annual Employer Cost per Grade'!$U$2:$U$17,0,0))*(INDEX('Headcount Phasing'!$B$3:$M$18,MATCH(B7,'Headcount Phasing'!$A$3:$A$18,0),MATCH($I$2,'Headcount Phasing'!$B$2:$M$2,0))) -> 458050.88 | J7: =(_xlfn.XLOOKUP(B7,'Annual Employer Cost per Grade'!$C$2:$C$17,'Annual Employer Cost per Grade'!$U$2:$U$17,0,0))*(INDEX('Headcount Phasing'!$B$3:$M$18,MATCH(B7,'Headcount Phasing'!$A$3:$A$18,0),MATCH($J$2,'Headcount Phasing'!$B$2:$M$2,0))) -> 458050.88 | K7: =(_xlfn.XLOOKUP(B7,'Annual Employer Cost per Grade'!$C$2:$C$17,'Annual Employer Cost per Grade'!$U$2:$U$17,0,0))*(INDEX('Headcount Phasing'!$B$3:$M$18,MATCH(B7,'Headcount Phasing'!$A$3:$A$18,0),MATCH($K$2,'Headcount Phasing'!$B$2:$M$2,0))) -> 458050.88 | L7: =(_xlfn.XLOOKUP(B7,'Annual Employer Cost per Grade'!$C$2:$C$17,'Annual Employer Cost per Grade'!$U$2:$U$17,0,0))*(INDEX('Headcount Phasing'!$B$3:$M$18,MATCH(B7,'Headcount Phasing'!$A$3:$A$18,0),MATCH($L$2,'Headcount Phasing'!$B$2:$M$2,0))) -> 458050.88 | M7: =(_xlfn.XLOOKUP(B7,'Annual Employer Cost per Grade'!$C$2:$C$17,'Annual Employer Cost per Grade'!$U$2:$U$17,0,0))*(INDEX('Headcount Phasing'!$B$3:$M$18,MATCH(B7,'Headcount Phasing'!$A$3:$A$18,0),MATCH($M$2,'Headcount Phasing'!$B$2:$M$2,0))) -> 458050.88 | N7: =(_xlfn.XLOOKUP(B7,'Annual Employer Cost per Grade'!$C$2:$C$17,'Annual Employer Cost per Grade'!$U$2:$U$17,0,0))*(INDEX('Headcount Phasing'!$B$3:$M$18,MATCH(B7,'Headcount Phasing'!$A$3:$A$18,0),MATCH($N$2,'Headcount Phasing'!$B$2:$M$2,0))) -> 458050.88 | O7: =SUM(C7:N7) -> 4122457.9
A8: =A7+1 -> 6 | B8: Front Desk Associate (x1) | C8: =(_xlfn.XLOOKUP(B8,'Annual Employer Cost per Grade'!$C$2:$C$17,'Annual Employer Cost per Grade'!$U$2:$U$17,0,0))*(INDEX('Headcount Phasing'!$B$3:$M$18,MATCH(B8,'Headcount Phasing'!$A$3:$A$18,0),MATCH($C$2,'Headcount Phasing'!$B$2:$M$2,0))) -> 0 | D8: =(_xlfn.XLOOKUP(B8,'Annual Employer Cost per Grade'!$C$2:$C$17,'Annual Employer Cost per Grade'!$U$2:$U$17,0,0))*(INDEX('Headcount Phasing'!$B$3:$M$18,MATCH(B8,'Headcount Phasing'!$A$3:$A$18,0),MATCH($D$2,'Headcount Phasing'!$B$2:$M$2,0))) -> 0 | E8: =(_xlfn.XLOOKUP(B8,'Annual Employer Cost per Grade'!$C$2:$C$17,'Annual Employer Cost per Grade'!$U$2:$U$17,0,0))*(INDEX('Headcount Phasing'!$B$3:$M$18,MATCH(B8,'Headcount Phasing'!$A$3:$A$18,0),MATCH($E$2,'Headcount Phasing'!$B$2:$M$2,0))) -> 0 | F8: =(_xlfn.XLOOKUP(B8,'Annual Employer Cost per Grade'!$C$2:$C$17,'Annual Employer Cost per Grade'!$U$2:$U$17,0,0))*(INDEX('Headcount Phasing'!$B$3:$M$18,MATCH(B8,'Headcount Phasing'!$A$3:$A$18,0),MATCH($F$2,'Headcount Phasing'!$B$2:$M$2,0))) -> 458050.88 | G8: =(_xlfn.XLOOKUP(B8,'Annual Employer Cost per Grade'!$C$2:$C$17,'Annual Employer Cost per Grade'!$U$2:$U$17,0,0))*(INDEX('Headcount Phasing'!$B$3:$M$18,MATCH(B8,'Headcount Phasing'!$A$3:$A$18,0),MATCH($G$2,'Headcount Phasing'!$B$2:$M$2,0))) -> 458050.88 | H8: =(_xlfn.XLOOKUP(B8,'Annual Employer Cost per Grade'!$C$2:$C$17,'Annual Employer Cost per Grade'!$U$2:$U$17,0,0))*(INDEX('Headcount Phasing'!$B$3:$M$18,MATCH(B8,'Headcount Phasing'!$A$3:$A$18,0),MATCH($H$2,'Headcount Phasing'!$B$2:$M$2,0))) -> 458050.88 | I8: =(_xlfn.XLOOKUP(B8,'Annual Employer Cost per Grade'!$C$2:$C$17,'Annual Employer Cost per Grade'!$U$2:$U$17,0,0))*(INDEX('Headcount Phasing'!$B$3:$M$18,MATCH(B8,'Headcount Phasing'!$A$3:$A$18,0),MATCH($I$2,'Headcount Phasing'!$B$2:$M$2,0))) -> 458050.88 | J8: =(_xlfn.XLOOKUP(B8,'Annual Employer Cost per Grade'!$C$2:$C$17,'Annual Employer Cost per Grade'!$U$2:$U$17,0,0))*(INDEX('Headcount Phasing'!$B$3:$M$18,MATCH(B8,'Headcount Phasing'!$A$3:$A$18,0),MATCH($J$2,'Headcount Phasing'!$B$2:$M$2,0))) -> 458050.88 | K8: =(_xlfn.XLOOKUP(B8,'Annual Employer Cost per Grade'!$C$2:$C$17,'Annual Employer Cost per Grade'!$U$2:$U$17,0,0))*(INDEX('Headcount Phasing'!$B$3:$M$18,MATCH(B8,'Headcount Phasing'!$A$3:$A$18,0),MATCH($K$2,'Headcount Phasing'!$B$2:$M$2,0))) -> 458050.88 | L8: =(_xlfn.XLOOKUP(B8,'Annual Employer Cost per Grade'!$C$2:$C$17,'Annual Employer Cost per Grade'!$U$2:$U$17,0,0))*(INDEX('Headcount Phasing'!$B$3:$M$18,MATCH(B8,'Headcount Phasing'!$A$3:$A$18,0),MATCH($L$2,'Headcount Phasing'!$B$2:$M$2,0))) -> 458050.88 | M8: =(_xlfn.XLOOKUP(B8,'Annual Employer Cost per Grade'!$C$2:$C$17,'Annual Employer Cost per Grade'!$U$2:$U$17,0,0))*(INDEX('Headcount Phasing'!$B$3:$M$18,MATCH(B8,'Headcount Phasing'!$A$3:$A$18,0),MATCH($M$2,'Headcount Phasing'!$B$2:$M$2,0))) -> 458050.88 | N8: =(_xlfn.XLOOKUP(B8,'Annual Employer Cost per Grade'!$C$2:$C$17,'Annual Employer Cost per Grade'!$U$2:$U$17,0,0))*(INDEX('Headcount Phasing'!$B$3:$M$18,MATCH(B8,'Headcount Phasing'!$A$3:$A$18,0),MATCH($N$2,'Headcount Phasing'!$B$2:$M$2,0))) -> 458050.88 | O8: =SUM(C8:N8) -> 4122457.9
A9: =A8+1 -> 7 | B9: Front Desk Support (Tech Grade 1) | F9: =(_xlfn.XLOOKUP(B9,'Annual Employer Cost per Grade'!$C$2:$C$17,'Annual Employer Cost per Grade'!$U$2:$U$17,0,0))*(INDEX('Headcount Phasing'!$B$3:$M$18,MATCH(B9,'Headcount Phasing'!$A$3:$A$18,0),MATCH($F$2,'Headcount Phasing'!$B$2:$M$2,0))) -> 231183.15 | G9: =(_xlfn.XLOOKUP(B9,'Annual Employer Cost per Grade'!$C$2:$C$17,'Annual Employer Cost per Grade'!$U$2:$U$17,0,0))*(INDEX('Headcount Phasing'!$B$3:$M$18,MATCH(B9,'Headcount Phasing'!$A$3:$A$18,0),MATCH($G$2,'Headcount Phasing'!$B$2:$M$2,0))) -> 231183.15 | H9: =(_xlfn.XLOOKUP(B9,'Annual Employer Cost per Grade'!$C$2:$C$17,'Annual Employer Cost per Grade'!$U$2:$U$17,0,0))*(INDEX('Headcount Phasing'!$B$3:$M$18,MATCH(B9,'Headcount Phasing'!$A$3:$A$18,0),MATCH($H$2,'Headcount Phasing'!$B$2:$M$2,0))) -> 231183.15 | I9: =(_xlfn.XLOOKUP(B9,'Annual Employer Cost per Grade'!$C$2:$C$17,'Annual Employer Cost per Grade'!$U$2:$U$17,0,0))*(INDEX('Headcount Phasing'!$B$3:$M$18,MATCH(B9,'Headcount Phasing'!$A$3:$A$18,0),MATCH($I$2,'Headcount Phasing'!$B$2:$M$2,0))) -> 231183.15 | J9: =(_xlfn.XLOOKUP(B9,'Annual Employer Cost per Grade'!$C$2:$C$17,'Annual Employer Cost per Grade'!$U$2:$U$17,0,0))*(INDEX('Headcount Phasing'!$B$3:$M$18,MATCH(B9,'Headcount Phasing'!$A$3:$A$18,0),MATCH($J$2,'Headcount Phasing'!$B$2:$M$2,0))) -> 231183.15 | K9: =(_xlfn.XLOOKUP(B9,'Annual Employer Cost per Grade'!$C$2:$C$17,'Annual Employer Cost per Grade'!$U$2:$U$17,0,0))*(INDEX('Headcount Phasing'!$B$3:$M$18,MATCH(B9,'Headcount Phasing'!$A$3:$A$18,0),MATCH($K$2,'Headcount Phasing'!$B$2:$M$2,0))) -> 231183.15 | L9: =(_xlfn.XLOOKUP(B9,'Annual Employer Cost per Grade'!$C$2:$C$17,'Annual Employer Cost per Grade'!$U$2:$U$17,0,0))*(INDEX('Headcount Phasing'!$B$3:$M$18,MATCH(B9,'Headcount Phasing'!$A$3:$A$18,0),MATCH($L$2,'Headcount Phasing'!$B$2:$M$2,0))) -> 231183.15 | M9: =(_xlfn.XLOOKUP(B9,'Annual Employer Cost per Grade'!$C$2:$C$17,'Annual Employer Cost per Grade'!$U$2:$U$17,0,0))*(INDEX('Headcount Phasing'!$B$3:$M$18,MATCH(B9,'Headcount Phasing'!$A$3:$A$18,0),MATCH($M$2,'Headcount Phasing'!$B$2:$M$2,0))) -> 231183.15 | N9: =(_xlfn.XLOOKUP(B9,'Annual Employer Cost per Grade'!$C$2:$C$17,'Annual Employer Cost per Grade'!$U$2:$U$17,0,0))*(INDEX('Headcount Phasing'!$B$3:$M$18,MATCH(B9,'Headcount Phasing'!$A$3:$A$18,0),MATCH($N$2,'Headcount Phasing'!$B$2:$M$2,0))) -> 231183.15 | O9: =SUM(C9:N9) -> 2080648.3
A10: =A9+1 -> 8 | B10: Finance Associate | C10: =(_xlfn.XLOOKUP(B10,'Annual Employer Cost per Grade'!$C$2:$C$17,'Annual Employer Cost per Grade'!$U$2:$U$17,0,0))*(INDEX('Headcount Phasing'!$B$3:$M$18,MATCH(B10,'Headcount Phasing'!$A$3:$A$18,0),MATCH($C$2,'Headcount Phasing'!$B$2:$M$2,0))) -> 0 | D10: =(_xlfn.XLOOKUP(B10,'Annual Employer Cost per Grade'!$C$2:$C$17,'Annual Employer Cost per Grade'!$U$2:$U$17,0,0))*(INDEX('Headcount Phasing'!$B$3:$M$18,MATCH(B10,'Headcount Phasing'!$A$3:$A$18,0),MATCH($D$2,'Headcount Phasing'!$B$2:$M$2,0))) -> 0 | E10: =(_xlfn.XLOOKUP(B10,'Annual Employer Cost per Grade'!$C$2:$C$17,'Annual Employer Cost per Grade'!$U$2:$U$17,0,0))*(INDEX('Headcount Phasing'!$B$3:$M$18,MATCH(B10,'Headcount Phasing'!$A$3:$A$18,0),MATCH($E$2,'Headcount Phasing'!$B$2:$M$2,0))) -> 0 | F10: =(_xlfn.XLOOKUP(B10,'Annual Employer Cost per Grade'!$C$2:$C$17,'Annual Employer Cost per Grade'!$U$2:$U$17,0,0))*(INDEX('Headcount Phasing'!$B$3:$M$18,MATCH(B10,'Headcount Phasing'!$A$3:$A$18,0),MATCH($F$2,'Headcount Phasing'!$B$2:$M$2,0))) -> 458050.88 | G10: =(_xlfn.XLOOKUP(B10,'Annual Employer Cost per Grade'!$C$2:$C$17,'Annual Employer Cost per Grade'!$U$2:$U$17,0,0))*(INDEX('Headcount Phasing'!$B$3:$M$18,MATCH(B10,'Headcount Phasing'!$A$3:$A$18,0),MATCH($G$2,'Headcount Phasing'!$B$2:$M$2,0))) -> 458050.88 | H10: =(_xlfn.XLOOKUP(B10,'Annual Employer Cost per Grade'!$C$2:$C$17,'Annual Employer Cost per Grade'!$U$2:$U$17,0,0))*(INDEX('Headcount Phasing'!$B$3:$M$18,MATCH(B10,'Headcount Phasing'!$A$3:$A$18,0),MATCH($H$2,'Headcount Phasing'!$B$2:$M$2,0))) -> 458050.88 | I10: =(_xlfn.XLOOKUP(B10,'Annual Employer Cost per Grade'!$C$2:$C$17,'Annual Employer Cost per Grade'!$U$2:$U$17,0,0))*(INDEX('Headcount Phasing'!$B$3:$M$18,MATCH(B10,'Headcount Phasing'!$A$3:$A$18,0),MATCH($I$2,'Headcount Phasing'!$B$2:$M$2,0))) -> 458050.88 | J10: =(_xlfn.XLOOKUP(B10,'Annual Employer Cost per Grade'!$C$2:$C$17,'Annual Employer Cost per Grade'!$U$2:$U$17,0,0))*(INDEX('Headcount Phasing'!$B$3:$M$18,MATCH(B10,'Headcount Phasing'!$A$3:$A$18,0),MATCH($J$2,'Headcount Phasing'!$B$2:$M$2,0))) -> 458050.88 | K10: =(_xlfn.XLOOKUP(B10,'Annual Employer Cost per Grade'!$C$2:$C$17,'Annual Employer Cost per Grade'!$U$2:$U$17,0,0))*(INDEX('Headcount Phasing'!$B$3:$M$18,MATCH(B10,'Headcount Phasing'!$A$3:$A$18,0),MATCH($K$2,'Headcount Phasing'!$B$2:$M$2,0))) -> 458050.88 | L10: =(_xlfn.XLOOKUP(B10,'Annual Employer Cost per Grade'!$C$2:$C$17,'Annual Employer Cost per Grade'!$U$2:$U$17,0,0))*(INDEX('Headcount Phasing'!$B$3:$M$18,MATCH(B10,'Headcount Phasing'!$A$3:$A$18,0),MATCH($L$2,'Headcount Phasing'!$B$2:$M$2,0))) -> 458050.88 | M10: =(_xlfn.XLOOKUP(B10,'Annual Employer Cost per Grade'!$C$2:$C$17,'Annual Employer Cost per Grade'!$U$2:$U$17,0,0))*(INDEX('Headcount Phasing'!$B$3:$M$18,MATCH(B10,'Headcount Phasing'!$A$3:$A$18,0),MATCH($M$2,'Headcount Phasing'!$B$2:$M$2,0))) -> 458050.88 | N10: =(_xlfn.XLOOKUP(B10,'Annual Employer Cost per Grade'!$C$2:$C$17,'Annual Employer Cost per Grade'!$U$2:$U$17,0,0))*(INDEX('Headcount Phasing'!$B$3:$M$18,MATCH(B10,'Headcount Phasing'!$A$3:$A$18,0),MATCH($N$2,'Headcount Phasing'!$B$2:$M$2,0))) -> 458050.88 | O10: =SUM(C10:N10) -> 4122457.9
A11: =A10+1 -> 9 | B11: Admin & HR Associate | C11: =(_xlfn.XLOOKUP(B11,'Annual Employer Cost per Grade'!$C$2:$C$17,'Annual Employer Cost per Grade'!$U$2:$U$17,0,0))*(INDEX('Headcount Phasing'!$B$3:$M$18,MATCH(B11,'Headcount Phasing'!$A$3:$A$18,0),MATCH($C$2,'Headcount Phasing'!$B$2:$M$2,0))) -> 0 | D11: =(_xlfn.XLOOKUP(B11,'Annual Employer Cost per Grade'!$C$2:$C$17,'Annual Employer Cost per Grade'!$U$2:$U$17,0,0))*(INDEX('Headcount Phasing'!$B$3:$M$18,MATCH(B11,'Headcount Phasing'!$A$3:$A$18,0),MATCH($D$2,'Headcount Phasing'!$B$2:$M$2,0))) -> 0 | E11: =(_xlfn.XLOOKUP(B11,'Annual Employer Cost per Grade'!$C$2:$C$17,'Annual Employer Cost per Grade'!$U$2:$U$17,0,0))*(INDEX('Headcount Phasing'!$B$3:$M$18,MATCH(B11,'Headcount Phasing'!$A$3:$A$18,0),MATCH($E$2,'Headcount Phasing'!$B$2:$M$2,0))) -> 0 | F11: =(_xlfn.XLOOKUP(B11,'Annual Employer Cost per Grade'!$C$2:$C$17,'Annual Employer Cost per Grade'!$U$2:$U$17,0,0))*(INDEX('Headcount Phasing'!$B$3:$M$18,MATCH(B11,'Headcount Phasing'!$A$3:$A$18,0),MATCH($F$2,'Headcount Phasing'!$B$2:$M$2,0))) -> 458050.88 | G11: =(_xlfn.XLOOKUP(B11,'Annual Employer Cost per Grade'!$C$2:$C$17,'Annual Employer Cost per Grade'!$U$2:$U$17,0,0))*(INDEX('Headcount Phasing'!$B$3:$M$18,MATCH(B11,'Headcount Phasing'!$A$3:$A$18,0),MATCH($G$2,'Headcount Phasing'!$B$2:$M$2,0))) -> 458050.88 | H11: =(_xlfn.XLOOKUP(B11,'Annual Employer Cost per Grade'!$C$2:$C$17,'Annual Employer Cost per Grade'!$U$2:$U$17,0,0))*(INDEX('Headcount Phasing'!$B$3:$M$18,MATCH(B11,'Headcount Phasing'!$A$3:$A$18,0),MATCH($H$2,'Headcount Phasing'!$B$2:$M$2,0))) -> 458050.88 | I11: =(_xlfn.XLOOKUP(B11,'Annual Employer Cost per Grade'!$C$2:$C$17,'Annual Employer Cost per Grade'!$U$2:$U$17,0,0))*(INDEX('Headcount Phasing'!$B$3:$M$18,MATCH(B11,'Headcount Phasing'!$A$3:$A$18,0),MATCH($I$2,'Headcount Phasing'!$B$2:$M$2,0))) -> 458050.88 | J11: =(_xlfn.XLOOKUP(B11,'Annual Employer Cost per Grade'!$C$2:$C$17,'Annual Employer Cost per Grade'!$U$2:$U$17,0,0))*(INDEX('Headcount Phasing'!$B$3:$M$18,MATCH(B11,'Headcount Phasing'!$A$3:$A$18,0),MATCH($J$2,'Headcount Phasing'!$B$2:$M$2,0))) -> 458050.88 | K11: =(_xlfn.XLOOKUP(B11,'Annual Employer Cost per Grade'!$C$2:$C$17,'Annual Employer Cost per Grade'!$U$2:$U$17,0,0))*(INDEX('Headcount Phasing'!$B$3:$M$18,MATCH(B11,'Headcount Phasing'!$A$3:$A$18,0),MATCH($K$2,'Headcount Phasing'!$B$2:$M$2,0))) -> 458050.88 | L11: =(_xlfn.XLOOKUP(B11,'Annual Employer Cost per Grade'!$C$2:$C$17,'Annual Employer Cost per Grade'!$U$2:$U$17,0,0))*(INDEX('Headcount Phasing'!$B$3:$M$18,MATCH(B11,'Headcount Phasing'!$A$3:$A$18,0),MATCH($L$2,'Headcount Phasing'!$B$2:$M$2,0))) -> 458050.88 | M11: =(_xlfn.XLOOKUP(B11,'Annual Employer Cost per Grade'!$C$2:$C$17,'Annual Employer Cost per Grade'!$U$2:$U$17,0,0))*(INDEX('Headcount Phasing'!$B$3:$M$18,MATCH(B11,'Headcount Phasing'!$A$3:$A$18,0),MATCH($M$2,'Headcount Phasing'!$B$2:$M$2,0))) -> 458050.88 | N11: =(_xlfn.XLOOKUP(B11,'Annual Employer Cost per Grade'!$C$2:$C$17,'Annual Employer Cost per Grade'!$U$2:$U$17,0,0))*(INDEX('Headcount Phasing'!$B$3:$M$18,MATCH(B11,'Headcount Phasing'!$A$3:$A$18,0),MATCH($N$2,'Headcount Phasing'!$B$2:$M$2,0))) -> 458050.88 | O11: =SUM(C11:N11) -> 4122457.9
A12: =A11+1 -> 10 | B12: IT Support Associate (x2) | C12: =(_xlfn.XLOOKUP(B12,'Annual Employer Cost per Grade'!$C$2:$C$17,'Annual Employer Cost per Grade'!$U$2:$U$17,0,0))*(INDEX('Headcount Phasing'!$B$3:$M$18,MATCH(B12,'Headcount Phasing'!$A$3:$A$18,0),MATCH($C$2,'Headcount Phasing'!$B$2:$M$2,0))) -> 0 | D12: =(_xlfn.XLOOKUP(B12,'Annual Employer Cost per Grade'!$C$2:$C$17,'Annual Employer Cost per Grade'!$U$2:$U$17,0,0))*(INDEX('Headcount Phasing'!$B$3:$M$18,MATCH(B12,'Headcount Phasing'!$A$3:$A$18,0),MATCH($D$2,'Headcount Phasing'!$B$2:$M$2,0))) -> 0 | E12: =(_xlfn.XLOOKUP(B12,'Annual Employer Cost per Grade'!$C$2:$C$17,'Annual Employer Cost per Grade'!$U$2:$U$17,0,0))*(INDEX('Headcount Phasing'!$B$3:$M$18,MATCH(B12,'Headcount Phasing'!$A$3:$A$18,0),MATCH($E$2,'Headcount Phasing'!$B$2:$M$2,0))) -> 0 | F12: =(_xlfn.XLOOKUP(B12,'Annual Employer Cost per Grade'!$C$2:$C$17,'Annual Employer Cost per Grade'!$U$2:$U$17,0,0))*(INDEX('Headcount Phasing'!$B$3:$M$18,MATCH(B12,'Headcount Phasing'!$A$3:$A$18,0),MATCH($F$2,'Headcount Phasing'!$B$2:$M$2,0))) -> 458050.88 | G12: =(_xlfn.XLOOKUP(B12,'Annual Employer Cost per Grade'!$C$2:$C$17,'Annual Employer Cost per Grade'!$U$2:$U$17,0,0))*(INDEX('Headcount Phasing'!$B$3:$M$18,MATCH(B12,'Headcount Phasing'!$A$3:$A$18,0),MATCH($G$2,'Headcount Phasing'!$B$2:$M$2,0))) -> 458050.88 | H12: =(_xlfn.XLOOKUP(B12,'Annual Employer Cost per Grade'!$C$2:$C$17,'Annual Employer Cost per Grade'!$U$2:$U$17,0,0))*(INDEX('Headcount Phasing'!$B$3:$M$18,MATCH(B12,'Headcount Phasing'!$A$3:$A$18,0),MATCH($H$2,'Headcount Phasing'!$B$2:$M$2,0))) -> 458050.88 | I12: =(_xlfn.XLOOKUP(B12,'Annual Employer Cost per Grade'!$C$2:$C$17,'Annual Employer Cost per Grade'!$U$2:$U$17,0,0))*(INDEX('Headcount Phasing'!$B$3:$M$18,MATCH(B12,'Headcount Phasing'!$A$3:$A$18,0),MATCH($I$2,'Headcount Phasing'!$B$2:$M$2,0))) -> 458050.88 | J12: =(_xlfn.XLOOKUP(B12,'Annual Employer Cost per Grade'!$C$2:$C$17,'Annual Employer Cost per Grade'!$U$2:$U$17,0,0))*(INDEX('Headcount Phasing'!$B$3:$M$18,MATCH(B12,'Headcount Phasing'!$A$3:$A$18,0),MATCH($J$2,'Headcount Phasing'!$B$2:$M$2,0))) -> 458050.88 | K12: =(_xlfn.XLOOKUP(B12,'Annual Employer Cost per Grade'!$C$2:$C$17,'Annual Employer Cost per Grade'!$U$2:$U$17,0,0))*(INDEX('Headcount Phasing'!$B$3:$M$18,MATCH(B12,'Headcount Phasing'!$A$3:$A$18,0),MATCH($K$2,'Headcount Phasing'!$B$2:$M$2,0))) -> 458050.88 | L12: =(_xlfn.XLOOKUP(B12,'Annual Employer Cost per Grade'!$C$2:$C$17,'Annual Employer Cost per Grade'!$U$2:$U$17,0,0))*(INDEX('Headcount Phasing'!$B$3:$M$18,MATCH(B12,'Headcount Phasing'!$A$3:$A$18,0),MATCH($L$2,'Headcount Phasing'!$B$2:$M$2,0))) -> 458050.88 | M12: =(_xlfn.XLOOKUP(B12,'Annual Employer Cost per Grade'!$C$2:$C$17,'Annual Employer Cost per Grade'!$U$2:$U$17,0,0))*(INDEX('Headcount Phasing'!$B$3:$M$18,MATCH(B12,'Headcount Phasing'!$A$3:$A$18,0),MATCH($M$2,'Headcount Phasing'!$B$2:$M$2,0))) -> 458050.88 | N12: =(_xlfn.XLOOKUP(B12,'Annual Employer Cost per Grade'!$C$2:$C$17,'Annual Employer Cost per Grade'!$U$2:$U$17,0,0))*(INDEX('Headcount Phasing'!$B$3:$M$18,MATCH(B12,'Headcount Phasing'!$A$3:$A$18,0),MATCH($N$2,'Headcount Phasing'!$B$2:$M$2,0))) -> 458050.88 | O12: =SUM(C12:N12) -> 4122457.9
A13: =A12+1 -> 11 | B13: Content & Digital Marketing Lead | C13: =(_xlfn.XLOOKUP(B13,'Annual Employer Cost per Grade'!$C$2:$C$17,'Annual Employer Cost per Grade'!$U$2:$U$17,0,0))*(INDEX('Headcount Phasing'!$B$3:$M$18,MATCH(B13,'Headcount Phasing'!$A$3:$A$18,0),MATCH($C$2,'Headcount Phasing'!$B$2:$M$2,0))) -> 0 | D13: =(_xlfn.XLOOKUP(B13,'Annual Employer Cost per Grade'!$C$2:$C$17,'Annual Employer Cost per Grade'!$U$2:$U$17,0,0))*(INDEX('Headcount Phasing'!$B$3:$M$18,MATCH(B13,'Headcount Phasing'!$A$3:$A$18,0),MATCH($D$2,'Headcount Phasing'!$B$2:$M$2,0))) -> 0 | E13: =(_xlfn.XLOOKUP(B13,'Annual Employer Cost per Grade'!$C$2:$C$17,'Annual Employer Cost per Grade'!$U$2:$U$17,0,0))*(INDEX('Headcount Phasing'!$B$3:$M$18,MATCH(B13,'Headcount Phasing'!$A$3:$A$18,0),MATCH($E$2,'Headcount Phasing'!$B$2:$M$2,0))) -> 0 | F13: =(_xlfn.XLOOKUP(B13,'Annual Employer Cost per Grade'!$C$2:$C$17,'Annual Employer Cost per Grade'!$U$2:$U$17,0,0))*(INDEX('Headcount Phasing'!$B$3:$M$18,MATCH(B13,'Headcount Phasing'!$A$3:$A$18,0),MATCH($F$2,'Headcount Phasing'!$B$2:$M$2,0))) -> 465550.88 | G13: =(_xlfn.XLOOKUP(B13,'Annual Employer Cost per Grade'!$C$2:$C$17,'Annual Employer Cost per Grade'!$U$2:$U$17,0,0))*(INDEX('Headcount Phasing'!$B$3:$M$18,MATCH(B13,'Headcount Phasing'!$A$3:$A$18,0),MATCH($G$2,'Headcount Phasing'!$B$2:$M$2,0))) -> 465550.88 | H13: =(_xlfn.XLOOKUP(B13,'Annual Employer Cost per Grade'!$C$2:$C$17,'Annual Employer Cost per Grade'!$U$2:$U$17,0,0))*(INDEX('Headcount Phasing'!$B$3:$M$18,MATCH(B13,'Headcount Phasing'!$A$3:$A$18,0),MATCH($H$2,'Headcount Phasing'!$B$2:$M$2,0))) -> 465550.88 | I13: =(_xlfn.XLOOKUP(B13,'Annual Employer Cost per Grade'!$C$2:$C$17,'Annual Employer Cost per Grade'!$U$2:$U$17,0,0))*(INDEX('Headcount Phasing'!$B$3:$M$18,MATCH(B13,'Headcount Phasing'!$A$3:$A$18,0),MATCH($I$2,'Headcount Phasing'!$B$2:$M$2,0))) -> 465550.88 | J13: =(_xlfn.XLOOKUP(B13,'Annual Employer Cost per Grade'!$C$2:$C$17,'Annual Employer Cost per Grade'!$U$2:$U$17,0,0))*(INDEX('Headcount Phasing'!$B$3:$M$18,MATCH(B13,'Headcount Phasing'!$A$3:$A$18,0),MATCH($J$2,'Headcount Phasing'!$B$2:$M$2,0))) -> 465550.88 | K13: =(_xlfn.XLOOKUP(B13,'Annual Employer Cost per Grade'!$C$2:$C$17,'Annual Employer Cost per Grade'!$U$2:$U$17,0,0))*(INDEX('Headcount Phasing'!$B$3:$M$18,MATCH(B13,'Headcount Phasing'!$A$3:$A$18,0),MATCH($K$2,'Headcount Phasing'!$B$2:$M$2,0))) -> 465550.88 | L13: =(_xlfn.XLOOKUP(B13,'Annual Employer Cost per Grade'!$C$2:$C$17,'Annual Employer Cost per Grade'!$U$2:$U$17,0,0))*(INDEX('Headcount Phasing'!$B$3:$M$18,MATCH(B13,'Headcount Phasing'!$A$3:$A$18,0),MATCH($L$2,'Headcount Phasing'!$B$2:$M$2,0))) -> 465550.88 | M13: =(_xlfn.XLOOKUP(B13,'Annual Employer Cost per Grade'!$C$2:$C$17,'Annual Employer Cost per Grade'!$U$2:$U$17,0,0))*(INDEX('Headcount Phasing'!$B$3:$M$18,MATCH(B13,'Headcount Phasing'!$A$3:$A$18,0),MATCH($M$2,'Headcount Phasing'!$B$2:$M$2,0))) -> 465550.88 | N13: =(_xlfn.XLOOKUP(B13,'Annual Employer Cost per Grade'!$C$2:$C$17,'Annual Employer Cost per Grade'!$U$2:$U$17,0,0))*(INDEX('Headcount Phasing'!$B$3:$M$18,MATCH(B13,'Headcount Phasing'!$A$3:$A$18,0),MATCH($N$2,'Headcount Phasing'!$B$2:$M$2,0))) -> 465550.88 | O13: =SUM(C13:N13) -> 4189957.9
A14: =A13+1 -> 12 | B14: Graphic & Multimedia Associate | C14: =(_xlfn.XLOOKUP(B14,'Annual Employer Cost per Grade'!$C$2:$C$17,'Annual Employer Cost per Grade'!$U$2:$U$17,0,0))*(INDEX('Headcount Phasing'!$B$3:$M$18,MATCH(B14,'Headcount Phasing'!$A$3:$A$18,0),MATCH($C$2,'Headcount Phasing'!$B$2:$M$2,0))) -> 0 | D14: =(_xlfn.XLOOKUP(B14,'Annual Employer Cost per Grade'!$C$2:$C$17,'Annual Employer Cost per Grade'!$U$2:$U$17,0,0))*(INDEX('Headcount Phasing'!$B$3:$M$18,MATCH(B14,'Headcount Phasing'!$A$3:$A$18,0),MATCH($D$2,'Headcount Phasing'!$B$2:$M$2,0))) -> 0 | E14: =(_xlfn.XLOOKUP(B14,'Annual Employer Cost per Grade'!$C$2:$C$17,'Annual Employer Cost per Grade'!$U$2:$U$17,0,0))*(INDEX('Headcount Phasing'!$B$3:$M$18,MATCH(B14,'Headcount Phasing'!$A$3:$A$18,0),MATCH($E$2,'Headcount Phasing'!$B$2:$M$2,0))) -> 0 | F14: =(_xlfn.XLOOKUP(B14,'Annual Employer Cost per Grade'!$C$2:$C$17,'Annual Employer Cost per Grade'!$U$2:$U$17,0,0))*(INDEX('Headcount Phasing'!$B$3:$M$18,MATCH(B14,'Headcount Phasing'!$A$3:$A$18,0),MATCH($F$2,'Headcount Phasing'!$B$2:$M$2,0))) -> 465550.88 | G14: =(_xlfn.XLOOKUP(B14,'Annual Employer Cost per Grade'!$C$2:$C$17,'Annual Employer Cost per Grade'!$U$2:$U$17,0,0))*(INDEX('Headcount Phasing'!$B$3:$M$18,MATCH(B14,'Headcount Phasing'!$A$3:$A$18,0),MATCH($G$2,'Headcount Phasing'!$B$2:$M$2,0))) -> 465550.88 | H14: =(_xlfn.XLOOKUP(B14,'Annual Employer Cost per Grade'!$C$2:$C$17,'Annual Employer Cost per Grade'!$U$2:$U$17,0,0))*(INDEX('Headcount Phasing'!$B$3:$M$18,MATCH(B14,'Headcount Phasing'!$A$3:$A$18,0),MATCH($H$2,'Headcount Phasing'!$B$2:$M$2,0))) -> 465550.88 | I14: =(_xlfn.XLOOKUP(B14,'Annual Employer Cost per Grade'!$C$2:$C$17,'Annual Employer Cost per Grade'!$U$2:$U$17,0,0))*(INDEX('Headcount Phasing'!$B$3:$M$18,MATCH(B14,'Headcount Phasing'!$A$3:$A$18,0),MATCH($I$2,'Headcount Phasing'!$B$2:$M$2,0))) -> 465550.88 | J14: =(_xlfn.XLOOKUP(B14,'Annual Employer Cost per Grade'!$C$2:$C$17,'Annual Employer Cost per Grade'!$U$2:$U$17,0,0))*(INDEX('Headcount Phasing'!$B$3:$M$18,MATCH(B14,'Headcount Phasing'!$A$3:$A$18,0),MATCH($J$2,'Headcount Phasing'!$B$2:$M$2,0))) -> 465550.88 | K14: =(_xlfn.XLOOKUP(B14,'Annual Employer Cost per Grade'!$C$2:$C$17,'Annual Employer Cost per Grade'!$U$2:$U$17,0,0))*(INDEX('Headcount Phasing'!$B$3:$M$18,MATCH(B14,'Headcount Phasing'!$A$3:$A$18,0),MATCH($K$2,'Headcount Phasing'!$B$2:$M$2,0))) -> 465550.88 | L14: =(_xlfn.XLOOKUP(B14,'Annual Employer Cost per Grade'!$C$2:$C$17,'Annual Employer Cost per Grade'!$U$2:$U$17,0,0))*(INDEX('Headcount Phasing'!$B$3:$M$18,MATCH(B14,'Headcount Phasing'!$A$3:$A$18,0),MATCH($L$2,'Headcount Phasing'!$B$2:$M$2,0))) -> 465550.88 | M14: =(_xlfn.XLOOKUP(B14,'Annual Employer Cost per Grade'!$C$2:$C$17,'Annual Employer Cost per Grade'!$U$2:$U$17,0,0))*(INDEX('Headcount Phasing'!$B$3:$M$18,MATCH(B14,'Headcount Phasing'!$A$3:$A$18,0),MATCH($M$2,'Headcount Phasing'!$B$2:$M$2,0))) -> 465550.88 | N14: =(_xlfn.XLOOKUP(B14,'Annual Employer Cost per Grade'!$C$2:$C$17,'Annual Employer Cost per Grade'!$U$2:$U$17,0,0))*(INDEX('Headcount Phasing'!$B$3:$M$18,MATCH(B14,'Headcount Phasing'!$A$3:$A$18,0),MATCH($N$2,'Headcount Phasing'!$B$2:$M$2,0))) -> 465550.88 | O14: =SUM(C14:N14) -> 4189957.9
A15: =A14+1 -> 13 | B15: Facility Technician (x3) | C15: =(_xlfn.XLOOKUP(B15,'Annual Employer Cost per Grade'!$C$2:$C$17,'Annual Employer Cost per Grade'!$U$2:$U$17,0,0))*(INDEX('Headcount Phasing'!$B$3:$M$18,MATCH(B15,'Headcount Phasing'!$A$3:$A$18,0),MATCH($C$2,'Headcount Phasing'!$B$2:$M$2,0))) -> 0 | D15: =(_xlfn.XLOOKUP(B15,'Annual Employer Cost per Grade'!$C$2:$C$17,'Annual Employer Cost per Grade'!$U$2:$U$17,0,0))*(INDEX('Headcount Phasing'!$B$3:$M$18,MATCH(B15,'Headcount Phasing'!$A$3:$A$18,0),MATCH($D$2,'Headcount Phasing'!$B$2:$M$2,0))) -> 0 | E15: =(_xlfn.XLOOKUP(B15,'Annual Employer Cost per Grade'!$C$2:$C$17,'Annual Employer Cost per Grade'!$U$2:$U$17,0,0))*(INDEX('Headcount Phasing'!$B$3:$M$18,MATCH(B15,'Headcount Phasing'!$A$3:$A$18,0),MATCH($E$2,'Headcount Phasing'!$B$2:$M$2,0))) -> 0 | F15: =(_xlfn.XLOOKUP(B15,'Annual Employer Cost per Grade'!$C$2:$C$17,'Annual Employer Cost per Grade'!$U$2:$U$17,0,0))*(INDEX('Headcount Phasing'!$B$3:$M$18,MATCH(B15,'Headcount Phasing'!$A$3:$A$18,0),MATCH($F$2,'Headcount Phasing'!$B$2:$M$2,0))) -> 231183.15 | G15: =(_xlfn.XLOOKUP(B15,'Annual Employer Cost per Grade'!$C$2:$C$17,'Annual Employer Cost per Grade'!$U$2:$U$17,0,0))*(INDEX('Headcount Phasing'!$B$3:$M$18,MATCH(B15,'Headcount Phasing'!$A$3:$A$18,0),MATCH($G$2,'Headcount Phasing'!$B$2:$M$2,0))) -> 231183.15 | H15: =(_xlfn.XLOOKUP(B15,'Annual Employer Cost per Grade'!$C$2:$C$17,'Annual Employer Cost per Grade'!$U$2:$U$17,0,0))*(INDEX('Headcount Phasing'!$B$3:$M$18,MATCH(B15,'Headcount Phasing'!$A$3:$A$18,0),MATCH($H$2,'Headcount Phasing'!$B$2:$M$2,0))) -> 231183.15 | I15: =(_xlfn.XLOOKUP(B15,'Annual Employer Cost per Grade'!$C$2:$C$17,'Annual Employer Cost per Grade'!$U$2:$U$17,0,0))*(INDEX('Headcount Phasing'!$B$3:$M$18,MATCH(B15,'Headcount Phasing'!$A$3:$A$18,0),MATCH($I$2,'Headcount Phasing'!$B$2:$M$2,0))) -> 231183.15 | J15: =(_xlfn.XLOOKUP(B15,'Annual Employer Cost per Grade'!$C$2:$C$17,'Annual Employer Cost per Grade'!$U$2:$U$17,0,0))*(INDEX('Headcount Phasing'!$B$3:$M$18,MATCH(B15,'Headcount Phasing'!$A$3:$A$18,0),MATCH($J$2,'Headcount Phasing'!$B$2:$M$2,0))) -> 231183.15 | K15: =(_xlfn.XLOOKUP(B15,'Annual Employer Cost per Grade'!$C$2:$C$17,'Annual Employer Cost per Grade'!$U$2:$U$17,0,0))*(INDEX('Headcount Phasing'!$B$3:$M$18,MATCH(B15,'Headcount Phasing'!$A$3:$A$18,0),MATCH($K$2,'Headcount Phasing'!$B$2:$M$2,0))) -> 231183.15 | L15: =(_xlfn.XLOOKUP(B15,'Annual Employer Cost per Grade'!$C$2:$C$17,'Annual Employer Cost per Grade'!$U$2:$U$17,0,0))*(INDEX('Headcount Phasing'!$B$3:$M$18,MATCH(B15,'Headcount Phasing'!$A$3:$A$18,0),MATCH($L$2,'Headcount Phasing'!$B$2:$M$2,0))) -> 231183.15 | M15: =(_xlfn.XLOOKUP(B15,'Annual Employer Cost per Grade'!$C$2:$C$17,'Annual Employer Cost per Grade'!$U$2:$U$17,0,0))*(INDEX('Headcount Phasing'!$B$3:$M$18,MATCH(B15,'Headcount Phasing'!$A$3:$A$18,0),MATCH($M$2,'Headcount Phasing'!$B$2:$M$2,0))) -> 231183.15 | N15: =(_xlfn.XLOOKUP(B15,'Annual Employer Cost per Grade'!$C$2:$C$17,'Annual Employer Cost per Grade'!$U$2:$U$17,0,0))*(INDEX('Headcount Phasing'!$B$3:$M$18,MATCH(B15,'Headcount Phasing'!$A$3:$A$18,0),MATCH($N$2,'Headcount Phasing'!$B$2:$M$2,0))) -> 231183.15 | O15: =SUM(C15:N15) -> 2080648.3
A16: =A15+1 -> 14 | B16: Driver | C16: =(_xlfn.XLOOKUP(B16,'Annual Employer Cost per Grade'!$C$2:$C$17,'Annual Employer Cost per Grade'!$U$2:$U$17,0,0))*(INDEX('Headcount Phasing'!$B$3:$M$18,MATCH(B16,'Headcount Phasing'!$A$3:$A$18,0),MATCH($C$2,'Headcount Phasing'!$B$2:$M$2,0))) -> 0 | D16: =(_xlfn.XLOOKUP(B16,'Annual Employer Cost per Grade'!$C$2:$C$17,'Annual Employer Cost per Grade'!$U$2:$U$17,0,0))*(INDEX('Headcount Phasing'!$B$3:$M$18,MATCH(B16,'Headcount Phasing'!$A$3:$A$18,0),MATCH($D$2,'Headcount Phasing'!$B$2:$M$2,0))) -> 0 | E16: =(_xlfn.XLOOKUP(B16,'Annual Employer Cost per Grade'!$C$2:$C$17,'Annual Employer Cost per Grade'!$U$2:$U$17,0,0))*(INDEX('Headcount Phasing'!$B$3:$M$18,MATCH(B16,'Headcount Phasing'!$A$3:$A$18,0),MATCH($E$2,'Headcount Phasing'!$B$2:$M$2,0))) -> 231183.15 | F16: =(_xlfn.XLOOKUP(B16,'Annual Employer Cost per Grade'!$C$2:$C$17,'Annual Employer Cost per Grade'!$U$2:$U$17,0,0))*(INDEX('Headcount Phasing'!$B$3:$M$18,MATCH(B16,'Headcount Phasing'!$A$3:$A$18,0),MATCH($F$2,'Headcount Phasing'!$B$2:$M$2,0))) -> 231183.15 | G16: =(_xlfn.XLOOKUP(B16,'Annual Employer Cost per Grade'!$C$2:$C$17,'Annual Employer Cost per Grade'!$U$2:$U$17,0,0))*(INDEX('Headcount Phasing'!$B$3:$M$18,MATCH(B16,'Headcount Phasing'!$A$3:$A$18,0),MATCH($G$2,'Headcount Phasing'!$B$2:$M$2,0))) -> 462366.29 | H16: =(_xlfn.XLOOKUP(B16,'Annual Employer Cost per Grade'!$C$2:$C$17,'Annual Employer Cost per Grade'!$U$2:$U$17,0,0))*(INDEX('Headcount Phasing'!$B$3:$M$18,MATCH(B16,'Headcount Phasing'!$A$3:$A$18,0),MATCH($H$2,'Headcount Phasing'!$B$2:$M$2,0))) -> 462366.29 | I16: =(_xlfn.XLOOKUP(B16,'Annual Employer Cost per Grade'!$C$2:$C$17,'Annual Employer Cost per Grade'!$U$2:$U$17,0,0))*(INDEX('Headcount Phasing'!$B$3:$M$18,MATCH(B16,'Headcount Phasing'!$A$3:$A$18,0),MATCH($I$2,'Headcount Phasing'!$B$2:$M$2,0))) -> 462366.29 | J16: =(_xlfn.XLOOKUP(B16,'Annual Employer Cost per Grade'!$C$2:$C$17,'Annual Employer Cost per Grade'!$U$2:$U$17,0,0))*(INDEX('Headcount Phasing'!$B$3:$M$18,MATCH(B16,'Headcount Phasing'!$A$3:$A$18,0),MATCH($J$2,'Headcount Phasing'!$B$2:$M$2,0))) -> 462366.29 | K16: =(_xlfn.XLOOKUP(B16,'Annual Employer Cost per Grade'!$C$2:$C$17,'Annual Employer Cost per Grade'!$U$2:$U$17,0,0))*(INDEX('Headcount Phasing'!$B$3:$M$18,MATCH(B16,'Headcount Phasing'!$A$3:$A$18,0),MATCH($K$2,'Headcount Phasing'!$B$2:$M$2,0))) -> 462366.29 | L16: =(_xlfn.XLOOKUP(B16,'Annual Employer Cost per Grade'!$C$2:$C$17,'Annual Employer Cost per Grade'!$U$2:$U$17,0,0))*(INDEX('Headcount Phasing'!$B$3:$M$18,MATCH(B16,'Headcount Phasing'!$A$3:$A$18,0),MATCH($L$2,'Headcount Phasing'!$B$2:$M$2,0))) -> 462366.29 | M16: =(_xlfn.XLOOKUP(B16,'Annual Employer Cost per Grade'!$C$2:$C$17,'Annual Employer Cost per Grade'!$U$2:$U$17,0,0))*(INDEX('Headcount Phasing'!$B$3:$M$18,MATCH(B16,'Headcount Phasing'!$A$3:$A$18,0),MATCH($M$2,'Headcount Phasing'!$B$2:$M$2,0))) -> 462366.29 | N16: =(_xlfn.XLOOKUP(B16,'Annual Employer Cost per Grade'!$C$2:$C$17,'Annual Employer Cost per Grade'!$U$2:$U$17,0,0))*(INDEX('Headcount Phasing'!$B$3:$M$18,MATCH(B16,'Headcount Phasing'!$A$3:$A$18,0),MATCH($N$2,'Headcount Phasing'!$B$2:$M$2,0))) -> 462366.29 | O16: =SUM(C16:N16) -> 4161296.6
A17: =A16+1 -> 15 | B17: NYSC Intern (x3) | C17: =(_xlfn.XLOOKUP(B17,'Annual Employer Cost per Grade'!$C$2:$C$17,'Annual Employer Cost per Grade'!$U$2:$U$17,0,0))*(INDEX('Headcount Phasing'!$B$3:$M$18,MATCH(B17,'Headcount Phasing'!$A$3:$A$18,0),MATCH($C$2,'Headcount Phasing'!$B$2:$M$2,0))) -> 0 | D17: =(_xlfn.XLOOKUP(B17,'Annual Employer Cost per Grade'!$C$2:$C$17,'Annual Employer Cost per Grade'!$U$2:$U$17,0,0))*(INDEX('Headcount Phasing'!$B$3:$M$18,MATCH(B17,'Headcount Phasing'!$A$3:$A$18,0),MATCH($D$2,'Headcount Phasing'!$B$2:$M$2,0))) -> 0 | E17: =(_xlfn.XLOOKUP(B17,'Annual Employer Cost per Grade'!$C$2:$C$17,'Annual Employer Cost per Grade'!$U$2:$U$17,0,0))*(INDEX('Headcount Phasing'!$B$3:$M$18,MATCH(B17,'Headcount Phasing'!$A$3:$A$18,0),MATCH($E$2,'Headcount Phasing'!$B$2:$M$2,0))) -> 0 | F17: =(_xlfn.XLOOKUP(B17,'Annual Employer Cost per Grade'!$C$2:$C$17,'Annual Employer Cost per Grade'!$U$2:$U$17,0,0))*(INDEX('Headcount Phasing'!$B$3:$M$18,MATCH(B17,'Headcount Phasing'!$A$3:$A$18,0),MATCH($F$2,'Headcount Phasing'!$B$2:$M$2,0))) -> 0 | G17: =(_xlfn.XLOOKUP(B17,'Annual Employer Cost per Grade'!$C$2:$C$17,'Annual Employer Cost per Grade'!$U$2:$U$17,0,0))*(INDEX('Headcount Phasing'!$B$3:$M$18,MATCH(B17,'Headcount Phasing'!$A$3:$A$18,0),MATCH($G$2,'Headcount Phasing'!$B$2:$M$2,0))) -> 199189.62 | H17: =(_xlfn.XLOOKUP(B17,'Annual Employer Cost per Grade'!$C$2:$C$17,'Annual Employer Cost per Grade'!$U$2:$U$17,0,0))*(INDEX('Headcount Phasing'!$B$3:$M$18,MATCH(B17,'Headcount Phasing'!$A$3:$A$18,0),MATCH($H$2,'Headcount Phasing'!$B$2:$M$2,0))) -> 199189.62 | I17: =(_xlfn.XLOOKUP(B17,'Annual Employer Cost per Grade'!$C$2:$C$17,'Annual Employer Cost per Grade'!$U$2:$U$17,0,0))*(INDEX('Headcount Phasing'!$B$3:$M$18,MATCH(B17,'Headcount Phasing'!$A$3:$A$18,0),MATCH($I$2,'Headcount Phasing'!$B$2:$M$2,0))) -> 199189.62 | J17: =(_xlfn.XLOOKUP(B17,'Annual Employer Cost per Grade'!$C$2:$C$17,'Annual Employer Cost per Grade'!$U$2:$U$17,0,0))*(INDEX('Headcount Phasing'!$B$3:$M$18,MATCH(B17,'Headcount Phasing'!$A$3:$A$18,0),MATCH($J$2,'Headcount Phasing'!$B$2:$M$2,0))) -> 199189.62 | K17: =(_xlfn.XLOOKUP(B17,'Annual Employer Cost per Grade'!$C$2:$C$17,'Annual Employer Cost per Grade'!$U$2:$U$17,0,0))*(INDEX('Headcount Phasing'!$B$3:$M$18,MATCH(B17,'Headcount Phasing'!$A$3:$A$18,0),MATCH($K$2,'Headcount Phasing'!$B$2:$M$2,0))) -> 199189.62 | L17: =(_xlfn.XLOOKUP(B17,'Annual Employer Cost per Grade'!$C$2:$C$17,'Annual Employer Cost per Grade'!$U$2:$U$17,0,0))*(INDEX('Headcount Phasing'!$B$3:$M$18,MATCH(B17,'Headcount Phasing'!$A$3:$A$18,0),MATCH($L$2,'Headcount Phasing'!$B$2:$M$2,0))) -> 199189.62 | M17: =(_xlfn.XLOOKUP(B17,'Annual Employer Cost per Grade'!$C$2:$C$17,'Annual Employer Cost per Grade'!$U$2:$U$17,0,0))*(INDEX('Headcount Phasing'!$B$3:$M$18,MATCH(B17,'Headcount Phasing'!$A$3:$A$18,0),MATCH($M$2,'Headcount Phasing'!$B$2:$M$2,0))) -> 199189.62 | N17: =(_xlfn.XLOOKUP(B17,'Annual Employer Cost per Grade'!$C$2:$C$17,'Annual Employer Cost per Grade'!$U$2:$U$17,0,0))*(INDEX('Headcount Phasing'!$B$3:$M$18,MATCH(B17,'Headcount Phasing'!$A$3:$A$18,0),MATCH($N$2,'Headcount Phasing'!$B$2:$M$2,0))) -> 199189.62 | O17: =SUM(C17:N17) -> 1593517
A18: =A17+1 -> 16 | B18: Student Intern (x3) | C18: =(_xlfn.XLOOKUP(B18,'Annual Employer Cost per Grade'!$C$2:$C$17,'Annual Employer Cost per Grade'!$U$2:$U$17,0,0))*(INDEX('Headcount Phasing'!$B$3:$M$18,MATCH(B18,'Headcount Phasing'!$A$3:$A$18,0),MATCH($C$2,'Headcount Phasing'!$B$2:$M$2,0))) -> 0 | D18: =(_xlfn.XLOOKUP(B18,'Annual Employer Cost per Grade'!$C$2:$C$17,'Annual Employer Cost per Grade'!$U$2:$U$17,0,0))*(INDEX('Headcount Phasing'!$B$3:$M$18,MATCH(B18,'Headcount Phasing'!$A$3:$A$18,0),MATCH($D$2,'Headcount Phasing'!$B$2:$M$2,0))) -> 0 | E18: =(_xlfn.XLOOKUP(B18,'Annual Employer Cost per Grade'!$C$2:$C$17,'Annual Employer Cost per Grade'!$U$2:$U$17,0,0))*(INDEX('Headcount Phasing'!$B$3:$M$18,MATCH(B18,'Headcount Phasing'!$A$3:$A$18,0),MATCH($E$2,'Headcount Phasing'!$B$2:$M$2,0))) -> 0 | F18: =(_xlfn.XLOOKUP(B18,'Annual Employer Cost per Grade'!$C$2:$C$17,'Annual Employer Cost per Grade'!$U$2:$U$17,0,0))*(INDEX('Headcount Phasing'!$B$3:$M$18,MATCH(B18,'Headcount Phasing'!$A$3:$A$18,0),MATCH($F$2,'Headcount Phasing'!$B$2:$M$2,0))) -> 240702 | G18: =(_xlfn.XLOOKUP(B18,'Annual Employer Cost per Grade'!$C$2:$C$17,'Annual Employer Cost per Grade'!$U$2:$U$17,0,0))*(INDEX('Headcount Phasing'!$B$3:$M$18,MATCH(B18,'Headcount Phasing'!$A$3:$A$18,0),MATCH($G$2,'Headcount Phasing'!$B$2:$M$2,0))) -> 240702 | H18: =(_xlfn.XLOOKUP(B18,'Annual Employer Cost per Grade'!$C$2:$C$17,'Annual Employer Cost per Grade'!$U$2:$U$17,0,0))*(INDEX('Headcount Phasing'!$B$3:$M$18,MATCH(B18,'Headcount Phasing'!$A$3:$A$18,0),MATCH($H$2,'Headcount Phasing'!$B$2:$M$2,0))) -> 240702 | I18: =(_xlfn.XLOOKUP(B18,'Annual Employer Cost per Grade'!$C$2:$C$17,'Annual Employer Cost per Grade'!$U$2:$U$17,0,0))*(INDEX('Headcount Phasing'!$B$3:$M$18,MATCH(B18,'Headcount Phasing'!$A$3:$A$18,0),MATCH($I$2,'Headcount Phasing'!$B$2:$M$2,0))) -> 240702 | J18: =(_xlfn.XLOOKUP(B18,'Annual Employer Cost per Grade'!$C$2:$C$17,'Annual Employer Cost per Grade'!$U$2:$U$17,0,0))*(INDEX('Headcount Phasing'!$B$3:$M$18,MATCH(B18,'Headcount Phasing'!$A$3:$A$18,0),MATCH($J$2,'Headcount Phasing'!$B$2:$M$2,0))) -> 240702 | K18: =(_xlfn.XLOOKUP(B18,'Annual Employer Cost per Grade'!$C$2:$C$17,'Annual Employer Cost per Grade'!$U$2:$U$17,0,0))*(INDEX('Headcount Phasing'!$B$3:$M$18,MATCH(B18,'Headcount Phasing'!$A$3:$A$18,0),MATCH($K$2,'Headcount Phasing'!$B$2:$M$2,0))) -> 240702 | L18: =(_xlfn.XLOOKUP(B18,'Annual Employer Cost per Grade'!$C$2:$C$17,'Annual Employer Cost per Grade'!$U$2:$U$17,0,0))*(INDEX('Headcount Phasing'!$B$3:$M$18,MATCH(B18,'Headcount Phasing'!$A$3:$A$18,0),MATCH($L$2,'Headcount Phasing'!$B$2:$M$2,0))) -> 240702 | M18: =(_xlfn.XLOOKUP(B18,'Annual Employer Cost per Grade'!$C$2:$C$17,'Annual Employer Cost per Grade'!$U$2:$U$17,0,0))*(INDEX('Headcount Phasing'!$B$3:$M$18,MATCH(B18,'Headcount Phasing'!$A$3:$A$18,0),MATCH($M$2,'Headcount Phasing'!$B$2:$M$2,0))) -> 240702 | N18: =(_xlfn.XLOOKUP(B18,'Annual Employer Cost per Grade'!$C$2:$C$17,'Annual Employer Cost per Grade'!$U$2:$U$17,0,0))*(INDEX('Headcount Phasing'!$B$3:$M$18,MATCH(B18,'Headcount Phasing'!$A$3:$A$18,0),MATCH($N$2,'Headcount Phasing'!$B$2:$M$2,0))) -> 240702 | O18: =SUM(C18:N18) -> 2166318
B19: Total | C19: =SUM(C3:C18) -> 0 | D19: =SUM(D3:D18) -> 0 | E19: =SUM(E3:E18) -> 6418849.8 | F19: =SUM(F3:F18) -> 15152263 | G19: =SUM(G3:G18) -> 15582636 | H19: =SUM(H3:H18) -> 15582636 | I19: =SUM(I3:I18) -> 15582636 | J19: =SUM(J3:J18) -> 15582636 | ... O19: =SUM(O3:O18) -> 1.462322e+08
M29: reduction
L30: 2.3501734e+08 | M30: =L30-O19 -> 88785135
M31: =(L30-O19)/L30 -> 0.37778122

Sheet Headcount Phasing
A2: Grade | B2: Jan | C2: Feb | D2: Mar | E2: Apr | F2: May | G2: Jun | H2: Jul | I2: Aug | J2: Sep | K2: Oct | L2: Nov | M2: Dec | N2: Total Number of Months
A3: Managing Director | B3: 0 | C3: 0 | D3: 1 | E3: 1 | F3: 1 | G3: 1 | H3: 1 | I3: 1 | J3: 1 | K3: 1 | L3: 1 | M3: 1 | N3: 10
A4: Director of Programs | B4: 0 | C4: 0 | D4: 0 | E4: 1 | F4: 1 | G4: 1 | H4: 1 | I4: 1 | J4: 1 | K4: 1 | L4: 1 | M4: 1 | N4: 9
A5: IT Manager | B5: 0 | C5: 0 | D5: 0 | E5: 1 | F5: 1 | G5: 1 | H5: 1 | I5: 1 | J5: 1 | K5: 1 | L5: 1 | M5: 1 | N5: 9
A6: Community Manager | B6: 0 | C6: 0 | D6: 0 | E6: 1 | F6: 1 | G6: 1 | H6: 1 | I6: 1 | J6: 1 | K6: 1 | L6: 1 | M6: 1 | N6: 9
A7: Facility Associate | B7: 0 | C7: 0 | D7: 0 | E7: 1 | F7: 1 | G7: 1 | H7: 1 | I7: 1 | J7: 1 | K7: 1 | L7: 1 | M7: 1 | N7: 9
A8: Front Desk Associate (x1) | B8: 0 | C8: 0 | D8: 0 | E8: 1 | F8: 1 | G8: 1 | H8: 1 | I8: 1 | J8: 1 | K8: 1 | L8: 1 | M8: 1 | N8: 9
A9: Front Desk Support (Tech Grade 1) | B9: 0 | C9: 0 | D9: 0 | E9: 1 | F9: 1 | G9: 1 | H9: 1 | I9: 1 | J9: 1 | K9: 1 | L9: 1 | M9: 1 | N9: 9
A10: Finance Associate | B10: 0 | C10: 0 | D10: 0 | E10: 1 | F10: 1 | G10: 1 | H10: 1 | I10: 1 | J10: 1 | K10: 1 | L10: 1 | M10: 1 | N10: 9
A11: Admin & HR Associate | B11: 0 | C11: 0 | D11: 0 | E11: 1 | F11: 1 | G11: 1 | H11: 1 | I11: 1 | J11: 1 | K11: 1 | L11: 1 | M11: 1 | N11: 9
A12: IT Support Associate (x2) | B12: 0 | C12: 0 | D12: 0 | E12: 1 | F12: 1 | G12: 1 | H12: 1 | I12: 1 | J12: 1 | K12: 1 | L12: 1 | M12: 1 | N12: 9
A13: Content & Digital Marketing Lead | B13: 0 | C13: 0 | D13: 0 | E13: 1 | F13: 1 | G13: 1 | H13: 1 | I13: 1 | J13: 1 | K13: 1 | L13: 1 | M13: 1 | N13: 9
A14: Graphic & Multimedia Associate | B14: 0 | C14: 0 | D14: 0 | E14: 1 | F14: 1 | G14: 1 | H14: 1 | I14: 1 | J14: 1 | K14: 1 | L14: 1 | M14: 1 | N14: 9
... A18: Student Intern (x3) | B18: 0 | C18: 0 | D18: 0 | E18: 3 | F18: 3 | G18: 3 | H18: 3 | I18: 3 | J18: 3 | K18: 3 | L18: 3 | M18: 3 | N18: 10

Sheet Annual Cost Summary
A1: S/N | B1: Job Role | C1: Headcount | D1: Unit HC | E1: Total Annual Gross | F1: Total Leave Allowance | G1: Total 13th Month | H1: Total Bonus Pot | I1: Telephone | J1: Airtime | K1: Mobile Data Plan | L1: Total Cafeteria Subsidy | M1: Total Health Insurance | N1: Employer Pension Contr. | O1: Group Life Insurance Premium Cost | P1: ITF Cost | Q1: NSITF (ECS) | R1: Annual Employer Cost | T1: Monthly Employer Cost | U1: Total Nos. of Months | V1: Total Cost For 2025 | Z1: Range
A2: 1 | B2: Managing Director | C2: 1 | D2: 1 | E2: ='Annual Employer Cost per Grade'!F2*D2 -> 57120000 | F2: ='Annual Employer Cost per Grade'!G2*'Annual Cost Summary'!D2 -> 3998400 | G2: ='Annual Employer Cost per Grade'!H2*'Annual Cost Summary'!D2 -> 3998400 | H2: ='Annual Employer Cost per Grade'!I2*'Annual Cost Summary'!D2 -> 0 | I2: ='Annual Employer Cost per Grade'!J2*'Annual Cost Summary'!D2 -> 200000 | J2: ='Annual Employer Cost per Grade'!K2*'Annual Cost Summary'!D2 -> 300000 | K2: ='Annual Employer Cost per Grade'!L2*'Annual Cost Summary'!D2 -> 0 | L2: ='Annual Employer Cost per Grade'!M2*'Annual Cost Summary'!D2 -> 312000 | M2: ='Annual Employer Cost per Grade'!N2*'Annual Cost Summary'!D2 -> 954720 | N2: ='Annual Employer Cost per Grade'!O2*'Annual Cost Summary'!D2 -> 5140800 | O2: ='Annual Employer Cost per Grade'!P2*'Annual Cost Summary'!D2 -> 925344 | P2: ='Annual Employer Cost per Grade'!Q2*'Annual Cost Summary'!D2 -> 651168 | Q2: ='Annual Employer Cost per Grade'!R2*'Annual Cost Summary'!D2 -> 651168 | R2: =SUM(E2:Q2) -> 74252000 | T2: =R2/12 -> 6187666.7 | U2: =VLOOKUP(B2,'Headcount Phasing'!$A$3:$N$18,14,FALSE) -> 10 | V2: =U2*T2 -> 61876667 | Z2: G4
A3: =A2+1 -> 2 | B3: Director of Programs | C3: 1 | D3: 1 | E3: ='Annual Employer Cost per Grade'!F3*D3 -> 32520000 | F3: ='Annual Employer Cost per Grade'!G3*'Annual Cost Summary'!D3 -> 2276400 | G3: ='Annual Employer Cost per Grade'!H3*'Annual Cost Summary'!D3 -> 2276400 | H3: ='Annual Employer Cost per Grade'!I3*'Annual Cost Summary'!D3 -> 0 | I3: ='Annual Employer Cost per Grade'!J3*'Annual Cost Summary'!D3 -> 200000 | J3: ='Annual Employer Cost per Grade'!K3*'Annual Cost Summary'!D3 -> 300000 | K3: ='Annual Employer Cost per Grade'!L3*'Annual Cost Summary'!D3 -> 0 | L3: ='Annual Employer Cost per Grade'!M3*'Annual Cost Summary'!D3 -> 312000 | M3: ='Annual Employer Cost per Grade'!N3*'Annual Cost Summary'!D3 -> 585975 | N3: ='Annual Employer Cost per Grade'!O3*'Annual Cost Summary'!D3 -> 2926800 | O3: ='Annual Employer Cost per Grade'!P3*'Annual Cost Summary'!D3 -> 526824 | P3: ='Annual Employer Cost per Grade'!Q3*'Annual Cost Summary'!D3 -> 370728 | Q3: ='Annual Employer Cost per Grade'!R3*'Annual Cost Summary'!D3 -> 370728 | R3: =SUM(E3:Q3) -> 42665855 | T3: =R3/12 -> 3555487.9 | U3: =VLOOKUP(B3,'Headcount Phasing'!$A$3:$N$18,14,FALSE) -> 9 | V3: =U3*T3 -> 31999391 | Z3: G5
A4: =A3+1 -> 3 | B4: IT Manager | C4: 1 | D4: 1 | E4: ='Annual Employer Cost per Grade'!F4*D4 -> 6660000 | F4: ='Annual Employer Cost per Grade'!G4*'Annual Cost Summary'!D4 -> 466200 | G4: ='Annual Employer Cost per Grade'!H4*'Annual Cost Summary'!D4 -> 466200 | H4: ='Annual Employer Cost per Grade'!I4*'Annual Cost Summary'!D4 -> 0 | I4: ='Annual Employer Cost per Grade'!J4*'Annual Cost Summary'!D4 -> 150000 | J4: ='Annual Employer Cost per Grade'!K4*'Annual Cost Summary'!D4 -> 180000 | K4: ='Annual Employer Cost per Grade'!L4*'Annual Cost Summary'!D4 -> 0 | L4: ='Annual Employer Cost per Grade'!M4*'Annual Cost Summary'!D4 -> 312000 | M4: ='Annual Employer Cost per Grade'!N4*'Annual Cost Summary'!D4 -> 254826 | N4: ='Annual Employer Cost per Grade'!O4*'Annual Cost Summary'!D4 -> 599400 | O4: ='Annual Employer Cost per Grade'!P4*'Annual Cost Summary'!D4 -> 107892 | P4: ='Annual Employer Cost per Grade'!Q4*'Annual Cost Summary'!D4 -> 75924 | Q4: ='Annual Employer Cost per Grade'!R4*'Annual Cost Summary'!D4 -> 75924 | R4: =SUM(E4:Q4) -> 9348366 | T4: =R4/12 -> 779030.5 | U4: =VLOOKUP(B4,'Headcount Phasing'!$A$3:$N$18,14,FALSE) -> 9 | V4: =U4*T4 -> 7011274.5 | Z4: G6
