Workbook

Sheet BUDGET 
A2: Category | B2: Description | D2: 45741 | E2: 45748 | F2: 45778 | G2: 45809 | H2: 45863 | I2: 45894 | J2: 45925 | K2: 45955 | L2: 45986 | M2: 46016 | N2: FY 2025 | O2: Comment/Justification | P2: One Time
A4: Items in green have been paid for the entire year as Q2 one-time costs | E4: =#REF!/3 -> #REF!
E5: =E4*3 -> #REF!
A7: Kwara State Government Grants | B7: Public sector funding | N7: =SUM(E7:G7) -> 0
A8: IHS Operational Funds | B8: Corporate partnerships & sponsorships | D8: 6908850 | F8: 133916648 | H8: =104296540-C16 -> 85159576 | K8: =100000000+C16 -> 1.1913696e+08 | N8: =SUM(D8:M8) -> 345122038
A9: Membership Fees | B9: Fees from startups & researchers | N9: =SUM(E9:G9) -> 0
A10: Consulting & Advisory Services | B10: Consulting services revenue | N10: =SUM(E10:G10) -> 0
A11: Event Hosting & Sponsorships | B11: Revenue from events & hackathons | E11: ='[1]Rental, Hosting & Sponsorships'!F12 -> 0 | F11: ='[1]Rental, Hosting & Sponsorships'!G12 -> 0 | G11: ='[1]Rental, Hosting & Sponsorships'!H12 -> 0 | N11: =SUM(E11:G11) -> 0
A12: Facility Rentals | E12: ='[1]Rental, Hosting & Sponsorships'!F6 -> 0 | F12: ='[1]Rental, Hosting & Sponsorships'!G6 -> 0 | G12: ='[1]Rental, Hosting & Sponsorships'!H6 -> 0 | N12: =SUM(E12:G12) -> 0
A13: Other Income | B13: Miscellaneous revenue | N13: =SUM(E13:G13) -> 0
D14: =SUM(D6:D13) -> 6908850 | E14: =SUM(E6:E13) -> 0 | F14: =SUM(F6:F13) -> 133916648 | G14: =SUM(G6:G13) -> 0 | H14: =SUM(H6:H13) -> 85159576 | I14: =SUM(I6:I13) -> 0 | J14: =SUM(J6:J13) -> 0 | K14: =SUM(K6:K13) -> 1.1913696e+08 | ... N14: =SUM(N6:N13) -> 345122038
C16: 19136964
A19: Salaries & Wages | B19: Staff salaries, mentors | D19: =[1]Salaries1!E19 -> 6418849.8 | E19: =[1]Salaries1!F19 -> 6659551.8 | F19: =[1]Salaries1!G40 -> 15298345 | G19: =[1]Salaries1!H19 -> 16040687 | H19: =[1]Salaries1!I19 -> 16040687 | I19: =[1]Salaries1!J19 -> 16040687 | J19: =[1]Salaries1!K19 -> 16040687 | K19: =[1]Salaries1!L19 -> 16040687 | L19: =[1]Salaries1!M19 -> 16040687 | M19: =[1]Salaries1!N19+[1]Salaries1!N19 -> 32081374 | N19: =SUM(D19:M19) -> 1.5670224e+08
A22: Utilities & Maintenance | B22: Rent, utilities, internet, security, cleaning
A23: Internet A Subscription (MTN) 45Mbps | F23: =1201234*8 -> 9609872 | N23: =SUM(D23:M23) -> 9609872 | O23: Till 2025 year end (8 months)
A24: Internet A Setup Cost (MTN) | F24: =1982000 -> 1982000 | N24: =SUM(D24:M24) -> 1982000 | O24: Last mile fiber + installation
A25: Internet B Subscription (Starlink) | F25: =38000*8 -> 304000 | N25: =SUM(D25:M25) -> 304000 | O25: Till 2025 year end (8 months)
A26: Internet B Device (Starlink) | F26: 679000 | N26: =SUM(D26:M26) -> 679000 | O26: Device Cost (Femtech IT, Ilorin)
A27: Internet B Installation (Starlink) | F27: 200000 | N27: =SUM(D27:M27) -> 200000 | O27: Installation + any required additional materials
A28: Cleaning | D28: 240000 | E28: 240000 | F28: 1328000 | G28: 1328000 | H28: 1328000 | I28: 1328000 | J28: 1328000 | K28: 1328000 | L28: 1328000 | M28: 1328000 | N28: =SUM(D28:M28) -> 11104000 | O28: 11 man cleaning team & consumables
A29: Landscaping | F29: 300000 | G29: 300000 | H29: 300000 | I29: 300000 | J29: 300000 | K29: 300000 | L29: 300000 | M29: 300000 | N29: =SUM(D29:M29) -> 2400000
A30: Facility Maintenance & Repairs | E30: =172000+136000+300000+800000+4429000 -> 5837000 | F30: 1500000 | G30: 1500000 | H30: 1500000 | I30: 1500000 | J30: 1500000 | K30: 1500000 | L30: 1500000 | M30: 1500000 | N30: =SUM(D30:M30) -> 17837000 | O30: Conservative estimate for repairs
A31: Security | F31: 1000000 | G31: 1000000 | H31: 920000 | I31: 920000 | J31: 920000 | K31: 920000 | L31: 920000 | M31: 920000 | N31: =SUM(D31:M31) -> 7520000 | O31: 8 guards - 5 day, 3 night at N100,000/mo and 1 supervisor @N120,000/mo
A32: HVAC Maintenance (Quarterly) | G32: 2000000 | J32: 2000000 | M32: 2000000 | N32: =SUM(D32:M32) -> 6000000 | O32: As quoted by Project Manager
A33: Solar Maintenance (Biannually) | N33: =SUM(D33:M33) -> 0 | O33: As quoted by Project Manager. Not due until Q3
A34: Electrical Maintenance (Monthly) | F34: 250000 | G34: 250000 | H34: 250000 | I34: 250000 | J34: 250000 | K34: 250000 | L34: 250000 | M34: 250000 | N34: =SUM(D34:M34) -> 2000000 | O34: As quoted by Project Manager
A35: Mechanical Maintenance (Monthly) | F35: 400000 | G35: 400000 | H35: 400000 | I35: 400000 | J35: 400000 | K35: 400000 | L35: 400000 | M35: 400000 | N35: =SUM(D35:M35) -> 3200000 | O35: As quoted by Project Manager
A36: LED Screen Maintenance (Annually) | N36: =SUM(D36:M36) -> 0 | O36: Not due until next year
A37: Access Control Maintenance (Annually) | N37: =SUM(D37:M37) -> 0 | O37: Not due until next year
A38: Project Manager Professional Fee ? | E38: 3000000 | F38: 3000000 | G38: 3000000 | H38: 3000000 | I38: 3000000 | J38: 3000000 | K38: 3000000 | L38: 3000000 | M38: 3000000 | N38: =SUM(D38:M38) -> 27000000 | O38: Geniserve
A39: Provision for Spare Parts for Solar, Electrical, Mechanical, LED Screens | G39: 10735000 | N39: =SUM(D39:M39) -> 10735000 | O39: Purchase of spare parts for hardware infrastructure. As quoted by Project Manager
D40: =SUM(D23:D39) -> 240000 | E40: =SUM(E23:E39) -> 9077000 | F40: =SUM(F23:F39) -> 20552872 | G40: =SUM(G23:G39) -> 20513000 | H40: =SUM(H23:H39) -> 7698000 | I40: =SUM(I23:I39) -> 7698000 | J40: =SUM(J23:J39) -> 9698000 | K40: =SUM(K23:K39) -> 7698000 | ... N40: =SUM(N23:N39) -> 100570872
A42: Travel & Conferences | B42: 1.1 | O42: Considering 2 people
A43: International Conference Registration | F43: 2251027 | K43: =F43*B42 -> 2476129.7 | N43: =SUM(D43:M43) -> 4727156.7 | O43: Q4 Travel costs are considered at a 10% increase from Q2 costs
A44: International Travel Flights | F44: 5478430 | K44: =F44*B42 -> 6026273 | N44: =SUM(D44:M44) -> 11504703 | O44: Q4 Travel costs are considered at a 10% increase from Q2 costs
A45: International Travel Accomodation | F45: 3214346 | K45: =F45*B42 -> 3535780.6 | N45: =SUM(D45:M45) -> 6750126.6 | O45: Q4 Travel costs are considered at a 10% increase from Q2 costs
A46: International Travel Allowance | F46: 4017435 | K46: =F46 -> 4017435 | N46: =SUM(D46:M46) -> 8034870 | O46: $200 per night for 5 nights
A47: International Visa Processing | F47: 548642 | K47: =F47 -> 548642 | N47: =SUM(D47:M47) -> 1097284 | O47: €300 @ €150 visa fee per person
A48: Local Conference Registration | G48: 750000 | J48: 750000 | M48: 750000 | N48: =SUM(D48:M48) -> 2250000 | O48: Estimated to cover any local conference reg
A49: Local Conference Exhibition | G49: 2000000 | J49: 2000000 | M49: 2000000 | N49: =SUM(D49:M49) -> 6000000 | O49: Opportunity to showcase our startups at conferences
...

Sheet ACTUAL SPENT 
A1: Category | B1: Description | D1: 45741 | E1: 45748 | F1: 45778 | G1: 45809 | H1: 45863 | I1: 45894 | J1: 45925 | K1: 45955 | L1: 45986 | M1: 46016 | N1: FY 2025 | O1: Comment/Justification | P1: One Time
A3: Items in green have been paid for the entire year as Q2 one-time costs | E3: =#REF!/3 -> #REF!
E4: =E3*3 -> #REF!
A6: Kwara State Government Grants | B6: Public sector funding | N6: =SUM(D6:M6) -> 0
A7: IHS Operational Funds | B7: Corporate partnerships & sponsorships | D7: 6908850 | F7: 133916648 | H7: =104296540-C15 -> 85159576 | K7: =100000000+C15 -> 1.1913696e+08 | N7: =SUM(D7:M7) -> 345122038
A8: Membership Fees | B8: Fees from startups & researchers | N8: =SUM(D8:M8) -> 0
A9: Consulting & Advisory Services | B9: Consulting services revenue | N9: =SUM(D9:M9) -> 0
A10: Event Hosting & Sponsorships | B10: Revenue from events & hackathons | E10: ='[1]Rental, Hosting & Sponsorships'!F12 -> 0 | F10: ='[1]Rental, Hosting & Sponsorships'!G12 -> 0 | G10: ='[1]Rental, Hosting & Sponsorships'!H12 -> 0 | N10: =SUM(D10:M10) -> 0
A11: Facility Rentals | E11: ='[1]Rental, Hosting & Sponsorships'!F6 -> 0 | F11: ='[1]Rental, Hosting & Sponsorships'!G6 -> 0 | G11: ='[1]Rental, Hosting & Sponsorships'!H6 -> 0 | N11: =SUM(D11:M11) -> 0
A12: Other Income | B12: Miscellaneous revenue | N12: =SUM(D12:M12) -> 0
D13: =SUM(D5:D12) -> 6908850 | E13: =SUM(E5:E12) -> 0 | F13: =SUM(F5:F12) -> 133916648 | G13: =SUM(G5:G12) -> 0 | H13: =SUM(H5:H12) -> 85159576 | I13: =SUM(I5:I12) -> 0 | J13: =SUM(J5:J12) -> 0 | K13: =SUM(K5:K12) -> 1.1913696e+08 | ... M13: =SUM(M5:M12) -> 0 | N13: =SUM(D13:M13) -> 345122038
C15: 19136964
A18: Salaries & Wages | B18: Staff salaries, mentors | D18: 3722854.4 | E18: 3722854.4 | F18: 7356317.3 | G18: 9973607.5 | N18: =SUM(D18:M18) -> 24775634
A21: Utilities & Maintenance | B21: Rent, utilities, internet, security, cleaning
A22: Internet A Subscription (MTN) 45Mbps | G22: 2999175.8 | N22: =SUM(D22:M22) -> 2999175.8
A23: Internet A Setup Cost (MTN) | N23: =SUM(D23:M23) -> 0
A24: Internet B Subscription (Starlink) | N24: =SUM(D24:M24) -> 0
A25: Internet B Device (Starlink) | N25: =SUM(D25:M25) -> 0
A26: Internet B Installation (Starlink) | G26: 725000 | N26: =SUM(D26:M26) -> 725000
A27: Cleaning | D27: 240000 | E27: 240000 | F27: 572000 | G27: 852600 | N27: =SUM(D27:M27) -> 1904600
A28: Landscaping | G28: 860000 | N28: =SUM(D28:M28) -> 860000
A29: Facility Maintenance & Repairs | G29: 1140700 | N29: =SUM(D29:M29) -> 1140700
A30: Security | G30: 250000 | N30: =SUM(D30:M30) -> 250000
A31: HVAC Maintenance (Quarterly) | N31: =SUM(D31:M31) -> 0
A32: Solar Maintenance (Biannually) | N32: =SUM(D32:M32) -> 0
A33: Electrical Maintenance (Monthly) | N33: =SUM(D33:M33) -> 0
A34: Mechanical Maintenance (Monthly) | N34: =SUM(D34:M34) -> 0
A35: LED Screen Maintenance (Annually) | N35: =SUM(D35:M35) -> 0
A36: Access Control Maintenance (Annually) | N36: =SUM(D36:M36) -> 0
A37: Project Manager Professional Fee ? | N37: =SUM(D37:M37) -> 0
A38: Provision for Spare Parts for Solar, Electrical, Mechanical, LED Screens | G38: 1581325 | N38: =SUM(D38:M38) -> 1581325
D39: =SUM(D18:D38) -> 3962854.4 | E39: =SUM(E18:E38) -> 3962854.4 | F39: =SUM(F18:F38) -> 7928317.3 | G39: =SUM(G18:G38) -> 18382408 | H39: =SUM(H18:H38) -> 0 | I39: =SUM(I18:I38) -> 0 | J39: =SUM(J18:J38) -> 0 | K39: =SUM(K18:K38) -> 0 | ... N39: =SUM(N18:N38) -> 34236434
A41: Travel & Conferences | B41: 1.1
A42: International Conference Registration | N42: =SUM(D42:M42) -> 0
A43: International Travel Flights | N43: =SUM(D43:M43) -> 0
A44: International Travel Accomodation | N44: =SUM(D44:M44) -> 0
A45: International Travel Allowance | N45: =SUM(D45:M45) -> 0
A46: International Visa Processing | N46: =SUM(D46:M46) -> 0
A47: Local Conference Registration | N47: =SUM(D47:M47) -> 0
A48: Local Conference Exhibition | N48: =SUM(D48:M48) -> 0
...

Sheet SURPLUS AND DEFICIT
A2: Category | B2: Description | D2: 45741 | E2: 45748 | F2: 45778 | G2: 45809 | H2: 45863 | I2: 45894 | J2: 45925 | K2: 45955 | L2: 45986 | M2: 46016 | N2: FY 2025 | O2: Comment/Justification | P2: One Time
A4: Items in green have been paid for the entire year as Q2 one-time costs
A7: Kwara State Government Grants | B7: Public sector funding | N7: =SUM(D7:M7) -> 0
A8: IHS Operational Funds | B8: Corporate partnerships & sponsorships | D8: 6908850 | F8: 133916648 | H8: =104296540-C16 -> 104296540 | K8: =100000000+C16 -> 100000000 | N8: =SUM(D8:M8) -> 345122038
A9: Membership Fees | B9: Fees from startups & researchers | N9: =SUM(D9:M9) -> 0
A10: Consulting & Advisory Services | B10: Consulting services revenue | N10: =SUM(D10:M10) -> 0
A11: Event Hosting & Sponsorships | B11: Revenue from events & hackathons | E11: ='[1]Rental, Hosting & Sponsorships'!F12 -> 0 | F11: ='[1]Rental, Hosting & Sponsorships'!G12 -> 0 | G11: ='[1]Rental, Hosting & Sponsorships'!H12 -> 0 | N11: =SUM(D11:M11) -> 0
A12: Facility Rentals | E12: ='[1]Rental, Hosting & Sponsorships'!F6 -> 0 | F12: ='[1]Rental, Hosting & Sponsorships'!G6 -> 0 | G12: ='[1]Rental, Hosting & Sponsorships'!H6 -> 0 | N12: =SUM(D12:M12) -> 0
A13: Other Income | B13: Miscellaneous revenue | N13: =SUM(D13:M13) -> 0
D14: =SUM(D6:D13) -> 6908850 | E14: =SUM(E6:E13) -> 0 | F14: =SUM(F6:F13) -> 133916648 | G14: =SUM(G6:G13) -> 0 | H14: =SUM(H6:H13) -> 104296540 | I14: =SUM(I6:I13) -> 0 | J14: =SUM(J6:J13) -> 0 | K14: =SUM(K6:K13) -> 100000000 | ... M14: =SUM(M6:M13) -> 0 | N14: =SUM(D14:M14) -> 345122038
C15: 19136964
A18: Salaries & Wages | B18: Staff salaries, mentors | D18: ='BUDGET '!D19-'ACTUAL SPENT '!D18 -> 2695995.4 | E18: ='BUDGET '!E19-'ACTUAL SPENT '!E18 -> 2936697.4 | F18: ='BUDGET '!F19-'ACTUAL SPENT '!F18 -> 7942027.4 | G18: ='BUDGET '!G19-'ACTUAL SPENT '!G18 -> 6067079.3 | H18: ='BUDGET '!H19-'ACTUAL SPENT '!H18 -> 16040687 | I18: ='BUDGET '!I19-'ACTUAL SPENT '!I18 -> 16040687 | J18: ='BUDGET '!J19-'ACTUAL SPENT '!J18 -> 16040687 | K18: ='BUDGET '!K19-'ACTUAL SPENT '!K18 -> 16040687 | ... M18: ='BUDGET '!M19-'ACTUAL SPENT '!M18 -> 32081374 | N18: =SUM(D18:M18) -> 1.3192661e+08
D19: ='BUDGET '!D20-'ACTUAL SPENT '!D19 -> 0 | E19: ='BUDGET '!E20-'ACTUAL SPENT '!E19 -> 0 | F19: ='BUDGET '!F20-'ACTUAL SPENT '!F19 -> 0 | G19: ='BUDGET '!G20-'ACTUAL SPENT '!G19 -> 0 | H19: ='BUDGET '!H20-'ACTUAL SPENT '!H19 -> 0 | I19: ='BUDGET '!I20-'ACTUAL SPENT '!I19 -> 0 | J19: ='BUDGET '!J20-'ACTUAL SPENT '!J19 -> 0 | K19: ='BUDGET '!K20-'ACTUAL SPENT '!K19 -> 0 | ... M19: ='BUDGET '!M20-'ACTUAL SPENT '!M19 -> 0 | N19: =SUM(D19:M19) -> 0
D20: ='BUDGET '!D21-'ACTUAL SPENT '!D20 -> 0 | E20: ='BUDGET '!E21-'ACTUAL SPENT '!E20 -> 0 | F20: ='BUDGET '!F21-'ACTUAL SPENT '!F20 -> 0 | G20: ='BUDGET '!G21-'ACTUAL SPENT '!G20 -> 0 | H20: ='BUDGET '!H21-'ACTUAL SPENT '!H20 -> 0 | I20: ='BUDGET '!I21-'ACTUAL SPENT '!I20 -> 0 | J20: ='BUDGET '!J21-'ACTUAL SPENT '!J20 -> 0 | K20: ='BUDGET '!K21-'ACTUAL SPENT '!K20 -> 0 | ... M20: ='BUDGET '!M21-'ACTUAL SPENT '!M20 -> 0 | N20: =SUM(D20:M20) -> 0
A21: Utilities & Maintenance | B21: Rent, utilities, internet, security, cleaning | D21: ='BUDGET '!D22-'ACTUAL SPENT '!D21 -> 0 | E21: ='BUDGET '!E22-'ACTUAL SPENT '!E21 -> 0 | F21: ='BUDGET '!F22-'ACTUAL SPENT '!F21 -> 0 | G21: ='BUDGET '!G22-'ACTUAL SPENT '!G21 -> 0 | H21: ='BUDGET '!H22-'ACTUAL SPENT '!H21 -> 0 | I21: ='BUDGET '!I22-'ACTUAL SPENT '!I21 -> 0 | J21: ='BUDGET '!J22-'ACTUAL SPENT '!J21 -> 0 | K21: ='BUDGET '!K22-'ACTUAL SPENT '!K21 -> 0 | ... M21: ='BUDGET '!M22-'ACTUAL SPENT '!M21 -> 0 | N21: =SUM(D21:M21) -> 0
A22: Internet A Subscription (MTN) 45Mbps | D22: ='BUDGET '!D23-'ACTUAL SPENT '!D22 -> 0 | E22: ='BUDGET '!E23-'ACTUAL SPENT '!E22 -> 0 | F22: ='BUDGET '!F23-'ACTUAL SPENT '!F22 -> 9609872 | G22: ='BUDGET '!G23-'ACTUAL SPENT '!G22 -> -2999175.8 | H22: ='BUDGET '!H23-'ACTUAL SPENT '!H22 -> 0 | I22: ='BUDGET '!I23-'ACTUAL SPENT '!I22 -> 0 | J22: ='BUDGET '!J23-'ACTUAL SPENT '!J22 -> 0 | K22: ='BUDGET '!K23-'ACTUAL SPENT '!K22 -> 0 | ... M22: ='BUDGET '!M23-'ACTUAL SPENT '!M22 -> 0 | N22: =SUM(D22:M22) -> 6610696.2
A23: Internet A Setup Cost (MTN) | D23: ='BUDGET '!D24-'ACTUAL SPENT '!D23 -> 0 | E23: ='BUDGET '!E24-'ACTUAL SPENT '!E23 -> 0 | F23: ='BUDGET '!F24-'ACTUAL SPENT '!F23 -> 1982000 | G23: ='BUDGET '!G24-'ACTUAL SPENT '!G23 -> 0 | H23: ='BUDGET '!H24-'ACTUAL SPENT '!H23 -> 0 | I23: ='BUDGET '!I24-'ACTUAL SPENT '!I23 -> 0 | J23: ='BUDGET '!J24-'ACTUAL SPENT '!J23 -> 0 | K23: ='BUDGET '!K24-'ACTUAL SPENT '!K23 -> 0 | ... M23: ='BUDGET '!M24-'ACTUAL SPENT '!M23 -> 0 | N23: =SUM(D23:M23) -> 1982000
A24: Internet B Subscription (Starlink) | D24: ='BUDGET '!D25-'ACTUAL SPENT '!D24 -> 0 | E24: ='BUDGET '!E25-'ACTUAL SPENT '!E24 -> 0 | F24: ='BUDGET '!F25-'ACTUAL SPENT '!F24 -> 304000 | G24: ='BUDGET '!G25-'ACTUAL SPENT '!G24 -> 0 | H24: ='BUDGET '!H25-'ACTUAL SPENT '!H24 -> 0 | I24: ='BUDGET '!I25-'ACTUAL SPENT '!I24 -> 0 | J24: ='BUDGET '!J25-'ACTUAL SPENT '!J24 -> 0 | K24: ='BUDGET '!K25-'ACTUAL SPENT '!K24 -> 0 | ... M24: ='BUDGET '!M25-'ACTUAL SPENT '!M24 -> 0 | N24: =SUM(D24:M24) -> 304000
A25: Internet B Device (Starlink) | D25: ='BUDGET '!D26-'ACTUAL SPENT '!D25 -> 0 | E25: ='BUDGET '!E26-'ACTUAL SPENT '!E25 -> 0 | F25: ='BUDGET '!F26-'ACTUAL SPENT '!F25 -> 679000 | G25: ='BUDGET '!G26-'ACTUAL SPENT '!G25 -> 0 | H25: ='BUDGET '!H26-'ACTUAL SPENT '!H25 -> 0 | I25: ='BUDGET '!I26-'ACTUAL SPENT '!I25 -> 0 | J25: ='BUDGET '!J26-'ACTUAL SPENT '!J25 -> 0 | K25: ='BUDGET '!K26-'ACTUAL SPENT '!K25 -> 0 | ... M25: ='BUDGET '!M26-'ACTUAL SPENT '!M25 -> 0 | N25: =SUM(D25:M25) -> 679000
A26: Internet B Installation (Starlink) | D26: ='BUDGET '!D27-'ACTUAL SPENT '!D26 -> 0 | E26: ='BUDGET '!E27-'ACTUAL SPENT '!E26 -> 0 | F26: ='BUDGET '!F27-'ACTUAL SPENT '!F26 -> 200000 | G26: ='BUDGET '!G27-'ACTUAL SPENT '!G26 -> -725000 | H26: ='BUDGET '!H27-'ACTUAL SPENT '!H26 -> 0 | I26: ='BUDGET '!I27-'ACTUAL SPENT '!I26 -> 0 | J26: ='BUDGET '!J27-'ACTUAL SPENT '!J26 -> 0 | K26: ='BUDGET '!K27-'ACTUAL SPENT '!K26 -> 0 | ... M26: ='BUDGET '!M27-'ACTUAL SPENT '!M26 -> 0 | N26: =SUM(D26:M26) -> -525000
A27: Cleaning | D27: ='BUDGET '!D28-'ACTUAL SPENT '!D27 -> 0 | E27: ='BUDGET '!E28-'ACTUAL SPENT '!E27 -> 0 | F27: ='BUDGET '!F28-'ACTUAL SPENT '!F27 -> 756000 | G27: ='BUDGET '!G28-'ACTUAL SPENT '!G27 -> 475400 | H27: ='BUDGET '!H28-'ACTUAL SPENT '!H27 -> 1328000 | I27: ='BUDGET '!I28-'ACTUAL SPENT '!I27 -> 1328000 | J27: ='BUDGET '!J28-'ACTUAL SPENT '!J27 -> 1328000 | K27: ='BUDGET '!K28-'ACTUAL SPENT '!K27 -> 1328000 | ... M27: ='BUDGET '!M28-'ACTUAL SPENT '!M27 -> 1328000 | N27: =SUM(D27:M27) -> 9199400
A28: Landscaping | D28: ='BUDGET '!D29-'ACTUAL SPENT '!D28 -> 0 | E28: ='BUDGET '!E29-'ACTUAL SPENT '!E28 -> 0 | F28: ='BUDGET '!F29-'ACTUAL SPENT '!F28 -> 300000 | G28: ='BUDGET '!G29-'ACTUAL SPENT '!G28 -> -560000 | H28: ='BUDGET '!H29-'ACTUAL SPENT '!H28 -> 300000 | I28: ='BUDGET '!I29-'ACTUAL SPENT '!I28 -> 300000 | J28: ='BUDGET '!J29-'ACTUAL SPENT '!J28 -> 300000 | K28: ='BUDGET '!K29-'ACTUAL SPENT '!K28 -> 300000 | ... M28: ='BUDGET '!M29-'ACTUAL SPENT '!M28 -> 300000 | N28: =SUM(D28:M28) -> 1540000
A29: Facility Maintenance & Repairs | D29: ='BUDGET '!D30-'ACTUAL SPENT '!D29 -> 0 | E29: ='BUDGET '!E30-'ACTUAL SPENT '!E29 -> 5837000 | F29: ='BUDGET '!F30-'ACTUAL SPENT '!F29 -> 1500000 | G29: ='BUDGET '!G30-'ACTUAL SPENT '!G29 -> 359300 | H29: ='BUDGET '!H30-'ACTUAL SPENT '!H29 -> 1500000 | I29: ='BUDGET '!I30-'ACTUAL SPENT '!I29 -> 1500000 | J29: ='BUDGET '!J30-'ACTUAL SPENT '!J29 -> 1500000 | K29: ='BUDGET '!K30-'ACTUAL SPENT '!K29 -> 1500000 | ... M29: ='BUDGET '!M30-'ACTUAL SPENT '!M29 -> 1500000 | N29: =SUM(D29:M29) -> 16696300
A30: Security | D30: ='BUDGET '!D31-'ACTUAL SPENT '!D30 -> 0 | E30: ='BUDGET '!E31-'ACTUAL SPENT '!E30 -> 0 | F30: ='BUDGET '!F31-'ACTUAL SPENT '!F30 -> 1000000 | G30: ='BUDGET '!G31-'ACTUAL SPENT '!G30 -> 750000 | H30: ='BUDGET '!H31-'ACTUAL SPENT '!H30 -> 920000 | I30: ='BUDGET '!I31-'ACTUAL SPENT '!I30 -> 920000 | J30: ='BUDGET '!J31-'ACTUAL SPENT '!J30 -> 920000 | K30: ='BUDGET '!K31-'ACTUAL SPENT '!K30 -> 920000 | ... M30: ='BUDGET '!M31-'ACTUAL SPENT '!M30 -> 920000 | N30: =SUM(D30:M30) -> 7270000
A31: HVAC Maintenance (Quarterly) | D31: ='BUDGET '!D32-'ACTUAL SPENT '!D31 -> 0 | E31: ='BUDGET '!E32-'ACTUAL SPENT '!E31 -> 0 | F31: ='BUDGET '!F32-'ACTUAL SPENT '!F31 -> 0 | G31: ='BUDGET '!G32-'ACTUAL SPENT '!G31 -> 2000000 | H31: ='BUDGET '!H32-'ACTUAL SPENT '!H31 -> 0 | I31: ='BUDGET '!I32-'ACTUAL SPENT '!I31 -> 0 | J31: ='BUDGET '!J32-'ACTUAL SPENT '!J31 -> 2000000 | K31: ='BUDGET '!K32-'ACTUAL SPENT '!K31 -> 0 | ... M31: ='BUDGET '!M32-'ACTUAL SPENT '!M31 -> 2000000 | N31: =SUM(D31:M31) -> 6000000
A32: Solar Maintenance (Biannually) | D32: ='BUDGET '!D33-'ACTUAL SPENT '!D32 -> 0 | E32: ='BUDGET '!E33-'ACTUAL SPENT '!E32 -> 0 | F32: ='BUDGET '!F33-'ACTUAL SPENT '!F32 -> 0 | G32: ='BUDGET '!G33-'ACTUAL SPENT '!G32 -> 0 | H32: ='BUDGET '!H33-'ACTUAL SPENT '!H32 -> 0 | I32: ='BUDGET '!I33-'ACTUAL SPENT '!I32 -> 0 | J32: ='BUDGET '!J33-'ACTUAL SPENT '!J32 -> 0 | K32: ='BUDGET '!K33-'ACTUAL SPENT '!K32 -> 0 | ... M32: ='BUDGET '!M33-'ACTUAL SPENT '!M32 -> 0 | N32: =SUM(D32:M32) -> 0
A33: Electrical Maintenance (Monthly) | D33: ='BUDGET '!D34-'ACTUAL SPENT '!D33 -> 0 | E33: ='BUDGET '!E34-'ACTUAL SPENT '!E33 -> 0 | F33: ='BUDGET '!F34-'ACTUAL SPENT '!F33 -> 250000 | G33: ='BUDGET '!G34-'ACTUAL SPENT '!G33 -> 250000 | H33: ='BUDGET '!H34-'ACTUAL SPENT '!H33 -> 250000 | I33: ='BUDGET '!I34-'ACTUAL SPENT '!I33 -> 250000 | J33: ='BUDGET '!J34-'ACTUAL SPENT '!J33 -> 250000 | K33: ='BUDGET '!K34-'ACTUAL SPENT '!K33 -> 250000 | ... M33: ='BUDGET '!M34-'ACTUAL SPENT '!M33 -> 250000 | N33: =SUM(D33:M33) -> 2000000
... A38: Provision for Spare Parts for Solar, Electrical, Mechanical, LED Screens | D38: ='BUDGET '!D39-'ACTUAL SPENT '!D38 -> 0 | E38: ='BUDGET '!E39-'ACTUAL SPENT '!E38 -> 0 | F38: ='BUDGET '!F39-'ACTUAL SPENT '!F38 -> 0 | G38: ='BUDGET '!G39-'ACTUAL SPENT '!G38 -> 9153675 | H38: ='BUDGET '!H39-'ACTUAL SPENT '!H38 -> 0 | I38: ='BUDGET '!I39-'ACTUAL SPENT '!I38 -> 0 | J38: ='BUDGET '!J39-'ACTUAL SPENT '!J38 -> 0 | K38: ='BUDGET '!K39-'ACTUAL SPENT '!K38 -> 0 | ... M38: ='BUDGET '!M39-'ACTUAL SPENT '!M38 -> 0 | N38: =SUM(D38:M38) -> 9153675
D39: ='BUDGET '!D40-'ACTUAL SPENT '!D39 -> -3722854.4 | E39: ='BUDGET '!E40-'ACTUAL SPENT '!E39 -> 5114145.6 | F39: ='BUDGET '!F40-'ACTUAL SPENT '!F39 -> 12624555 | G39: ='BUDGET '!G40-'ACTUAL SPENT '!G39 -> 2130591.7 | H39: ='BUDGET '!H40-'ACTUAL SPENT '!H39 -> 7698000 | I39: ='BUDGET '!I40-'ACTUAL SPENT '!I39 -> 7698000 | J39: ='BUDGET '!J40-'ACTUAL SPENT '!J39 -> 9698000 | K39: ='BUDGET '!K40-'ACTUAL SPENT '!K39 -> 7698000 | ... M39: ='BUDGET '!M40-'ACTUAL SPENT '!M39 -> 9698000 | N39: =SUM(D39:M39) -> 66334438
D40: ='BUDGET '!D41-'ACTUAL SPENT '!D40 -> 0 | E40: ='BUDGET '!E41-'ACTUAL SPENT '!E40 -> 0 | F40: ='BUDGET '!F41-'ACTUAL SPENT '!F40 -> 0 | G40: ='BUDGET '!G41-'ACTUAL SPENT '!G40 -> 0 | H40: ='BUDGET '!H41-'ACTUAL SPENT '!H40 -> 0 | I40: ='BUDGET '!I41-'ACTUAL SPENT '!I40 -> 0 | J40: ='BUDGET '!J41-'ACTUAL SPENT '!J40 -> 0 | K40: ='BUDGET '!K41-'ACTUAL SPENT '!K40 -> 0 | ... M40: ='BUDGET '!M41-'ACTUAL SPENT '!M40 -> 0 | N40: =SUM(D40:M40) -> 0
A41: Travel & Conferences | C41: 1.1 | D41: ='BUDGET '!D42-'ACTUAL SPENT '!D41 -> 0 | E41: ='BUDGET '!E42-'ACTUAL SPENT '!E41 -> 0 | F41: ='BUDGET '!F42-'ACTUAL SPENT '!F41 -> 0 | G41: ='BUDGET '!G42-'ACTUAL SPENT '!G41 -> 0 | H41: ='BUDGET '!H42-'ACTUAL SPENT '!H41 -> 0 | I41: ='BUDGET '!I42-'ACTUAL SPENT '!I41 -> 0 | J41: ='BUDGET '!J42-'ACTUAL SPENT '!J41 -> 0 | K41: ='BUDGET '!K42-'ACTUAL SPENT '!K41 -> 0 | ... M41: ='BUDGET '!M42-'ACTUAL SPENT '!M41 -> 0 | N41: =SUM(D41:M41) -> 0
A42: International Conference Registration | D42: ='BUDGET '!D43-'ACTUAL SPENT '!D42 -> 0 | E42: ='BUDGET '!E43-'ACTUAL SPENT '!E42 -> 0 | F42: ='BUDGET '!F43-'ACTUAL SPENT '!F42 -> 2251027 | G42: ='BUDGET '!G43-'ACTUAL SPENT '!G42 -> 0 | H42: ='BUDGET '!H43-'ACTUAL SPENT '!H42 -> 0 | I42: ='BUDGET '!I43-'ACTUAL SPENT '!I42 -> 0 | J42: ='BUDGET '!J43-'ACTUAL SPENT '!J42 -> 0 | K42: ='BUDGET '!K43-'ACTUAL SPENT '!K42 -> 2476129.7 | ... M42: ='BUDGET '!M43-'ACTUAL SPENT '!M42 -> 0 | N42: =SUM(D42:M42) -> 4727156.7
A43: International Travel Flights | D43: ='BUDGET '!D44-'ACTUAL SPENT '!D43 -> 0 | E43: ='BUDGET '!E44-'ACTUAL SPENT '!E43 -> 0 | F43: ='BUDGET '!F44-'ACTUAL SPENT '!F43 -> 5478430 | G43: ='BUDGET '!G44-'ACTUAL SPENT '!G43 -> 0 | H43: ='BUDGET '!H44-'ACTUAL SPENT '!H43 -> 0 | I43: ='BUDGET '!I44-'ACTUAL SPENT '!I43 -> 0 | J43: ='BUDGET '!J44-'ACTUAL SPENT '!J43 -> 0 | K43: ='BUDGET '!K44-'ACTUAL SPENT '!K43 -> 6026273 | ... M43: ='BUDGET '!M44-'ACTUAL SPENT '!M43 -> 0 | N43: =SUM(D43:M43) -> 11504703
A44: International Travel Accomodation | D44: ='BUDGET '!D45-'ACTUAL SPENT '!D44 -> 0 | E44: ='BUDGET '!E45-'ACTUAL SPENT '!E44 -> 0 | F44: ='BUDGET '!F45-'ACTUAL SPENT '!F44 -> 3214346 | G44: ='BUDGET '!G45-'ACTUAL SPENT '!G44 -> 0 | H44: ='BUDGET '!H45-'ACTUAL SPENT '!H44 -> 0 | I44: ='BUDGET '!I45-'ACTUAL SPENT '!I44 -> 0 | J44: ='BUDGET '!J45-'ACTUAL SPENT '!J44 -> 0 | K44: ='BUDGET '!K45-'ACTUAL SPENT '!K44 -> 3535780.6 | ... M44: ='BUDGET '!M45-'ACTUAL SPENT '!M44 -> 0 | N44: =SUM(D44:M44) -> 6750126.6
A45: International Travel Allowance | D45: ='BUDGET '!D46-'ACTUAL SPENT '!D45 -> 0 | E45: ='BUDGET '!E46-'ACTUAL SPENT '!E45 -> 0 | F45: ='BUDGET '!F46-'ACTUAL SPENT '!F45 -> 4017435 | G45: ='BUDGET '!G46-'ACTUAL SPENT '!G45 -> 0 | H45: ='BUDGET '!H46-'ACTUAL SPENT '!H45 -> 0 | I45: ='BUDGET '!I46-'ACTUAL SPENT '!I45 -> 0 | J45: ='BUDGET '!J46-'ACTUAL SPENT '!J45 -> 0 | K45: ='BUDGET '!K46-'ACTUAL SPENT '!K45 -> 4017435 | ... M45: ='BUDGET '!M46-'ACTUAL SPENT '!M45 -> 0 | N45: =SUM(D45:M45) -> 8034870
A46: International Visa Processing | D46: ='BUDGET '!D47-'ACTUAL SPENT '!D46 -> 0 | E46: ='BUDGET '!E47-'ACTUAL SPENT '!E46 -> 0 | F46: ='BUDGET '!F47-'ACTUAL SPENT '!F46 -> 548642 | G46: ='BUDGET '!G47-'ACTUAL SPENT '!G46 -> 0 | H46: ='BUDGET '!H47-'ACTUAL SPENT '!H46 -> 0 | I46: ='BUDGET '!I47-'ACTUAL SPENT '!I46 -> 0 | J46: ='BUDGET '!J47-'ACTUAL SPENT '!J46 -> 0 | K46: ='BUDGET '!K47-'ACTUAL SPENT '!K46 -> 548642 | ... M46: ='BUDGET '!M47-'ACTUAL SPENT '!M46 -> 0 | N46: =SUM(D46:M46) -> 1097284
A47: Local Conference Registration | D47: ='BUDGET '!D48-'ACTUAL SPENT '!D47 -> 0 | E47: ='BUDGET '!E48-'ACTUAL SPENT '!E47 -> 0 | F47: ='BUDGET '!F48-'ACTUAL SPENT '!F47 -> 0 | G47: ='BUDGET '!G48-'ACTUAL SPENT '!G47 -> 750000 | H47: ='BUDGET '!H48-'ACTUAL SPENT '!H47 -> 0 | I47: ='BUDGET '!I48-'ACTUAL SPENT '!I47 -> 0 | J47: ='BUDGET '!J48-'ACTUAL SPENT '!J47 -> 750000 | K47: ='BUDGET '!K48-'ACTUAL SPENT '!K47 -> 0 | ... M47: ='BUDGET '!M48-'ACTUAL SPENT '!M47 -> 750000 | N47: =SUM(D47:M47) -> 2250000
A48: Local Conference Exhibition | D48: ='BUDGET '!D49-'ACTUAL SPENT '!D48 -> 0 | E48: ='BUDGET '!E49-'ACTUAL SPENT '!E48 -> 0 | F48: ='BUDGET '!F49-'ACTUAL SPENT '!F48 -> 0 | G48: ='BUDGET '!G49-'ACTUAL SPENT '!G48 -> 2000000 | H48: ='BUDGET '!H49-'ACTUAL SPENT '!H48 -> 0 | I48: ='BUDGET '!I49-'ACTUAL SPENT '!I48 -> 0 | J48: ='BUDGET '!J49-'ACTUAL SPENT '!J48 -> 2000000 | K48: ='BUDGET '!K49-'ACTUAL SPENT '!K48 -> 0 | ... M48: ='BUDGET '!M49-'ACTUAL SPENT '!M48 -> 2000000 | N48: =SUM(D48:M48) -> 6000000
A49: Local Travel | D49: ='BUDGET '!D50-'ACTUAL SPENT '!D49 -> 0 | E49: ='BUDGET '!E50-'ACTUAL SPENT '!E49 -> 0 | F49: ='BUDGET '!F50-'ACTUAL SPENT '!F49 -> 300000 | G49: ='BUDGET '!G50-'ACTUAL SPENT '!G49 -> 300000 | H49: ='BUDGET '!H50-'ACTUAL SPENT '!H49 -> 300000 | I49: ='BUDGET '!I50-'ACTUAL SPENT '!I49 -> 300000 | J49: ='BUDGET '!J50-'ACTUAL SPENT '!J49 -> 300000 | K49: ='BUDGET '!K50-'ACTUAL SPENT '!K49 -> 300000 | ... M49: ='BUDGET '!M50-'ACTUAL SPENT '!M49 -> 300000 | N49: =SUM(D49:M49) -> 2400000
D50: ='BUDGET '!D51-'ACTUAL SPENT '!D50 -> 0 | E50: ='BUDGET '!E51-'ACTUAL SPENT '!E50 -> 0 | F50: ='BUDGET '!F51-'ACTUAL SPENT '!F50 -> 15809880 | G50: ='BUDGET '!G51-'ACTUAL SPENT '!G50 -> 3050000 | H50: ='BUDGET '!H51-'ACTUAL SPENT '!H50 -> 300000 | I50: ='BUDGET '!I51-'ACTUAL SPENT '!I50 -> 300000 | J50: ='BUDGET '!J51-'ACTUAL SPENT '!J50 -> 3050000 | K50: ='BUDGET '!K51-'ACTUAL SPENT '!K50 -> 16904260 | ... M50: ='BUDGET '!M51-'ACTUAL SPENT '!M50 -> 3050000 | N50: =SUM(D50:M50) -> 42764140
...
