Workbook

Sheet Draft Budget
B2: Category | C2: Description | E2: 45658 | F2: 45689 | G2: 45717 | H2: 45748 | I2: 45778 | J2: 45809 | K2: 45839 | L2: 45870 | M2: 45901 | N2: 45931 | O2: 45962 | P2: 45992 | Q2: FY 2025
G4: =Q91 | H4: =G4/3
G5: =G4/9 | H5: =H4*3
A6: Inflows
B7: Kwara State Government Grants | C7: Public sector funding | Q7: =SUM(E7:P7)
B8: IHS Operational Funds | C8: Corporate partnerships & sponsorships | H8: 106000000 | K8: =H8 | N8: =K8 | Q8: =SUM(E8:P8)
B9: Membership Fees | C9: Fees from startups & researchers | E9: ='Membership Fees'!C5 | F9: ='Membership Fees'!D5 | Q9: =SUM(E9:P9)
B10: Consulting & Advisory Services | C10: Consulting services revenue | Q10: =SUM(E10:P10)
B11: Event Hosting & Sponsorships | C11: Revenue from events & hackathons | E11: ='Rental, Hosting & Sponsorships'!C12 | F11: ='Rental, Hosting & Sponsorships'!D12 | G11: ='Rental, Hosting & Sponsorships'!E12 | H11: ='Rental, Hosting & Sponsorships'!F12 | I11: ='Rental, Hosting & Sponsorships'!G12 | J11: ='Rental, Hosting & Sponsorships'!H12 | K11: ='Rental, Hosting & Sponsorships'!I12 | L11: ='Rental, Hosting & Sponsorships'!J12 | ... P11: ='Rental, Hosting & Sponsorships'!N12 | Q11: =SUM(E11:P11)
B12: Facility Rentals | E12: ='Rental, Hosting & Sponsorships'!C6 | F12: ='Rental, Hosting & Sponsorships'!D6 | G12: ='Rental, Hosting & Sponsorships'!E6 | H12: ='Rental, Hosting & Sponsorships'!F6 | I12: ='Rental, Hosting & Sponsorships'!G6 | J12: ='Rental, Hosting & Sponsorships'!H6 | K12: ='Rental, Hosting & Sponsorships'!I6 | L12: ='Rental, Hosting & Sponsorships'!J6 | ... P12: ='Rental, Hosting & Sponsorships'!N6 | Q12: =SUM(E12:P12)
B13: Other Income | C13: Miscellaneous revenue | Q13: =SUM(E13:P13)
A14: Total Revenue | E14: =SUM(E6:E13) | F14: =SUM(F6:F13) | G14: =SUM(G6:G13) | H14: =SUM(H6:H13) | I14: =SUM(I6:I13) | J14: =SUM(J6:J13) | K14: =SUM(K6:K13) | L14: =SUM(L6:L13) | ... Q14: =SUM(Q6:Q13)
A18: Operational Expenses
B19: Salaries & Wages | C19: Staff salaries, mentors | E19: =Salaries!F19 | F19: =Salaries!G19 | G19: =Salaries1!F27*0 | H19: 13078402 | I19: =Salaries1!H27 | J19: =Salaries1!I27 | K19: =Salaries1!J27 | L19: =Salaries1!K27 | M19: =Salaries1!L27 | N19: =Salaries1!M27 | O19: =Salaries1!N27 | P19: =Salaries1!O27 | Q19: =SUM(E19:P19)
B23: Utilities & Maintenance | C23: Rent, utilities, internet, security
B24: Internet Subscription | I24: 800000 | J24: 800000 | K24: 800000 | L24: 800000 | M24: 800000 | N24: 800000 | O24: 800000 | P24: 800000 | Q24: =SUM(E24:P24)
B25: Diesel | E25: =Diesel!C5 | F25: =Diesel!D5 | H25: =Diesel!F5 | I25: =Diesel!G5 | J25: =Diesel!H5 | K25: =Diesel!I5 | L25: =Diesel!J5 | M25: =Diesel!K5 | N25: =Diesel!L5 | O25: =Diesel!M5 | P25: =Diesel!N5 | Q25: =SUM(E25:P25)
B26: Cleaning & Landscaping | H26: =500000+1300000 | I26: 1300000 | J26: 1300000 | K26: 1300000 | L26: 1300000 | M26: 1300000 | N26: 1300000 | O26: 1300000 | P26: 1300000 | Q26: =SUM(E26:P26)
B27: Facility Maintenance & Repairs | I27: 1500000 | J27: 1000000 | K27: 833333.33 | L27: 833333.33 | M27: 833333.33 | N27: 833333.33 | O27: 833333.33 | P27: 833333.33 | Q27: =SUM(E27:P27)
B28: Security | I28: 1000000 | J28: 1000000 | K28: 1000000 | L28: 1000000 | M28: 1000000 | N28: 1000000 | O28: 1000000 | P28: 1000000 | Q28: =SUM(E28:P28)
B29: HVAC, Solar, Elevator, Access Control & LED Screen Maintenance | J29: =15000000/3 | L29: =J29 | P29: =L29 | Q29: =SUM(E29:P29)
G30: =SUM(G24:G29) | H30: =SUM(H24:H29) | I30: =SUM(I24:I29) | J30: =SUM(J24:J29) | K30: =SUM(K24:K29) | L30: =SUM(L24:L29) | M30: =SUM(M24:M29) | N30: =SUM(N24:N29) | ... Q30: =SUM(Q24:Q29)
B31: Travel & Conferences
B32: International Conference Registration | I32: 3000000 | Q32: =SUM(E32:P32)
B33: International Travel & Accomodation | I33: 7000000 | N33: 7000000 | P33: 7000000 | Q33: =SUM(E33:P33)
B34: Local Conference Registration | J34: 750000 | M34: 750000 | P34: 750000 | Q34: =SUM(E34:P34)
B35: Local Conference Exhibition | J35: 2000000 | M35: 2000000 | P35: 2000000 | Q35: =SUM(E35:P35)
B36: Local Travel | I36: 1000000 | J36: 1000000 | K36: 1000000 | O36: 1000000 | P36: 1000000 | Q36: =SUM(E36:P36)
G37: =SUM(G32:G36) | H37: =SUM(H32:H36) | I37: =SUM(I32:I36) | J37: =SUM(J32:J36) | K37: =SUM(K32:K36) | L37: =SUM(L32:L36) | M37: =SUM(M32:M36) | N37: =SUM(N32:N36) | ... Q37: =SUM(Q32:Q36)
B39: Equipment & Infrastructure | C39: Laptops, software, lab tools
B40: Cloud Servers | E40: =Others!C4 | F40: =Others!D4 | I40: =3750000/4 | K40: =3750000/4 | N40: =3750000/4 | Q40: =SUM(E40:P40)
B41: Staff Email | E41: =Others!C5 | F41: =Others!D5 | I41: =Others!E5 | J41: =Others!H5 | K41: =Others!I5 | L41: =Others!J5 | M41: =Others!K5 | N41: =Others!L5 | O41: =Others!M5 | P41: =Others!N5 | Q41: =SUM(E41:P41)
B42: Software Subscriptions & Licenses | E42: =Others!C6 | F42: =Others!D6 | I42: =Others!E6 | J42: =Others!H6 | K42: =Others!I6 | L42: =Others!J6 | M42: =Others!K6 | N42: =Others!L6 | O42: =Others!M6 | P42: =Others!N6 | Q42: =SUM(E42:P42)
B43: Access Control & Hub Management Software | I43: 6500000 | Q43: =SUM(E43:P43)
B44: Laptops | Q44: =SUM(E44:P44)
G45: =SUM(G40:G44) | H45: =SUM(H40:H44) | I45: =SUM(I40:I44) | J45: =SUM(J40:J44) | K45: =SUM(K40:K44) | L45: =SUM(L40:L44) | M45: =SUM(M40:M44) | N45: =SUM(N40:N44) | ... Q45: =SUM(Q40:Q44)
B48: Corporate Comms & PR | C48: Branding, events, PR
B49: Souvenirs | I49: 2500000 | M49: 2500000 | P49: 2500000 | Q49: =SUM(E49:P49)
B50: Guest Entertainment & Refreshments | I50: 350000 | J50: 350000 | K50: 350000 | L50: 350000 | M50: 350000 | N50: 350000 | O50: 350000 | P50: 350000 | Q50: =SUM(E50:P50)
B51: Banners | I51: 250000 | K51: 125000 | L51: 125000 | M51: 125000 | N51: 125000 | O51: 125000 | P51: 125000 | Q51: =SUM(E51:P51)
...

Sheet Full Year (2026)
B2: Category | C2: Description | E2: 46023 | F2: 46054 | G2: 46082 | H2: 46113 | I2: 46143 | J2: 46174 | K2: 46204 | L2: 46235 | M2: 46266 | N2: 46296 | O2: 46327 | P2: 46357 | Q2: FY 2026
G4: =Q116 | H4: =G4/3
G5: =G4/9 | H5: =H4*3
A6: Inflows
B7: Kwara State Government Grants | C7: Public sector funding | Q7: =SUM(E7:P7)
B8: IHS Operational Funds | C8: Corporate partnerships & sponsorships | F8: 118173383 | G8: 2644898 | H8: 2.1586157e+08 | J8: 151500000 | K8: 1.6264411e+08 | M8: 151500000 | N8: 99956712 | P8: 151500000 | Q8: =SUM(E8:P8)
B9: Membership Fees | C9: Fees from startups & researchers | E9: ='Membership Fees'!C5 | F9: ='Membership Fees'!D5 | Q9: =SUM(E9:P9)
B10: Consulting & Advisory Services | C10: Consulting services revenue | Q10: =SUM(E10:P10)
B11: Event Hosting & Sponsorships | C11: Revenue from events & hackathons | Q11: =SUM(E11:P11)
B12: Facility Rentals | E12: 3000000 | F12: 3000000 | G12: 3000000 | H12: 3000000 | I12: 3000000 | J12: 3000000 | K12: 3000000 | L12: 3000000 | M12: 3000000 | N12: 3000000 | O12: 3000000 | P12: 3000000 | Q12: =SUM(E12:P12)
B13: Other Income | C13: Miscellaneous revenue | Q13: =SUM(E13:P13)
A14: Total Revenue | E14: =SUM(E6:E13) | F14: =SUM(F6:F13) | G14: =SUM(G6:G13) | H14: =SUM(H6:H13) | I14: =SUM(I6:I13) | J14: =SUM(J6:J13) | K14: =SUM(K6:K13) | L14: =SUM(L6:L13) | ... Q14: =SUM(Q6:Q13)
A18: Operational Expenses
B19: Salaries & Wages | C19: Staff salaries, mentors | E19: =Salaries1!D27 | F19: =Salaries1!E27 | G19: =Salaries1!F27 | H19: =Salaries1!G27 | I19: =Salaries1!H27 | J19: =Salaries1!I27 | K19: =Salaries1!J27 | L19: =Salaries1!K27 | ... P19: =Salaries1!O27 | Q19: =SUM(E19:P19)
B20: Performance Bonus | P20: =Salaries1!Q27
B23: Utilities & Maintenance | C23: Rent, utilities, internet, security
B24: Internet A Subscription (MTN) 155Mbps STM1 | E24: 1710550 | F24: 1710550 | G24: 1710550 | H24: 1710550 | I24: 1710550 | J24: 1710550 | K24: 1710550 | L24: 1710550 | M24: 1710550 | N24: 1710550 | O24: 1710550 | P24: 1710550 | Q24: =SUM(E24:P24)
B25: Internet B Subscription (Starlink) | E25: 159000 | F25: 159000 | G25: 159000 | H25: 159000 | I25: 159000 | J25: 159000 | K25: 159000 | L25: 159000 | M25: 159000 | N25: 159000 | O25: 159000 | P25: 159000 | Q25: =SUM(E25:P25)
B26: Internet C Subscription (Mobile Starlink Mini) | Q26: =SUM(E26:P26)
B27: Diesel | E27: =Diesel!C5 | F27: =Diesel!D5 | G27: =Diesel!E5 | H27: =Diesel!F5 | I27: =Diesel!G5 | J27: =Diesel!H5 | K27: =Diesel!I5 | L27: =Diesel!J5 | ... P27: =Diesel!N5 | Q27: 0
B28: Electricity Bill (Band B) | E28: 500000 | F28: 500000 | G28: 500000 | H28: 500000 | I28: 500000 | J28: 500000 | K28: 500000 | L28: 500000 | M28: 500000 | N28: 500000 | O28: 500000 | P28: 500000 | Q28: =SUM(E28:P28)
B29: Professional Cleaning | E29: 1300000 | F29: 1300000 | G29: 1300000 | H29: 1300000 | I29: 1300000 | J29: 1300000 | K29: 1300000 | L29: 1300000 | M29: 1300000 | N29: 1300000 | O29: 1300000 | P29: 1300000 | Q29: =SUM(E29:P29)
B30: Landscaping | E30: 500000 | F30: 500000 | G30: 500000 | H30: 500000 | I30: 500000 | J30: 500000 | K30: 500000 | L30: 500000 | M30: 500000 | N30: 500000 | O30: 500000 | P30: 500000 | Q30: =SUM(E30:P30)
B31: Fumigation (Indoor + Outdoor) | E31: 550000 | H31: 550000 | K31: 550000 | N31: 550000 | Q31: =SUM(E31:P31)
B32: Facility Maintenance & Repairs (Electrical) | E32: 500000 | F32: 500000 | G32: 500000 | H32: 500000 | I32: 500000 | J32: 500000 | K32: 500000 | L32: 500000 | M32: 500000 | N32: 500000 | O32: 500000 | P32: 500000 | Q32: =SUM(E32:P32)
B33: Facility Maintenance & Repairs (Civil & mechanical) | E33: 500000 | F33: 500000 | G33: 500000 | H33: 500000 | I33: 500000 | J33: 500000 | K33: 500000 | L33: 500000 | M33: 500000 | N33: 500000 | O33: 500000 | P33: 500000 | Q33: =SUM(E33:P33)
B34: Security | E34: 1000000 | F34: 1000000 | G34: 1000000 | H34: 1000000 | I34: 1000000 | J34: 1000000 | K34: 1000000 | L34: 1000000 | M34: 1000000 | N34: 1000000 | O34: 1000000 | P34: 1000000 | Q34: =SUM(E34:P34)
B35: HVAC Maintenance (Quarterly) | F35: 2000000 | I35: 2000000 | L35: 2000000 | O35: 2000000 | P35: =M35 | Q35: =SUM(F35:P35)
B36: Solar Maintenance (Twice annually) | E36: 4000000 | K36: 4000000 | P36: =L36 | Q36: =SUM(E36:P36)
B37: Elevator Maintenance | P37: =L37 | Q37: =SUM(E37:P37)
B38: Access Control Maintenance | G38: 500000 | P38: =L38 | Q38: =SUM(E38:P38)
B39: LED Screen Maintenance | G39: 2500000 | P39: =L39 | Q39: =SUM(E39:P39)
E41: =SUM(E24:E39) | F41: =SUM(F24:F39) | G41: =SUM(G24:G39) | H41: =SUM(H24:H39) | I41: =SUM(I24:I39) | J41: =SUM(J24:J39) | K41: =SUM(K24:K39) | L41: =SUM(L24:L39) | ... Q41: =SUM(Q24:Q39)
B42: Travel & Conferences
B43: International Conference Registration | F43: 3000000 | I43: 3000000 | L43: 3000000 | O43: 0 | Q43: 9000000
B44: International Flights | F44: 4000000 | I44: 4000000 | L44: 4000000 | O44: 0 | Q44: 12000000
B45: International Travel Allowance | F45: 2300000 | I45: 2300000 | L45: 2300000 | O45: 0 | Q45: 6900000
B46: International Travel Accomodation | F46: 1500000 | I46: 1500000 | L46: 1500000 | O46: 0 | Q46: 4500000
B47: Local Conference Registration | G47: 750000 | J47: 750000 | M47: 750000 | P47: 750000 | Q47: =SUM(E47:P47)
B48: Local Travel Flights | E48: 1000000 | F48: 1000000 | G48: 1000000 | H48: 1000000 | I48: 1000000 | J48: 1000000 | K48: 1000000 | L48: 1000000 | M48: 1000000 | N48: 1000000 | O48: 1000000 | P48: 1000000 | Q48: =SUM(E48:P48)
...

Sheet Full Year (2025)
B2: Category | C2: Description | E2: 45741 | F2: 45748 | G2: 45778 | H2: 45809 | I2: 45863 | J2: 45894 | K2: 45925 | L2: 45955 | M2: 45986 | N2: 46016 | O2: FY 2025 | P2: Comment/Justification | Q2: One Time | R2: Code
B4: Items in green have been paid for the entire year as Q2 one-time costs | F4: =#REF!/3
F5: =F4*3
A6: Inflows
B7: Kwara State Government Grants | C7: Public sector funding | O7: =SUM(F7:H7)
B8: IHS Operational Funds | C8: Corporate partnerships & sponsorships | E8: 6908850 | G8: 133916648 | I8: =104296540-D16 | L8: =100000000+D16 | O8: =SUM(E8:N8)
B9: Membership Fees | C9: Fees from startups & researchers | O9: =SUM(F9:H9)
B10: Consulting & Advisory Services | C10: Consulting services revenue | O10: =SUM(F10:H10)
B11: Event Hosting & Sponsorships | C11: Revenue from events & hackathons | F11: ='Rental, Hosting & Sponsorships'!F12 | G11: ='Rental, Hosting & Sponsorships'!G12 | H11: ='Rental, Hosting & Sponsorships'!H12 | O11: =SUM(F11:H11)
B12: Facility Rentals | F12: ='Rental, Hosting & Sponsorships'!F6 | G12: ='Rental, Hosting & Sponsorships'!G6 | H12: ='Rental, Hosting & Sponsorships'!H6 | O12: =SUM(F12:H12)
B13: Other Income | C13: Miscellaneous revenue | O13: =SUM(F13:H13)
A14: Total Revenue | E14: =SUM(E6:E13) | F14: =SUM(F6:F13) | G14: =SUM(G6:G13) | H14: =SUM(H6:H13) | I14: =SUM(I6:I13) | J14: =SUM(J6:J13) | K14: =SUM(K6:K13) | L14: =SUM(L6:L13) | ... O14: =SUM(O6:O13)
D16: 19136964
A18: Operational Expenses
B19: Salaries & Wages | C19: Staff salaries, mentors | E19: =Salaries1!F27 | F19: =Salaries1!G27 | G19: =Salaries1!H48 | H19: =Salaries1!I27 | I19: =Salaries1!J27 | J19: =Salaries1!K27 | K19: =Salaries1!L27 | L19: =Salaries1!M27 | M19: =Salaries1!N27 | N19: =Salaries1!O27+Salaries1!O27 | O19: =SUM(E19:N19)
B22: Utilities & Maintenance | C22: Rent, utilities, internet, security, cleaning
B23: Internet A Subscription (MTN) 45Mbps | G23: =1201234*8 | O23: =SUM(E23:N23) | P23: Till 2025 year end (8 months)
B24: Internet A Setup Cost (MTN) | G24: =1982000 | O24: =SUM(E24:N24) | P24: Last mile fiber + installation
B25: Internet B Subscription (Starlink) | G25: =38000*8 | O25: =SUM(E25:N25) | P25: Till 2025 year end (8 months)
B26: Internet B Device (Starlink) | G26: 679000 | O26: =SUM(E26:N26) | P26: Device Cost (Femtech IT, Ilorin)
B27: Internet B Installation (Starlink) | G27: 200000 | O27: =SUM(E27:N27) | P27: Installation + any required additional materials
B28: Cleaning | E28: 240000 | F28: 240000 | G28: 1328000 | H28: 1328000 | I28: 1328000 | J28: 1328000 | K28: 1328000 | L28: 1328000 | M28: 1328000 | N28: 1328000 | O28: =SUM(E28:N28) | P28: 11 man cleaning team & consumables
B29: Landscaping | G29: 300000 | H29: 300000 | I29: 300000 | J29: 300000 | K29: 300000 | L29: 300000 | M29: 300000 | N29: 300000 | O29: =SUM(E29:N29)
B30: Facility Maintenance & Repairs | F30: =172000+136000+300000+800000+4429000 | G30: 1500000 | H30: 1500000 | I30: 1500000 | J30: 1500000 | K30: 1500000 | L30: 1500000 | M30: 1500000 | N30: 1500000 | O30: =SUM(E30:N30) | P30: Conservative estimate for repairs
B31: Security | G31: 1000000 | H31: 1000000 | I31: 920000 | J31: 920000 | K31: 920000 | L31: 920000 | M31: 920000 | N31: 920000 | O31: =SUM(E31:N31) | P31: 8 guards - 5 day, 3 night at N100,000/mo and 1 supervisor @N120,000/mo
B32: HVAC Maintenance (Quarterly) | H32: 2000000 | K32: 2000000 | N32: 2000000 | O32: =SUM(E32:N32) | P32: As quoted by Project Manager
B33: Solar Maintenance (Biannually) | O33: =SUM(E33:N33) | P33: As quoted by Project Manager. Not due until Q3
B34: Electrical Maintenance (Monthly) | G34: 250000 | H34: 250000 | I34: 250000 | J34: 250000 | K34: 250000 | L34: 250000 | M34: 250000 | N34: 250000 | O34: =SUM(E34:N34) | P34: As quoted by Project Manager
B35: Mechanical Maintenance (Monthly) | G35: 400000 | H35: 400000 | I35: 400000 | J35: 400000 | K35: 400000 | L35: 400000 | M35: 400000 | N35: 400000 | O35: =SUM(E35:N35) | P35: As quoted by Project Manager
B36: LED Screen Maintenance (Annually) | O36: =SUM(E36:N36) | P36: Not due until next year
B37: Access Control Maintenance (Annually) | O37: =SUM(E37:N37) | P37: Not due until next year
B38: Project Manager Professional Fee ? | F38: 3000000 | G38: 3000000 | H38: 3000000 | I38: 3000000 | J38: 3000000 | K38: 3000000 | L38: 3000000 | M38: 3000000 | N38: 3000000 | O38: =SUM(E38:N38) | P38: Geniserve
B39: Provision for Spare Parts for Solar, Electrical, Mechanical, LED Screens | H39: 10735000 | O39: =SUM(E39:N39) | P39: Purchase of spare parts for hardware infrastructure. As quoted by Project Manager
E40: =SUM(E23:E39) | F40: =SUM(F23:F39) | G40: =SUM(G23:G39) | H40: =SUM(H23:H39) | I40: =SUM(I23:I39) | J40: =SUM(J23:J39) | K40: =SUM(K23:K39) | L40: =SUM(L23:L39) | ... O40: =SUM(O23:O39)
B42: Travel & Conferences | C42: 1.1 | P42: Considering 2 people
B43: International Conference Registration | G43: 2251027 | L43: =G43*C42 | O43: =SUM(E43:N43) | P43: Q4 Travel costs are considered at a 10% increase from Q2 costs
B44: International Travel Flights | G44: 5478430 | L44: =G44*C42 | O44: =SUM(E44:N44) | P44: Q4 Travel costs are considered at a 10% increase from Q2 costs
B45: International Travel Accomodation | G45: 3214346 | L45: =G45*C42 | O45: =SUM(E45:N45) | P45: Q4 Travel costs are considered at a 10% increase from Q2 costs
B46: International Travel Allowance | G46: 4017435 | L46: =G46 | O46: =SUM(E46:N46) | P46: $200 per night for 5 nights
B47: International Visa Processing | G47: 548642 | L47: =G47 | O47: =SUM(E47:N47) | P47: €300 @ €150 visa fee per person
...

Sheet Quarterly (Q3)
B2: Category | C2: Description | E2: 45863 | F2: 45894 | G2: 45925 | H2: FY 2025 | I2: Comment/Justification | J2: One Time
A5: Inflows
B6: Kwara State Government Grants | C6: Public sector funding | H6: =SUM(#REF!)
B7: IHS Operational Funds | C7: Corporate partnerships & sponsorships | E7: 85159573 | H7: =SUM(E7:G7)
B8: Membership Fees | C8: Fees from startups & researchers | H8: =SUM(#REF!)
B9: Consulting & Advisory Services | C9: Consulting services revenue | H9: =SUM(#REF!)
B10: Event Hosting & Sponsorships | C10: Revenue from events & hackathons | H10: =SUM(#REF!)
B11: Facility Rentals | H11: =SUM(#REF!)
B12: Other Income | C12: Miscellaneous revenue | H12: =SUM(#REF!)
A13: Total Revenue | E13: =SUM(E5:E12) | F13: =SUM(F5:F12) | G13: =SUM(G5:G12) | H13: =SUM(H5:H12)
D15: 19136964
A17: Operational Expenses
B18: Salaries & Wages | C18: Staff salaries, mentors | E18: =Salaries1!J27 | F18: =Salaries1!K27 | G18: =Salaries1!L27 | H18: =SUM(E18:G18)
B21: Utilities & Maintenance | C21: Rent, utilities, internet, security, cleaning
B22: Cleaning | E22: 1328000 | F22: 1328000 | G22: 1328000 | H22: =SUM(E22:G22) | I22: 11 man cleaning team & consumables
B23: Landscaping | E23: 300000 | F23: 300000 | G23: 300000 | H23: =SUM(E23:G23)
B24: Facility Maintenance & Repairs | E24: 1500000 | F24: 1500000 | G24: 1500000 | H24: =SUM(E24:G24) | I24: Conservative estimate for repairs
B25: Security | E25: 920000 | F25: 920000 | G25: 920000 | H25: =SUM(E25:G25) | I25: 8 guards - 5 day, 3 night at N100,000/mo and 1 supervisor @N120,000/mo
B26: HVAC Maintenance (Quarterly) | G26: 2000000 | H26: =SUM(E26:G26) | I26: As quoted by Project Manager
B27: Electrical Maintenance (Monthly) | E27: 250000 | F27: 250000 | G27: 250000 | H27: =SUM(E27:G27) | I27: As quoted by Project Manager
B28: Mechanical Maintenance (Monthly) | E28: 400000 | F28: 400000 | G28: 400000 | H28: =SUM(E28:G28) | I28: As quoted by Project Manager
B29: Additional Furniture & Building Modifications | E29: 3000000 | F29: 3000000 | G29: 3000000 | H29: =SUM(E29:G29) | I29: These needs have been discovered post-operations launch
E30: =SUM(E22:E29) | F30: =SUM(F22:F29) | G30: =SUM(G22:G29) | H30: =SUM(H22:H29)
B32: Travel & Conferences | C32: 1.1 | I32: Considering 2 people
B33: Local Conference Registration | G33: 750000 | H33: =SUM(E33:G33) | I33: Estimated to cover any local conference reg
B34: Local Conference Exhibition | G34: 2000000 | H34: =SUM(E34:G34) | I34: Opportunity to showcase our startups at conferences
B35: Local Travel | E35: 300000 | F35: 300000 | G35: 300000 | H35: =SUM(E35:G35) | I35: Assuming N150,000 per flight within Nigeria
E36: =SUM(E33:E35) | F36: =SUM(F33:F35) | G36: =SUM(G33:G35) | H36: =SUM(H33:H35)
B40: Corporate Comms & PR | C40: Branding, PR
B41: Guest Entertainment & Refreshments | E41: 350000 | F41: 350000 | G41: 350000 | H41: =SUM(E41:G41) | I41: For hosting guests
B42: Online & Social Media Marketing | E42: 250000 | F42: 250000 | G42: 250000 | H42: =SUM(E42:G42) | I42: Paid online ads
E43: =SUM(E41:E42) | F43: =SUM(F41:F42) | G43: =SUM(G41:G42) | H43: =SUM(H41:H42)
B45: Administrative Costs | C45: Office admin costs & supplies
B46: Stationery & Office Supplies | E46: 150000 | F46: 150000 | G46: 150000 | H46: =SUM(E46:G46) | I46: Printer toner, water, tea, coffee
E47: =SUM(E46:E46) | F47: =SUM(F46:F46) | G47: =SUM(G46:G46) | H47: =SUM(H46:H46)
B50: Total Operational Expenses | E50: =SUM(E47,E43,E36,E30,E18) | F50: =SUM(F47,F43,F36,F30,F18) | G50: =SUM(G47,G43,G36,G30,G18) | H50: =SUM(E50:G50)
A54: Innovation & Program Support | H54: =SUM(#REF!)
B55: Monthly Meetups | C55: Startup acceleration & support | E55: =Others!I12 | F55: =Others!J12 | G55: =Others!K12 | H55: =SUM(E55:G55) | I55: Networking events like Founders Match or hosted event support - tags, refreshments etc
B56: Field Events | E56: 200000 | F56: 200000 | G56: 200000 | H56: =SUM(E56:G56) | I56: Campus outreach events around Ilorin (UNILORIN, KWASU, Landmark, Al-Hikmah etc
B57: Webinars | E57: 136000 | F57: 136000 | G57: 136000 | H57: =SUM(E57:G57) | I57: Zoom webinar subscription @ $79/mo
...

Sheet Quarterly (Q2)
B2: Category | C2: Description | E2: 45741 | F2: 45748 | G2: 45778 | H2: 45809 | I2: Q2 2025 | J2: Comment/Justification | K2: One Time
B4: Items in green have been paid for the entire year as Q2 one-time costs | F4: =#REF!/3
F5: =F4*3
A6: Inflows
B7: Kwara State Government Grants | C7: Public sector funding | I7: =SUM(F7:H7)
B8: IHS Operational Funds | C8: Corporate partnerships & sponsorships | G8: 133916648 | I8: =SUM(G8:H8)
B9: Membership Fees | C9: Fees from startups & coworking members | I9: =SUM(F9:H9)
B10: Consulting & Advisory Services | C10: Consulting services revenue | I10: =SUM(F10:H10)
B11: Event Hosting & Sponsorships | C11: Revenue from events & hackathons | F11: ='Rental, Hosting & Sponsorships'!F12 | G11: ='Rental, Hosting & Sponsorships'!G12 | H11: ='Rental, Hosting & Sponsorships'!H12 | I11: =SUM(F11:H11)
B12: Facility Rentals | F12: ='Rental, Hosting & Sponsorships'!F6 | G12: ='Rental, Hosting & Sponsorships'!G6 | H12: ='Rental, Hosting & Sponsorships'!H6 | I12: =SUM(F12:H12)
B13: Other Income | C13: Miscellaneous revenue | I13: =SUM(F13:H13)
A14: Total Revenue | F14: =SUM(F6:F13) | G14: =SUM(G6:G13) | H14: =SUM(H6:H13) | I14: =SUM(I6:I13)
B18: Operational Expenses
A19: A | B19: Salaries & Wages | C19: Staff salaries, mentors | E19: =Salaries1!F27 | F19: =Salaries1!G27 | G19: =Salaries1!H48 | H19: =Salaries1!I27 | I19: =SUM(F19:H19)
A22: B | B22: Utilities & Maintenance | C22: Rent, utilities, internet, security, cleaning
A23: B01 | B23: Internet A Subscription (MTN) 45Mbps | G23: =1201234*8 | I23: =SUM(F23:H23) | J23: Till 2025 year end (8 months)
A24: B02 | B24: Internet A Setup Cost (MTN) | G24: =1982000 | I24: =SUM(F24:H24) | J24: Last mile fiber + installation | K24: x
A25: B03 | B25: Internet B Subscription (Starlink) | G25: =38000*8 | I25: =SUM(F25:H25) | J25: Till 2025 year end (8 months)
A26: B04 | B26: Internet B Device (Starlink) | G26: 679000 | I26: =SUM(F26:H26) | J26: Device Cost (Femtech IT, Ilorin) | K26: x
A27: B05 | B27: Internet B Installation (Starlink) | G27: 200000 | I27: =SUM(F27:H27) | J27: Installation + any required additional materials
A28: B06 | B28: Cleaning | E28: 240000 | F28: 240000 | G28: 1328000 | H28: 1328000 | I28: =SUM(F28:H28) | J28: Including carryover from March & April (already paid for). Profesional cleaning starts in May. 11 man cleaning team & consumables
A29: B07 | B29: Landscaping | G29: 300000 | H29: 300000 | I29: =SUM(F29:H29) | J29: This includes greenery & hedge maintenance
A30: B08 | B30: Facility Maintenance & Repairs | F30: =172000+136000+300000+800000+4429000 | G30: 1500000 | H30: 1500000 | I30: =SUM(F30:H30) | J30: May includes cost of repair of roof & LED panel damaged during recent rainstorm. Other months are conservative estimate for repairs
A31: B09 | B31: Security | G31: 1000000 | H31: 1000000 | I31: =SUM(F31:H31)
A32: B10 | B32: HVAC Maintenance (Quarterly) | H32: 2000000 | I32: =SUM(F32:H32) | J32: As quoted by Project Manager
A33: B11 | B33: Solar Maintenance (Biannually) | J33: As quoted by Project Manager. Not due until Q3
A34: B12 | B34: Electrical Maintenance (Monthly) | G34: 250000 | H34: 250000 | I34: =SUM(F34:H34) | J34: As quoted by Project Manager
A35: B13 | B35: Mechanical Maintenance (Monthly) | G35: 400000 | H35: 400000 | I35: =SUM(F35:H35) | J35: As quoted by Project Manager
A36: B14 | B36: LED Screen Maintenance (Annually) | I36: =SUM(F36:H36) | J36: Not due until next year
A37: B15 | B37: Access Control Maintenance (Annually) | I37: =SUM(F37:H37) | J37: Not due until next year
A38: B16 | B38: Project Manager Professional Fee ? | F38: 3000000 | G38: 3000000 | H38: 3000000 | I38: =SUM(F38:H38) | J38: Geniserve
A39: B17 | B39: Provision for Spare Parts for Solar, Electrical, Mechanical, LED Screens | H39: 10735000 | I39: =SUM(F39:H39) | J39: Purchase of spare parts for hardware infrastructure. As quoted by Project Manager
E40: =SUM(E23:E39) | F40: =SUM(F23:F39) | G40: =SUM(G23:G39) | H40: =SUM(H23:H39) | I40: =SUM(I23:I39)
A42: C | B42: Travel & Conferences | J42: Considering 2 people
A43: C01 | B43: International Conference Registration | G43: 2251027 | I43: =SUM(F43:H43) | J43: Planned trip to Vivatech Paris at €700 per person
A44: C02 | B44: International Travel Flights | G44: 5478430 | I44: =SUM(F44:H44) | J44: $1500 return per person to Paris
A45: C03 | B45: International Travel Accomodation | G45: 3214346 | I45: =SUM(F45:H45) | J45: $200 per night for 5 nights
A46: C04 | B46: International Travel Allowance | G46: 4017435 | I46: =SUM(F46:H46) | J46: $200 per night for 5 nights
A47: C06 | B47: International Visa Processing | G47: 548642 | I47: =SUM(F47:H47) | J47: €300 @ €150 visa fee per person
A48: C07 | B48: Local Conference Registration | H48: 750000 | I48: =SUM(F48:H48) | J48: Estimated to cover any local conference reg
...

Sheet Q2 Summary
B4: Q2 2025 BUDGET SUMMARY
B6: This report provides a consolidated view of Q2 2025 expenses to support transparent and accountable disbursement of the IHS operational funds for the Ilorin Innovation Hub. The quarter’s activities remained aligned with the Hub’s broader mandate of fostering innovation, supporting local startups, and driving digital empowerment.
B7: Two line items have been left at zero - Phtography/Videography and Staff Professional Development. These are recommended for IHS consideration.
B8: The second quarter of 2025 focused on consolidating operations and laying the groundwork for long-term program sustainability at the Ilorin Innovation Hub. During this period, the Hub incurred total expenses amounting to, comprising both recurring and one-time costs.
B9: Majority of our recurring utilities are also being paid for the rest of the year, which is remaining a period of 8 months as one-time costs to ensure sustainability and avoid disruption in activities.
B11: FULL Q2 BREAKDOWN | C11: Amount (₦)
B13: Budget Category
B14: ='Quarterly (Q2)'!B18 | C14: =SUM(C15:C20)
B15: ='Quarterly (Q2)'!B19 | C15: ='Quarterly (Q2)'!I19
B16: ='Quarterly (Q2)'!B22 | C16: ='Quarterly (Q2)'!I40
B17: ='Quarterly (Q2)'!B42 | C17: ='Quarterly (Q2)'!I51
B18: ='Quarterly (Q2)'!B53 | C18: ='Quarterly (Q2)'!I60
B19: ='Quarterly (Q2)'!B63 | C19: ='Quarterly (Q2)'!I70
B20: ='Quarterly (Q2)'!B72 | C20: ='Quarterly (Q2)'!I75
B22: ='Quarterly (Q2)'!B82 | C22: ='Quarterly (Q2)'!I88
B24: ='Quarterly (Q2)'!B92 | C24: ='Quarterly (Q2)'!I95
B25: ='Quarterly (Q2)'!B93 | C25: ='Quarterly (Q2)'!I93
B26: ='Quarterly (Q2)'!B94 | C26: ='Quarterly (Q2)'!I94
B28: Total Expenses | C28: =C14+C22+C24
B31: Operational costs totaled | C31: ='Quarterly (Q2)'!I78+'Quarterly (Q2)'!I88+'Quarterly (Q2)'!I95
B32: Recurring costs totaled | C32: ='Q2 One-Time VS Recurring Costs'!C82
B33: One time costs totaled | C33: ='Q2 One-Time VS Recurring Costs'!C81
B36: Key Highlights
B38: Operational Expenses made up the bulk of the spending, with significant allocations to staff salaries, essential utilities, infrastructure maintenance, and key technology investments. | C38: ='Quarterly (Q2)'!I78
B39: Only the MD and driver salaries have been incurred with a carryover from March. Interns were added in April but did not add dignificantly to the budget. The monthly Payroll for April is: | C39: ='Quarterly (Q2)'!F19 | D39: included in operational expenses
B40: Building repairs also made a considerable addition as a recent rainstorm in Ilorin in April caused leakage on the roof which also damaged the LED screen in the main hall. Roof costs will be paid but deducted from Solar vendors retention. | C40: ='Quarterly (Q2)'!F30 | D40: included in operational expenses
B41: We have recommended a budget Provision for Spare Parts for Solar, Electrical, Mechanical, LED Screens, as quoted by vendors managed by the Project Manager | C41: ='Quarterly (Q2)'!H39 | D41: included in operational expenses
B42: We plan to attend Vivatech Paris in June 2025, with a 2-man delegation. The costs for this have been budgeted for.
B43: Program Support initiatives included recurring community meetups, field engagements, and capacity development through staff training programs. One ecosystem event was held in March. We didnt host any ecosystem event in April but hosted a few external events such as UNILORIN Build with AI and a Womens empowerment event at no cost to us.
B44: A portion of the budget was reserved for contingency and sustainability, including a 2% reserve fund allocation from inflows and a buffer for miscellaneous or unexpected costs. | C44: ='Quarterly (Q2)'!I95

Sheet Q3 Summary
B4: Q3 2025 BUDGET SUMMARY
B6: This report provides a consolidated view of Q3 2025 expenses to support transparent and accountable disbursement of the IHS operational funds for the Ilorin Innovation Hub. The quarter’s activities remained aligned with the Hub’s broader mandate of fostering innovation, supporting local startups, and driving digital empowerment.
B7: The third quarter of 2025 focused on building program momentum with stable operations at the Ilorin Innovation Hub. During this period, the Hub incurred total expenses comprising recurring costs and no one-time costs.
B10: FULL Q3 BREAKDOWN | C10: Amount (₦)
B12: Budget Category
B13: ='Quarterly (Q2)'!B18 | C13: =SUM(C14:C18)
B14: ='Quarterly (Q2)'!B19 | C14: ='Quarterly (Q3)'!H18
B15: ='Quarterly (Q2)'!B22 | C15: ='Quarterly (Q3)'!H30
B16: ='Quarterly (Q2)'!B42 | C16: ='Quarterly (Q3)'!H36
B17: ='Quarterly (Q2)'!B63 | C17: ='Quarterly (Q3)'!H43
B18: ='Quarterly (Q2)'!B72 | C18: ='Quarterly (Q3)'!H47
B20: ='Quarterly (Q2)'!B82 | C20: ='Quarterly (Q3)'!H59
B22: ='Quarterly (Q2)'!B92 | C22: ='Quarterly (Q3)'!H66
B23: ='Quarterly (Q2)'!B93 | C23: ='Quarterly (Q3)'!H64
B24: ='Quarterly (Q2)'!B94 | C24: ='Quarterly (Q3)'!H65
B26: Total Expenses | C26: =C13+C20+C22
B31: Key Highlights
B33: Operational Expenses made up the bulk of the spending, with significant allocations to staff salaries, essential utilities, infrastructure maintenance, and key technology investments. | C33: ='Quarterly (Q3)'!H50
B34: No Equipment/software and Connectivity utility costs for this quarter, as those have been paid as one time costs in previous Q2 budget.
B35: A portion of the budget was reserved for contingency and sustainability, including a 2% reserve fund allocation from inflows and a buffer for miscellaneous or unexpected costs. | C35: ='Quarterly (Q3)'!H66

Sheet Q2 One-Time VS Recurring Costs
B5: Q2 ONE TIME COSTS
B6: These costs are covering the remaining period of 2025 and will not come up in subsequent quarters Q3 and Q4
B8: ='Quarterly (Q2)'!B22 | C8: =SUM(C9:C14)
B9: ='Quarterly (Q2)'!B23 | C9: ='Quarterly (Q2)'!I23
B10: ='Quarterly (Q2)'!B24 | C10: ='Quarterly (Q2)'!I24
B11: ='Quarterly (Q2)'!B25 | C11: ='Quarterly (Q2)'!I25
B12: ='Quarterly (Q2)'!B26 | C12: ='Quarterly (Q2)'!I26
B13: ='Quarterly (Q2)'!B27 | C13: ='Quarterly (Q2)'!I27
B14: ='Quarterly (Q2)'!B39 | C14: ='Quarterly (Q2)'!I39
B16: ='Quarterly (Q2)'!B53 | C16: =SUM(C17:C22)
B17: ='Quarterly (Q2)'!B54 | C17: ='Quarterly (Q2)'!I54
B18: ='Quarterly (Q2)'!B55 | C18: ='Quarterly (Q2)'!I55
B19: ='Quarterly (Q2)'!B56 | C19: ='Quarterly (Q2)'!I56
B20: ='Quarterly (Q2)'!B57 | C20: ='Quarterly (Q2)'!I57
B21: ='Quarterly (Q2)'!B58 | C21: ='Quarterly (Q2)'!I58
B22: ='Quarterly (Q2)'!B59 | C22: ='Quarterly (Q2)'!I59
B24: ='Quarterly (Q2)'!B63 | C24: =SUM(C25:C27)
B25: ='Quarterly (Q2)'!B64 | C25: ='Quarterly (Q2)'!I64
B26: ='Quarterly (Q2)'!B66 | C26: ='Quarterly (Q2)'!I66
B27: ='Quarterly (Q2)'!B67 | C27: ='Quarterly (Q2)'!I67
B30: ='Quarterly (Q2)'!B72 | C30: =SUM(C31)
B31: ='Quarterly (Q2)'!B74 | C31: ='Quarterly (Q2)'!I74
B35: Q2 RECURRING COSTS
B37: ='Quarterly (Q2)'!B19 | C37: ='Quarterly (Q2)'!I19
B39: ='Quarterly (Q2)'!B22 | C39: =SUM(C40:C50)
B40: ='Quarterly (Q2)'!B28 | C40: ='Quarterly (Q2)'!I28
B41: ='Quarterly (Q2)'!B29 | C41: ='Quarterly (Q2)'!I29
B42: ='Quarterly (Q2)'!B30 | C42: ='Quarterly (Q2)'!I30
B43: ='Quarterly (Q2)'!B31 | C43: ='Quarterly (Q2)'!I31
B44: ='Quarterly (Q2)'!B32 | C44: ='Quarterly (Q2)'!I32
B45: ='Quarterly (Q2)'!B33 | C45: ='Quarterly (Q2)'!I33
B46: ='Quarterly (Q2)'!B34 | C46: ='Quarterly (Q2)'!I34
B47: ='Quarterly (Q2)'!B35 | C47: ='Quarterly (Q2)'!I35
B48: ='Quarterly (Q2)'!B36 | C48: ='Quarterly (Q2)'!I36
B49: ='Quarterly (Q2)'!B37 | C49: ='Quarterly (Q2)'!I37
B50: ='Quarterly (Q2)'!B38 | C50: ='Quarterly (Q2)'!I38
B52: ='Quarterly (Q2)'!B42 | C52: =SUM(C53:C60)
B53: ='Quarterly (Q2)'!B43 | C53: ='Quarterly (Q2)'!I43
B54: ='Quarterly (Q2)'!B44 | C54: ='Quarterly (Q2)'!I44
B55: ='Quarterly (Q2)'!B45 | C55: ='Quarterly (Q2)'!I45
...

Sheet Salaries1
F1: Employer Cost - aligned with the Headcount Phasing
A2: S/N | B2: Grade | C2: Qty | D2: Jan | E2: Feb | F2: Mar | G2: Apr | H2: May | I2: Jun | J2: Jul | K2: Aug | L2: Sep | M2: Oct | N2: Nov | O2: Dec | P2: Total Cost for the year 2026 | Q2: Performance Bonus
A3: 1 | B3: Managing Director | C3: 1 | D3: 4760000 | E3: 4760000 | F3: 4760000 | G3: 4760000 | H3: 4760000 | I3: 4760000 | J3: 4760000 | K3: 4760000 | L3: 4760000 | M3: 4760000 | N3: 4760000 | O3: 4760000 | P3: =SUM(D3:O3) | Q3: =P3*0.2
A4: =A3+1 | B4: Director of Programs | C4: 1 | D4: 2710000 | E4: 2710000 | F4: 2710000 | G4: 2710000 | H4: 2710000 | I4: 2710000 | J4: 2710000 | K4: 2710000 | L4: 2710000 | M4: 2710000 | N4: 2710000 | O4: 2710000 | P4: =SUM(D4:O4) | Q4: =P4*0.2
A5: =A4+1 | B5: Asst. Director of Operations | C5: 1 | F5: 1900000 | G5: 1900000 | H5: 1900000 | I5: 1900000 | J5: 1900000 | K5: 1900000 | L5: 1900000 | M5: 1900000 | N5: 1900000 | O5: 1900000 | P5: =SUM(D5:O5) | Q5: =P5*0.2
A6: =A5+1 | B6: IT Manager | C6: 1 | D6: 555000 | E6: 555000 | F6: 555000 | G6: 555000 | H6: 555000 | I6: 555000 | J6: 555000 | K6: 555000 | L6: 555000 | M6: 555000 | N6: 555000 | O6: 555000 | P6: =SUM(D6:O6) | Q6: =P6*0.15
A7: =A6+1 | B7: Community Manager | C7: 1 | D7: 315000 | E7: 555000 | F7: 555000 | G7: 555000 | H7: 555000 | I7: 555000 | J7: 555000 | K7: 555000 | L7: 555000 | M7: 555000 | N7: 555000 | O7: 555000 | P7: =SUM(D7:O7) | Q7: =P7*0.15
A8: =A7+1 | B8: Facility Associate | C8: 1 | D8: 315000 | E8: 315000 | F8: 315000 | G8: 315000 | H8: 315000 | I8: 315000 | J8: 315000 | K8: 315000 | L8: 315000 | M8: 315000 | N8: 315000 | O8: 315000 | P8: =SUM(D8:O8) | Q8: =P8*0.15
A9: =A8+1 | B9: HR Associate | C9: 1 | D9: 315000 | E9: 315000 | F9: 315000 | G9: 315000 | H9: 315000 | I9: 315000 | J9: 315000 | K9: 315000 | L9: 315000 | M9: 315000 | N9: 315000 | O9: 315000 | P9: =SUM(D9:O9) | Q9: =P9*0.15
A10: =A9+1 | B10: Admin Associate | C10: 1 | D10: 315000 | E10: 315000 | F10: 315000 | G10: 315000 | H10: 315000 | I10: 315000 | J10: 315000 | K10: 315000 | L10: 315000 | M10: 315000 | N10: 315000 | O10: 315000 | P10: =SUM(D10:O10) | Q10: =P10*0.15
A11: =A10+1 | B11: Finance Associate | C11: 1 | D11: 315000 | E11: 315000 | F11: 315000 | G11: 315000 | H11: 315000 | I11: 315000 | J11: 315000 | K11: 315000 | L11: 315000 | M11: 315000 | N11: 315000 | O11: 315000 | P11: =SUM(D11:O11) | Q11: =P11*0.15
A12: =A11+1 | B12: IT Support Associate | C12: 2 | D12: 315000 | E12: 315000 | F12: 315000 | G12: 315000 | H12: 315000 | I12: 315000 | J12: 315000 | K12: 315000 | L12: 315000 | M12: 315000 | N12: 315000 | O12: 315000 | P12: =SUM(D12:O12) | Q12: =P12*0.15
A13: =A12+1 | B13: Content & Digital Marketing Lead | C13: 1 | D13: 315000 | E13: 315000 | F13: 315000 | G13: 315000 | H13: 315000 | I13: 315000 | J13: 315000 | K13: 315000 | L13: 315000 | M13: 315000 | N13: 315000 | O13: 315000 | P13: =SUM(D13:O13) | Q13: =P13*0.15
A14: =A13+1 | B14: Graphic & Multimedia Associate | C14: 1 | D14: 315000 | E14: 315000 | F14: 315000 | G14: 315000 | H14: 315000 | I14: 315000 | J14: 315000 | K14: 315000 | L14: 315000 | M14: 315000 | N14: 315000 | O14: 315000 | P14: =SUM(D14:O14) | Q14: =P14*0.15
A15: =A14+1 | B15: Social Media Associate | C15: 1 | D15: 315000 | E15: 315000 | F15: 315000 | G15: 315000 | H15: 315000 | I15: 315000 | J15: 315000 | K15: 315000 | L15: 315000 | M15: 315000 | N15: 315000 | O15: 315000 | P15: =SUM(D15:O15) | Q15: =P15*0.15
A16: =A15+1 | B16: Front Desk Support | C16: 2 | D16: 150000 | E16: 150000 | F16: 150000 | G16: 150000 | H16: 150000 | I16: 150000 | J16: 150000 | K16: 150000 | L16: 150000 | M16: 150000 | N16: 150000 | O16: 150000 | P16: =SUM(D16:O16) | Q16: =P16*0.1
A17: =A16+1 | B17: Facility Technician | C17: 2 | D17: 150000 | E17: 150000 | F17: 150000 | G17: 150000 | H17: 150000 | I17: 150000 | J17: 150000 | K17: 150000 | L17: 150000 | M17: 150000 | N17: 150000 | O17: 150000 | P17: =SUM(D17:O17) | Q17: =P17*0.1
A18: =A17+1 | B18: Driver | C18: 1 | D18: 150000 | E18: 150000 | F18: 150000 | G18: 150000 | H18: 150000 | I18: 150000 | J18: 150000 | K18: 150000 | L18: 150000 | M18: 150000 | N18: 150000 | O18: 150000 | P18: =SUM(D18:O18) | Q18: =P18*0.1
A19: =A18+1 | B19: Contract Driver | C19: 1 | D19: 75000 | E19: 75000 | F19: 75000 | G19: 75000 | H19: 75000 | I19: 75000 | J19: 75000 | K19: 75000 | L19: 75000 | M19: 75000 | N19: 75000 | O19: 75000 | P19: =SUM(D19:O19) | Q19: =P19*0.1
A20: =A19+1 | B20: NYSC Intern | C20: 5 | D20: 55000 | E20: 55000 | F20: 55000 | G20: 55000 | H20: 55000 | I20: 55000 | J20: 55000 | K20: 55000 | L20: 55000 | M20: 55000 | N20: 55000 | O20: 55000 | P20: =SUM(D20:O20) | Q20: =P20*0.1
A21: =A20+1 | B21: Student Intern | C21: 5 | D21: 46000 | E21: 46000 | F21: 46000 | G21: 46000 | H21: 46000 | I21: 46000 | J21: 46000 | K21: 46000 | L21: 46000 | M21: 46000 | N21: 46000 | O21: 46000 | P21: =SUM(D21:O21) | Q21: =P21*0.1
C22: 1 | P22: =SUM(D22:O22) | Q22: =P22*0.1
B23: Proposed Additions | C23: 1 | P23: =SUM(D23:O23) | Q23: =P23*0.1
B24: Program Associate | C24: 1 | F24: 315000 | G24: 315000 | H24: 315000 | I24: 315000 | J24: 315000 | K24: 315000 | L24: 315000 | M24: 315000 | N24: 315000 | O24: 315000 | P24: =SUM(D24:O24) | Q24: =P24*0.1
B25: IT Support Associate (Event Production & Sound) | C25: 1 | F25: 315000 | G25: 315000 | H25: 315000 | I25: 315000 | J25: 315000 | K25: 315000 | L25: 315000 | M25: 315000 | N25: 315000 | O25: 315000 | P25: =SUM(D25:O25) | Q25: =P25*0.1
B26: Project Manager | C26: 1 | F26: 315000 | G26: 315000 | H26: 315000 | I26: 315000 | J26: 315000 | K26: 315000 | L26: 315000 | M26: 315000 | N26: 315000 | O26: 315000 | P26: =SUM(D26:O26) | Q26: =P26*0.1
B27: Total | C27: =SUM(C3:C26) | D27: =SUM(D3:D26) | E27: =SUM(E3:E26) | F27: =SUM(F3:F26) | G27: =SUM(G3:G26) | H27: =SUM(H3:H26) | I27: =SUM(I3:I26) | J27: =SUM(J3:J26) | ... Q27: =SUM(Q3:Q26)
N37: reduction
M38: 2.3501734e+08 | N38: =M38-P27
N39: =(M38-P27)/M38

Sheet Others
B2: Equipment & Infrastructure
C3: Jan | D3: Feb | E3: Mar | F3: Apr | G3: May | H3: Jun | I3: Jul | J3: Aug | K3: Sep | L3: Oct | M3: Nov | N3: Dec | O3: Total
B4: Cloud Servers | E4: =$O$4/4 | H4: =$O$4/4 | K4: =$O$4/4 | N4: =$O$4/4 | O4: 4166666.7
B5: Staff Email | E5: =$O$5/4 | H5: =$O$5/4 | K5: =$O$5/4 | N5: =$O$5/4 | O5: 2916666.7
B6: Miscellaneous Software Subscriptions & Licenses | E6: =$O$6/4 | H6: =$O$6/4 | K6: =$O$6/4 | N6: =$O$6/4 | O6: 1666666.7
B9: Innovation & Program Support
C10: Jan | D10: Feb | E10: Mar | F10: Apr | G10: May | H10: Jun | I10: Jul | J10: Aug | K10: Sep | L10: Oct | M10: Nov | N10: Dec | O10: Total
B11: Staff Professional Development (Afrilabs Capacity Building etc) | E11: =$O11/4 | H11: =$O11/4 | K11: =$O11/4 | N11: =$O11/4 | O11: 4000000
B12: Monthly Meetups | E12: =$O12/10 | F12: =$O12/10 | G12: =$O12/10 | H12: =$O12/10 | I12: =$O12/10 | J12: =$O12/10 | K12: =$O12/10 | L12: =$O12/10 | ... N12: =$O12/10 | O12: 2500000
B13: Field Events | E13: =$O13/4 | H13: =$O13/4 | K13: =$O13/4 | N13: =$O13/4 | O13: 2083333.3
B14: Webinars | E14: =$O14/4 | H14: =$O14/4 | K14: =$O14/4 | N14: =$O14/4 | O14: 1250000
B18: Conferences and Travels
C19: Jan | D19: Feb | E19: Mar | F19: Apr | G19: May | H19: Jun | I19: Jul | J19: Aug | K19: Sep | L19: Oct | M19: Nov | N19: Dec | O19: Total
B20: Trips - International | H20: 1 | L20: 1 | O20: 4000000
B21: Cost per trip (incl Intl travel) | O21: 2500000
B25: Webinars | E25: =$O25/4 | H25: =$O25/4 | K25: =$O25/4 | N25: =$O25/4 | O25: 1250000
B26: Trips - Local | E26: =$O26/4 | H26: =$O26/4 | K26: =$O26/4 | N26: =$O26/4 | O26: 2083333.3
B27: Cost per trip (incl local travel) | E27: =$O27/4 | H27: =$O27/4 | K27: =$O27/4 | N27: =$O27/4 | O27: 1250000

Sheet Membership Fees
C2: Jan | D2: Feb | E2: Mar | F2: Apr | G2: May | H2: Jun | I2: Jul | J2: Aug | K2: Sep | L2: Oct | M2: Nov | N2: Dec
B3: Fees/Member | C3: 50000 | D3: 50000 | E3: 50000 | F3: 50000 | G3: 50000 | H3: 50000 | I3: 50000 | J3: 50000 | K3: 50000 | L3: 50000 | M3: 50000 | N3: 50000
B4: No of members | C4: 0 | D4: 0 | E4: 5 | F4: =E4+10 | G4: =F4+10 | H4: 50 | I4: 50 | J4: 50 | K4: 50 | L4: 50 | M4: 50 | N4: 50
B5: Total | C5: =C3*C4 | D5: =D3*D4 | E5: =E3*E4 | F5: =F3*F4 | G5: =G3*G4 | H5: =H3*H4 | I5: =I3*I4 | J5: =J3*J4 | ... N5: =N3*N4

Sheet Diesel
C2: Jan | D2: Feb | E2: Mar | F2: Apr | G2: May | H2: Jun | I2: Jul | J2: Aug | K2: Sep | L2: Oct | M2: Nov | N2: Dec
B3: Price | C3: 990 | D3: 990 | E3: 990 | F3: 990 | G3: 990 | H3: 990 | I3: 990 | J3: 990 | K3: 990 | L3: 990 | M3: 990 | N3: 990
B4: Consumption | C4: 1000 | D4: 1000 | E4: 1000 | F4: 1000 | G4: 1000 | H4: 1000 | I4: 1000 | J4: 1000 | K4: 1000 | L4: 1000 | M4: 1000 | N4: 1000
B5: Total | C5: =C3*C4 | D5: =D3*D4 | E5: =E3*E4 | F5: =F3*F4 | G5: =G3*G4 | H5: =H3*H4 | I5: =I3*I4 | J5: =J3*J4 | ... N5: =N3*N4

Sheet Salaries
B2: Grade | C2: Annual Package (₦) | D2: Monhly Salary Amount (₦) | F2: Jan | G2: Feb | H2: Mar | I2: Apr | J2: May | K2: Jun | L2: Jul | M2: Aug | N2: Sep | O2: Oct | P2: Nov | Q2: Dec
B3: Managing Director | C3: 92560384 | D3: =C3/12 | H3: 1 | I3: 1 | J3: 1 | K3: 1 | L3: 1 | M3: 1 | N3: 1 | O3: 1 | P3: 1 | Q3: 1
B4: Director of Programs | C4: 51528999 | D4: =C4/12 | I4: 1 | J4: 1 | K4: 1 | L4: 1 | M4: 1 | N4: 1 | O4: 1 | P4: 1 | Q4: 1
B5: IT Manager | C5: 10365498 | D5: =C5/12 | I5: 1 | J5: 1 | K5: 1 | L5: 1 | M5: 1 | N5: 1 | O5: 1 | P5: 1 | Q5: 1
B6: Community Manager | C6: 10365498 | D6: =C6/12 | I6: 1 | J6: 1 | K6: 1 | L6: 1 | M6: 1 | N6: 1 | O6: 1 | P6: 1 | Q6: 1
B7: Facility Associate | C7: 5939986.5 | D7: =C7/12 | I7: 1 | J7: 1 | K7: 1 | L7: 1 | M7: 1 | N7: 1 | O7: 1 | P7: 1 | Q7: 1
B8: Front Desk Associate (x2) | C8: 11879973 | D8: =C8/12 | I8: 1 | J8: 1 | K8: 2 | L8: 2 | M8: 2 | N8: 2 | O8: 2 | P8: 2 | Q8: 2
B9: Finance Associate | C9: 5939986.5 | D9: =C9/12 | I9: 1 | J9: 1 | K9: 1 | L9: 1 | M9: 1 | N9: 1 | O9: 1 | P9: 1 | Q9: 1
B10: Admin & HR Associate | C10: 5939986.5 | D10: =C10/12 | I10: 1 | J10: 1 | K10: 1 | L10: 1 | M10: 1 | N10: 1 | O10: 1 | P10: 1 | Q10: 1
B11: IT Support Associate (x2) | C11: 11879973 | D11: =C11/12 | I11: 1 | J11: 1 | K11: 1 | L11: 1 | M11: 1 | N11: 1 | O11: 1 | P11: 1 | Q11: 1
B12: Content & Digital Marketing Lead | C12: 5939986.5 | D12: =C12/12 | I12: 1 | J12: 1 | K12: 1 | L12: 1 | M12: 1 | N12: 1 | O12: 1 | P12: 1 | Q12: 1
B13: Graphic & Multimedia Associate | C13: 5939986.5 | D13: =C13/12 | I13: 1 | J13: 1 | K13: 1 | L13: 1 | M13: 1 | N13: 1 | O13: 1 | P13: 1 | Q13: 1
B14: Facility Technician (x3) | C14: 8840273.2 | D14: =C14/12 | I14: 1 | J14: 1 | K14: 1 | L14: 1 | M14: 1 | N14: 1 | O14: 1 | P14: 1 | Q14: 1
B15: Driver | C15: 2946757.8 | D15: =C15/12 | I15: 1 | J15: 2 | K15: 2 | L15: 2 | M15: 2 | N15: 2 | O15: 2 | P15: 2 | Q15: 2
... B17: Intern (x3) | C17: 2689867.2 | D17: =C17/12 | I17: 3 | J17: 3 | K17: 3 | L17: 3 | M17: 3 | N17: 3 | O17: 3 | P17: 3 | Q17: 3
B19: Total Monthly Employee Cost | F19: =SUM(F3:F18) | G19: =SUM(G3:G18) | H19: =SUMPRODUCT(H3:H18,$D$3:$D$18) | I19: =SUMPRODUCT(I3:I18,$D$3:$D$18) | J19: =SUMPRODUCT(J3:J18,$D$3:$D$18) | K19: =SUMPRODUCT(K3:K18,$D$3:$D$18) | L19: =SUMPRODUCT(L3:L18,$D$3:$D$18) | M19: =SUMPRODUCT(M3:M18,$D$3:$D$18) | N19: =SUMPRODUCT(N3:N18,$D$3:$D$18) | O19: =SUMPRODUCT(O3:O18,$D$3:$D$18) | ... Q19: =SUMPRODUCT(Q3:Q18,$D$3:$D$18)
H22: 6418849.8 | I22: 15610314 | J22: 16040687 | K22: 16040687 | L22: 16040687 | M22: 16040687 | N22: 16040687 | O22: 16040687 | P22: 16040687 | Q22: 16040687

Sheet Rental, Hosting & Sponsorships
B2: Facility Rentals
C3: Jan | D3: Feb | E3: Mar | F3: Apr | G3: May | H3: Jun | I3: Jul | J3: Aug | K3: Sep | L3: Oct | M3: Nov | N3: Dec
B4: Rate | C4: 500000 | D4: 500000 | E4: 500000 | F4: 500000 | G4: 500000 | H4: 500000 | I4: 500000 | J4: 500000 | K4: 500000 | L4: 500000 | M4: 500000 | N4: 500000
B5: No of rentals | C5: 0 | D5: 0 | E5: 0 | F5: 0 | G5: 0 | H5: 0 | I5: 0 | J5: 0 | K5: 0 | L5: 0 | M5: 0 | N5: 0
B6: Total | C6: =C4*C5 | D6: =D4*D5 | E6: =E4*E5 | F6: =F4*F5 | G6: =G4*G5 | H6: =H4*H5 | I6: =I4*I5 | J6: =J4*J5 | ... N6: =N4*N5
B8: Event Hosting & Sponsorships
C9: Jan | D9: Feb | E9: Mar | F9: Apr | G9: May | H9: Jun | I9: Jul | J9: Aug | K9: Sep | L9: Oct | M9: Nov | N9: Dec
B10: Rate | C10: 1000000 | D10: 1000000 | E10: 1000000 | F10: 1000000 | G10: 1000000 | H10: 1000000 | I10: 1000000 | J10: 1000000 | K10: 1000000 | L10: 1000000 | M10: 1000000 | N10: 1000000
B11: No of events | C11: 0 | D11: 0 | E11: 0 | F11: 0 | G11: 0 | H11: 0 | I11: 0 | J11: 0 | K11: 0 | L11: 0 | M11: 0 | N11: 0
B12: Total | C12: =C10*C11 | D12: =D10*D11 | E12: =E10*E11 | F12: =F10*F11 | G12: =G10*G11 | H12: =H10*H11 | I12: =I10*I11 | J12: =J10*J11 | ... N12: =N10*N11
