Workbook

Sheet Sheet2 (2)
A1: Trans Date | B1: Value Date | C1: Transaction Details | D1: Category | E1: Transactions | F1: Bank
A2: 45798 | B2: 21-MAY- 2025 | C2: 016NIPT251410435 NIP TRSF FROM AYOBAMI JOEL ATOLAGBE IIH HALL BOOKING by | D2: Facility rentals | E2: -444000 | F2: Bank01
A3: 45798 | B3: 21-MAY- 2025 | C3: 016EMTL251410057 ELECTRONIC MONEY TRANSFER LEVY | D3: Bank charges | E3: 50 | F3: Bank01
A4: 45807 | B4: 30-MAY- 2025 | C4: 000MOBT25150A0VX Payment for 4 flags US EU UNDP NG NIP Transfer from ILORIN INNOVATION HUB LTD to LET S BR | D4: Stationery and Office Supplies | E4: 40000 | F4: Bank01
A5: 45807 | B5: 30-MAY- 2025 | C5: 000MOBT25150A0VX Payment for 4 flags US EU UNDP NG NIP Transfer from ILORIN INNOVATION HUB LTD to LET S BR | D5: Bank charges | E5: 25 | F5: Bank01
A6: 45807 | B6: 30-MAY- 2025 | C6: 000MOBT25150A0VX Payment for 4 flags US EU UNDP NG NIP Transfer from ILORIN INNOVATION HUB LTD to LET S BR | D6: Bank charges | E6: 1.88 | F6: Bank01
A7: 45807 | B7: 30-MAY- 2025 | C7: 0168840251500001 BNG LEGAL SEARCH FEE FOR ILORIN INNOVATION HUB LTD0040117676 | D7: Other Expenses | E7: 10750 | F7: Bank01
A8: 45807 | B8: 30-MAY- 2025 | C8: 000MOBT25150A5H9 Purchase of cleaning supplies NIP Transfer from ILORIN INNOVATION HUB LTD to MAUREEN DANIE | D8: Cleaning expenses | E8: 12000 | F8: Bank01
A9: 45807 | B9: 30-MAY- 2025 | C9: 000MOBT25150A5H9 Purchase of cleaning supplies NIP Transfer from ILORIN INNOVATION HUB LTD to MAUREEN DANIE | D9: Bank charges | E9: 25 | F9: Bank01
A10: 45807 | B10: 30-MAY- 2025 | C10: 000MOBT25150A5H9 Purchase of cleaning supplies NIP Transfer from ILORIN INNOVATION HUB LTD to MAUREEN DANIE | D10: Bank charges | E10: 1.88 | F10: Bank01
A11: 45807 | B11: 30-MAY- 2025 | C11: 000MOBT25150AA0U NIP Transfer from ILORIN INNOVATION HUB LTD to MAUREEN DANIEL OKEY | D11: Other Expenses | E11: 15300 | F11: Bank01
A12: 45807 | B12: 30-MAY- 2025 | C12: 000MOBT25150AA0U NIP Transfer from ILORIN INNOVATION HUB LTD to MAUREEN DANIEL OKEY | D12: Bank charges | E12: 25 | F12: Bank01
A13: 45807 | B13: 30-MAY- 2025 | C13: 000MOBT25150AA0U NIP Transfer from ILORIN INNOVATION HUB LTD to MAUREEN DANIEL OKEY | D13: Bank charges | E13: 1.88 | F13: Bank01
... A353: 45838 | B353: 30-JUN- 2025 | C353: 016AMFC25181003N ACCOUNT MAINTENANCE FEE | D353: Bank charges | E353: 45154.25 | F353: Bank01
A354: 45838 | B354: 30-JUN- 2025 | C354: 016AMFV25181003E VAT ON TRANSACTION CHARGES | D354: Bank charges | E354: 3386.68 | F354: Bank01 | G354: Expense
A355: 45838 | B355: 30-JUN- 2025 | C355: Bank transactions in June | D355: Bank balance | E355: =-SUM(E17:E354) -> 1.0133034e+08 | F355: Bank01 | G355: Bank
A356: 45839 | B356: 01-JUL- 2025 | C356: 000MOBT25182AT02 MONTHLY CLEANING BALANCE NIP Transfer from ILORIN INNOVATION HUB LTD to SIII MULTIPURPOSE | D356: Cleaning expenses | E356: 650000 | F356: Bank01
A357: 45839 | B357: 01-JUL- 2025 | C357: 000MOBT25182AT02 MONTHLY CLEANING BALANCE NIP Transfer from ILORIN INNOVATION HUB LTD to SIII MULTIPURPOSE | D357: Bank charges | E357: 50 | F357: Bank01
A358: 45839 | B358: 01-JUL- 2025 | C358: 000MOBT25182AT02 MONTHLY CLEANING BALANCE NIP Transfer from ILORIN INNOVATION HUB LTD to SIII MULTIPURPOSE | D358: Bank charges | E358: 3.75 | F358: Bank01
A359: 45840 | B359: 02-JUL- 2025 | C359: 000MOBT251834063 EODB LUNCH NIP Transfer from ILORIN INNOVATION HUB LTD to BOA FOODS RESTAURANT LTD 1 | D359: Guest and entertainment | E359: 190200 | F359: Bank01
A360: 45840 | B360: 02-JUL- 2025 | C360: 000MOBT251834063 EODB LUNCH NIP Transfer from ILORIN INNOVATION HUB LTD to BOA FOODS RESTAURANT LTD 1 | D360: Bank charges | E360: 50 | F360: Bank01
A361: 45840 | B361: 02-JUL- 2025 | C361: 000MOBT251834063 EODB LUNCH NIP Transfer from ILORIN INNOVATION HUB LTD to BOA FOODS RESTAURANT LTD 1 | D361: Bank charges | E361: 3.75 | F361: Bank01
A362: 45841 | B362: 03-JUL- 2025 | C362: 000MOBT251841910 EODB BREAKFAST NIP Transfer from ILORIN INNOVATION HUB LTD to Infinitus Innovations Limite | D362: Guest and entertainment | E362: 37500 | F362: Bank01
A363: 45841 | B363: 03-JUL- 2025 | C363: 000MOBT251841910 EODB BREAKFAST NIP Transfer from ILORIN INNOVATION HUB LTD to Infinitus Innovations Limite | D363: Bank charges | E363: 25 | F363: Bank01
A364: 45841 | B364: 03-JUL- 2025 | C364: 000MOBT251841910 EODB BREAKFAST NIP Transfer from ILORIN INNOVATION HUB LTD to Infinitus Innovations Limite | D364: Bank charges | E364: 1.88 | F364: Bank01
A365: 45841 | B365: 03-JUL- 2025 | C365: 000MOBT251846895 EODB Lunch NIP Transfer from ILORIN INNOVATION HUB LTD to BOA FOODS RESTAURANT LTD 1 | D365: Guest and entertainment | E365: 100200 | F365: Bank01
A366: 45841 | B366: 03-JUL- 2025 | C366: 000MOBT251846895 EODB Lunch NIP Transfer from ILORIN INNOVATION HUB LTD to BOA FOODS RESTAURANT LTD 1 | D366: Bank charges | E366: 50 | F366: Bank01
A367: 45841 | B367: 03-JUL- 2025 | C367: 000MOBT251846895 EODB Lunch NIP Transfer from ILORIN INNOVATION HUB LTD to BOA FOODS RESTAURANT LTD 1 | D367: Bank charges | E367: 3.75 | F367: Bank01
... A1025: 45908 | B1025: 08-SEP- 2025 | C1025: 000MOBT25251AIU6 PAYMENT FOR ACCOMODATION BALANCE FOR IIH STAFF ZOHO LAGOS TRIP NIP Transfer from ILORIN | D1025: Bank charges | E1025: 3.75 | F1025: Bank01

Sheet Cover
F15: Ilorin Innovation Hub
F16: Financial Report
F17: for the 7-month period ended 30th September 2025

Sheet SCI
B2: IIH Financial 2025 Report
B3: Statement of comprehensive income
B4: For the 7-month period ended 30 September 2025
D6: 45930 | E6: 30 xxx 2024
C7: Notes | D7: ₦’000 | E7: N'000
B8: Income | C8: =Notes!A6 -> 1 | D8: =Notes!D11 -> 617428.55
B9: Cost of sales | D9: 0
B10: Gross Surplus/(Deficit) | D10: =SUM(D8:D9) -> 617428.55 | E10: =SUM(E8:E9) -> 0
B11: Administrative expenses | C11: =Notes!A14 -> 2 | D11: =-Notes!D31 -> -390880.17
B12: Other income | C12: =Notes!A33 -> 3 | D12: =Notes!D37 -> 0
B13: Operating Surplus/(Deficit) | D13: =SUM(D10:D12) -> 226548.38 | E13: =SUM(E10:E12) -> 0
B14: Finance income | D14: 0
B15: Finance cost | D15: 0
B16: Surplus/(Deficit) before taxation | D16: =SUM(D13:D15) -> 226548.38 | E16: =SUM(E13:E15) -> 0
B17: Taxation charge | D17: 0
B18: Surplus/(Deficit) for the period | D18: =SUM(D16:D17) -> 226548.38 | E18: =SUM(E16:E17) -> 0

Sheet SFP
B2: IIH Financial 2025 Report
B3: Statement of financial position
B4: =SCI!B4 -> For the 7-month period ended 30 September 2025
D6: =SCI!D6 -> 45930 | E6: 30 xxx 2024
C7: Notes | D7: ₦’000 | E7: N'000
B8: ASSETS
B9: Non-current assets
B10: Property, plant and equipment | C10: =Notes!A40 -> 4 | D10: =Notes!D55 -> 6332
B11: Intangible assets
B12: Investments
D13: =SUM(D10:D12) -> 6332 | E13: =SUM(E10:E12) -> 0
B15: Current assets
B16: Trade and other receivables | C16: =Notes!A59 -> 5 | D16: =Notes!D65 -> 0
B17: Inventories | C17: =Notes!A67 -> 6 | D17: =Notes!D72 -> 0
B18: Bank and cash balances | C18: =Notes!A74 -> 7 | D18: =Notes!D78 -> 217516.38
D19: =SUM(D16:D18) -> 217516.38 | E19: =SUM(E16:E18) -> 0
B21: Total assets | D21: =D19+D13 -> 223848.38 | E21: =E19+E13 -> 0
B23: LIABILITIES
B24: Current liabilities
B25: Trade and other payables | C25: =Notes!A80 -> 8 | D25: =Notes!D86 -> -780
B26: Borrowings
B27: Provision for liabilities and charges
B28: Income tax liabilities
D29: =SUM(D25:D28) -> -780 | E29: =SUM(E25:E28) -> 0
B31: Non-current liabilities
B32: Borrowings
B33: Provision for liabilities and charges
D34: =SUM(D32:D33) -> 0 | E34: =SUM(E32:E33) -> 0
B36: Total liabilities | D36: =D34+D29 -> -780 | E36: =E34+E29 -> 0
B38: Net Asset/(liabilities) | D38: =D21-D36 -> 224628.38 | E38: =E21-E36 -> 0
B40: FUNDS/RESERVES
B41: Surplus/Deficit | C41: =Notes!A88 -> 9 | D41: =Notes!C93 -> 226548.38
B42: Reserves | D42: 0
B43: Total Accumulated Funds | D43: =SUM(D41:D42) -> 226548.38 | E43: =SUM(E41:E42) -> 0
B45: Total liabilities and funds | D45: =D43+D36 -> 225768.38 | E45: =E43+E36 -> 0
B46: Check | D46: =D45-D21 -> 1920

Sheet SCF
B2: IIH Financial 2025 Report
B3: Statement of cashflows
B4: =SFP!B4 -> For the 7-month period ended 30 September 2025
C6: =SFP!D6 -> 45930 | D6: 30 xxx 2024
B7: Cash flows from operating activities | C7: ₦’000 | D7: N'000
B8: Surplus/(Deficit) for the period | C8: =SCI!D18 -> 226548.38
B10: Add non-cash items:
B11: Depreciation expense | C11: =Notes!D50 -> 0
B12: Interest received | C12: =-Notes!D35 -> 0
C13: =SUM(C8:C11) -> 226548.38
B14: Changes in working capital:
B15: (Increase)/Decrease in receivables | C15: =SFP!E16-SFP!D16 -> 0
B16: Increase/(Decrease) in payables | C16: =SFP!D25-SFP!E25 -> -780
B17: (Increase)/Decrease in inventories | C17: =SFP!E17-SFP!D17 -> 0
C18: =SUM(C15:C17) -> -780 | D18: =SUM(D15:D16) -> 0
B20: Cash generated from operations | C20: =C18+C13 -> 225768.38
B21: Income taxes paid
B22: Net cash flows generated from operating activities | C22: =SUM(C20:C21) -> 225768.38
B24: Cash flows from investing activities
B25: Purchase of property, plant and equipment | C25: =-Notes!C44 -> -6332
B26: Purchase of software and licences
B27: Proceeds from sale of property, plant and equipment
B28: Proceeds from sale of investment
B29: Interest received | C29: =Notes!D35 -> 0
B30: Short term deposits
B31: Net cash used in investing activities | C31: =SUM(C25:C30) -> -6332
B33: Cash flows from financing activities
B34: Interest paid to third parties | C34: 0
B35: Interest paid to related parties | C35: 0
B36: Loan receipts from third parties | C36: 0
B37: Loan receipts from related parties | C37: 0
B38: Principal repayment to third parties | C38: 0
B39: Principal repayment to related parties | C39: 0
B40: Net cash used in financing activities | C40: =SUM(C34:C39) -> 0
B42: Increase/(decrease) in cash and cash equivalents | C42: =C40+C31+C22 -> 219436.38
B43: Cash and cash equivalents at beginning of the period | C43: 0
B44: Cash and cash equivalent at period end | C44: =SUM(C42:C43) -> 219436.38
B45: Check | C45: =C44-SFP!D18 -> 1920

Sheet Notes
B2: IIH Financial 2025 Report
B3: Notes to financial report
B4: =SCF!B4 -> For the 7-month period ended 30 September 2025
A6: 1 | B6: Income | D6: =SCF!C6 -> 45930 | E6: 30 xxx 2024
D7: =SCF!C7 -> ₦’000 | E7: N'000
B8: Donations | D8: =-SUMIF('Trial Balance'!E:E,B8,'Trial Balance'!C:C)/1000 -> 593624.75
B9: Facility rentals | D9: =-SUMIF('Trial Balance'!E:E,B9,'Trial Balance'!C:C)/1000 -> 23803.8
B10: Others | D10: =-SUMIF('Trial Balance'!E:E,B10,'Trial Balance'!C:C)/1000 -> 0
D11: =SUM(D8:D10) -> 617428.55 | E11: =SUM(E8:E10) -> 0
A14: =A6+1 -> 2 | B14: Administrative expenses | D14: =D6 -> 45930 | E14: 30 xxx 2024
D15: =D7 -> ₦’000 | E15: N'000
B16: Staff salaries and allowance | D16: =SUMIF('Trial Balance'!E:E,B16,'Trial Balance'!C:C)/1000 -> 92080.833
B17: Repairs and Maintenance | D17: =SUMIF('Trial Balance'!E:E,B17,'Trial Balance'!C:C)/1000 -> 16291.763
B18: Guest entertainment | D18: =SUMIF('Trial Balance'!E:E,B18,'Trial Balance'!C:C)/1000 -> 11368.791
B19: Travel expense - Local | D19: =SUMIF('Trial Balance'!E:E,B19,'Trial Balance'!C:C)/1000 -> 7716.458
B20: Travel expense - International | D20: =SUMIF('Trial Balance'!E:E,B20,'Trial Balance'!C:C)/1000 -> 12846.481
B21: Cleaning expense | D21: =SUMIF('Trial Balance'!E:E,B21,'Trial Balance'!C:C)/1000 -> 7882
B22: Telephone and Data expense | D22: =SUMIF('Trial Balance'!E:E,B22,'Trial Balance'!C:C)/1000 -> 7440.7992
B23: Office Supplies | D23: =SUMIF('Trial Balance'!E:E,B23,'Trial Balance'!C:C)/1000 -> 6723.9248
B24: Advertising And Marketing | D24: =SUMIF('Trial Balance'!E:E,B24,'Trial Balance'!C:C)/1000 -> 4020
B25: Bank Fees and Charges | D25: =SUMIF('Trial Balance'!E:E,B25,'Trial Balance'!C:C)/1000 -> 515.71798
B26: Security expense | D26: =SUMIF('Trial Balance'!E:E,B26,'Trial Balance'!C:C)/1000 -> 6462.3
B27: Fuel/Diesel Expenses | D27: =SUMIF('Trial Balance'!E:E,B27,'Trial Balance'!C:C)/1000 -> 507.71
... B30: Other Expenses | D30: =SUMIF('Trial Balance'!E:E,B30,'Trial Balance'!C:C)/1000 -> 5290.5165
D31: =SUM(D16:D30) -> 390880.17
A33: =A14+1 -> 3 | B33: Other income | D33: =D14 -> 45930 | E33: 30 xxx 2024
D34: =D15 -> ₦’000 | E34: N'000
B35: Interest Income | D35: =SUMIF('Trial Balance'!E:E,B35,'Trial Balance'!C:C)/1000 -> 0
D37: =SUM(D35:D36) -> 0
A40: =A33+1 -> 4 | B40: Property, plant and equipment
C41: Furniture & Equipment | D41: Total
B42: Cost | C42: =D34 -> ₦’000 | D42: =C42 -> ₦’000
B43: At beginning of year | C43: 0 | D43: =SUM(C43) -> 0
B44: Additions | C44: ='Trial Balance'!C53/1000 -> 6332 | D44: =SUM(C44) -> 6332
B45: Disposals
B46: At end of year | C46: =SUM(C44:C45) -> 6332 | D46: =SUM(D44:D45) -> 6332
B48: Depreciation and impairment
B49: At beginning of year | C49: 0 | D49: =SUM(C49) -> 0
B50: Charge for the year | C50: ='Trial Balance'!C54/1000 -> 0 | D50: =SUM(C50) -> 0
B51: Disposals
...

Sheet >>>>

Sheet Trial Balance
C1: =SUBTOTAL(9,C3:C80) -> -1920000
A2: Account Code | B2: Account Name | C2: Amount | D2: Account Type | E2: Category | F2: FSLI
B3: Donations | C3: =SUMIF(GL_Transactions!E:E,'Trial Balance'!B3,GL_Transactions!F:F) -> -5.9362475e+08 | D3: =VLOOKUP(B3,'Chart of Accounts'!B:F,4,0) -> Income | E3: Donations | F3: =VLOOKUP(B3,'Chart of Accounts'!B:F,5,0) -> Income
B4: Facility rentals | C4: =SUMIF(GL_Transactions!E:E,'Trial Balance'!B4,GL_Transactions!F:F) -> -12737150 | D4: =VLOOKUP(B4,'Chart of Accounts'!B:F,4,0) -> Income | E4: Facility rentals | F4: =VLOOKUP(B4,'Chart of Accounts'!B:F,5,0) -> Income
B5: Guest entertainment (Income) | C5: =SUMIF(GL_Transactions!E:E,'Trial Balance'!B5,GL_Transactions!F:F) -> -11066650 | D5: =VLOOKUP(B5,'Chart of Accounts'!B:F,4,0) -> Income | E5: Facility rentals | F5: =VLOOKUP(B5,'Chart of Accounts'!B:F,5,0) -> Income
B6: Discount | C6: =SUMIF(GL_Transactions!E:E,'Trial Balance'!B6,GL_Transactions!F:F) -> 0 | D6: =VLOOKUP(B6,'Chart of Accounts'!B:F,4,0) -> Income | E6: Facility rentals | F6: =VLOOKUP(B6,'Chart of Accounts'!B:F,5,0) -> Income
B7: Other Charges | C7: =SUMIF(GL_Transactions!E:E,'Trial Balance'!B7,GL_Transactions!F:F) -> 0 | D7: =VLOOKUP(B7,'Chart of Accounts'!B:F,4,0) -> Income | E7: Others | F7: =VLOOKUP(B7,'Chart of Accounts'!B:F,5,0) -> Income
B8: Sales | C8: =SUMIF(GL_Transactions!E:E,'Trial Balance'!B8,GL_Transactions!F:F) -> 0 | D8: =VLOOKUP(B8,'Chart of Accounts'!B:F,4,0) -> Income | E8: Others | F8: =VLOOKUP(B8,'Chart of Accounts'!B:F,5,0) -> Income
B9: General Income | C9: =SUMIF(GL_Transactions!E:E,'Trial Balance'!B9,GL_Transactions!F:F) -> 0 | D9: =VLOOKUP(B9,'Chart of Accounts'!B:F,4,0) -> Income | E9: Others | F9: =VLOOKUP(B9,'Chart of Accounts'!B:F,5,0) -> Income
B10: Interest Income | C10: =SUMIF(GL_Transactions!E:E,'Trial Balance'!B10,GL_Transactions!F:F) -> 0 | D10: =VLOOKUP(B10,'Chart of Accounts'!B:F,4,0) -> Income | E10: Interest Income | F10: Other income
B11: Late Fee Income | C11: =SUMIF(GL_Transactions!E:E,'Trial Balance'!B11,GL_Transactions!F:F) -> 0 | D11: =VLOOKUP(B11,'Chart of Accounts'!B:F,4,0) -> Income | E11: Others | F11: =VLOOKUP(B11,'Chart of Accounts'!B:F,5,0) -> Income
B12: Shipping Charge | C12: =SUMIF(GL_Transactions!E:E,'Trial Balance'!B12,GL_Transactions!F:F) -> 0 | D12: =VLOOKUP(B12,'Chart of Accounts'!B:F,4,0) -> Income | E12: Others | F12: =VLOOKUP(B12,'Chart of Accounts'!B:F,5,0) -> Income
B13: Cost of Goods Sold | C13: =SUMIF(GL_Transactions!E:E,'Trial Balance'!B13,GL_Transactions!F:F) -> 0 | D13: =VLOOKUP(B13,'Chart of Accounts'!B:F,4,0) -> Cost Of Goods Sold | E13: COGS | F13: =VLOOKUP(B13,'Chart of Accounts'!B:F,5,0) -> Cost of sales
B14: Guest entertainment | C14: =SUMIF(GL_Transactions!E:E,'Trial Balance'!B14,GL_Transactions!F:F) -> 11368791 | D14: =VLOOKUP(B14,'Chart of Accounts'!B:F,4,0) -> Expense | E14: Guest entertainment | F14: Administrative expenses
B15: Lodging | C15: =SUMIF(GL_Transactions!E:E,'Trial Balance'!B15,GL_Transactions!F:F) -> 0 | D15: =VLOOKUP(B15,'Chart of Accounts'!B:F,4,0) -> Expense | E15: Other Expenses | F15: =VLOOKUP(B15,'Chart of Accounts'!B:F,5,0) -> Administrative expenses
B16: Office Supplies | C16: =SUMIF(GL_Transactions!E:E,'Trial Balance'!B16,GL_Transactions!F:F) -> 6723924.8 | D16: =VLOOKUP(B16,'Chart of Accounts'!B:F,4,0) -> Expense | E16: Office Supplies | F16: =VLOOKUP(B16,'Chart of Accounts'!B:F,5,0) -> Administrative expenses
B17: Advertising And Marketing | C17: =SUMIF(GL_Transactions!E:E,'Trial Balance'!B17,GL_Transactions!F:F) -> 4020000 | D17: =VLOOKUP(B17,'Chart of Accounts'!B:F,4,0) -> Expense | E17: Advertising And Marketing | F17: =VLOOKUP(B17,'Chart of Accounts'!B:F,5,0) -> Administrative expenses
B18: Bank Fees and Charges | C18: =SUMIF(GL_Transactions!E:E,'Trial Balance'!B18,GL_Transactions!F:F) -> 515717.98 | D18: =VLOOKUP(B18,'Chart of Accounts'!B:F,4,0) -> Expense | E18: Bank Fees and Charges | F18: =VLOOKUP(B18,'Chart of Accounts'!B:F,5,0) -> Administrative expenses
B19: Credit Card Charges | C19: =SUMIF(GL_Transactions!E:E,'Trial Balance'!B19,GL_Transactions!F:F) -> 0 | D19: =VLOOKUP(B19,'Chart of Accounts'!B:F,4,0) -> Expense | E19: Other Expenses | F19: =VLOOKUP(B19,'Chart of Accounts'!B:F,5,0) -> Administrative expenses
B20: Telephone and Data expense | C20: =SUMIF(GL_Transactions!E:E,'Trial Balance'!B20,GL_Transactions!F:F) -> 7440799.2 | D20: =VLOOKUP(B20,'Chart of Accounts'!B:F,4,0) -> Expense | E20: Telephone and Data expense | F20: =VLOOKUP(B20,'Chart of Accounts'!B:F,5,0) -> Administrative expenses
B21: Software expense | C21: =SUMIF(GL_Transactions!E:E,'Trial Balance'!B21,GL_Transactions!F:F) -> 1623193.5 | D21: =VLOOKUP(B21,'Chart of Accounts'!B:F,4,0) -> Expense | E21: Software expense | F21: =VLOOKUP(B21,'Chart of Accounts'!B:F,5,0) -> Administrative expenses
B22: Exchange Gain or Loss | C22: =SUMIF(GL_Transactions!E:E,'Trial Balance'!B22,GL_Transactions!F:F) -> 0 | D22: =VLOOKUP(B22,'Chart of Accounts'!B:F,4,0) -> Other Expense | E22: Other Expenses | F22: =VLOOKUP(B22,'Chart of Accounts'!B:F,5,0) -> Administrative expenses
B23: Air Travel Expense | C23: =SUMIF(GL_Transactions!E:E,'Trial Balance'!B23,GL_Transactions!F:F) -> 0 | D23: =VLOOKUP(B23,'Chart of Accounts'!B:F,4,0) -> Expense | E23: Other Expenses | F23: =VLOOKUP(B23,'Chart of Accounts'!B:F,5,0) -> Administrative expenses
B24: Telephone Expense | C24: =SUMIF(GL_Transactions!E:E,'Trial Balance'!B24,GL_Transactions!F:F) -> 0 | D24: =VLOOKUP(B24,'Chart of Accounts'!B:F,4,0) -> Expense | E24: Other Expenses | F24: =VLOOKUP(B24,'Chart of Accounts'!B:F,5,0) -> Administrative expenses
B25: Automobile Expense | C25: =SUMIF(GL_Transactions!E:E,'Trial Balance'!B25,GL_Transactions!F:F) -> 0 | D25: =VLOOKUP(B25,'Chart of Accounts'!B:F,4,0) -> Expense | E25: Other Expenses | F25: =VLOOKUP(B25,'Chart of Accounts'!B:F,5,0) -> Administrative expenses
B26: IT and Internet Expenses | C26: =SUMIF(GL_Transactions!E:E,'Trial Balance'!B26,GL_Transactions!F:F) -> 870116.76 | D26: =VLOOKUP(B26,'Chart of Accounts'!B:F,4,0) -> Expense | E26: Other Expenses | F26: =VLOOKUP(B26,'Chart of Accounts'!B:F,5,0) -> Administrative expenses
... B80: Clearing account | C80: =SUMIF(GL_Transactions!E:E,'Trial Balance'!B80,GL_Transactions!F:F) -> -450000 | D80: =VLOOKUP(B80,'Chart of Accounts'!B:F,4,0) -> Expense | E80: Other Expenses | F80: =VLOOKUP(B80,'Chart of Accounts'!B:F,5,0) -> Administrative expenses
B82: Balance check | C82: =SUM(C3:C81) -> -1920000

Sheet GL_Transactions
A1: Trans Date | B1: Period | C1: Transaction Details | D1: Category | E1: Category per Zoho | F1: Transactions | G1: Bank | H1: Description | I1: Check with COA
A2: 45798 | B2: 45808 | C2: 016NIPT251410435 NIP TRSF FROM AYOBAMI JOEL ATOLAGBE IIH HALL BOOKING by | D2: Facility rentals | E2: Facility rentals | F2: -444000 | G2: Bank01 | H2: INV-000015 | I2: =VLOOKUP(E2,'Trial Balance'!B:B,1,0) -> Facility rentals
A3: 45798 | B3: 45808 | C3: 016EMTL251410057 ELECTRONIC MONEY TRANSFER LEVY | D3: Bank charges | E3: Bank Fees and Charges | F3: 50 | G3: Bank01 | I3: =VLOOKUP(E3,'Trial Balance'!B:B,1,0) -> Bank Fees and Charges
A4: 45807 | B4: 45808 | C4: 000MOBT25150A0VX Payment for 4 flags US EU UNDP NG NIP Transfer from ILORIN INNOVATION HUB LTD to LET S BR | D4: Stationery and Office Supplies | E4: Office Supplies | F4: 40000 | G4: Bank01 | I4: =VLOOKUP(E4,'Trial Balance'!B:B,1,0) -> Office Supplies
A5: 45807 | B5: 45808 | C5: 000MOBT25150A0VX Payment for 4 flags US EU UNDP NG NIP Transfer from ILORIN INNOVATION HUB LTD to LET S BR | D5: Bank charges | E5: Bank Fees and Charges | F5: 25 | G5: Bank01 | I5: =VLOOKUP(E5,'Trial Balance'!B:B,1,0) -> Bank Fees and Charges
A6: 45807 | B6: 45808 | C6: 000MOBT25150A0VX Payment for 4 flags US EU UNDP NG NIP Transfer from ILORIN INNOVATION HUB LTD to LET S BR | D6: Bank charges | E6: Bank Fees and Charges | F6: 1.88 | G6: Bank01 | I6: =VLOOKUP(E6,'Trial Balance'!B:B,1,0) -> Bank Fees and Charges
A7: 45807 | B7: 45808 | C7: 0168840251500001 BNG LEGAL SEARCH FEE FOR ILORIN INNOVATION HUB LTD0040117676 | D7: Bank charges | E7: Bank Fees and Charges | F7: 10750 | G7: Bank01 | I7: =VLOOKUP(E7,'Trial Balance'!B:B,1,0) -> Bank Fees and Charges
A8: 45807 | B8: 45808 | C8: 000MOBT25150A5H9 Purchase of cleaning supplies NIP Transfer from ILORIN INNOVATION HUB LTD to MAUREEN DANIE | D8: Cleaning expenses | E8: Janitorial Expense | F8: 12000 | G8: Bank01 | I8: =VLOOKUP(E8,'Trial Balance'!B:B,1,0) -> Janitorial Expense
A9: 45807 | B9: 45808 | C9: 000MOBT25150A5H9 Purchase of cleaning supplies NIP Transfer from ILORIN INNOVATION HUB LTD to MAUREEN DANIE | D9: Bank charges | E9: Bank Fees and Charges | F9: 25 | G9: Bank01 | I9: =VLOOKUP(E9,'Trial Balance'!B:B,1,0) -> Bank Fees and Charges
A10: 45807 | B10: 45808 | C10: 000MOBT25150A5H9 Purchase of cleaning supplies NIP Transfer from ILORIN INNOVATION HUB LTD to MAUREEN DANIE | D10: Bank charges | E10: Bank Fees and Charges | F10: 1.88 | G10: Bank01 | I10: =VLOOKUP(E10,'Trial Balance'!B:B,1,0) -> Bank Fees and Charges
A11: 45807 | B11: 45808 | C11: 000MOBT25150AA0U NIP Transfer from ILORIN INNOVATION HUB LTD to MAUREEN DANIEL OKEY | D11: Other Expenses | E11: Other Expenses | F11: 15300 | G11: Bank01 | I11: =VLOOKUP(E11,'Trial Balance'!B:B,1,0) -> Other Expenses
A12: 45807 | B12: 45808 | C12: 000MOBT25150AA0U NIP Transfer from ILORIN INNOVATION HUB LTD to MAUREEN DANIEL OKEY | D12: Bank charges | E12: Bank Fees and Charges | F12: 25 | G12: Bank01 | I12: =VLOOKUP(E12,'Trial Balance'!B:B,1,0) -> Bank Fees and Charges
A13: 45807 | B13: 45808 | C13: 000MOBT25150AA0U NIP Transfer from ILORIN INNOVATION HUB LTD to MAUREEN DANIEL OKEY | D13: Bank charges | E13: Bank Fees and Charges | F13: 1.88 | G13: Bank01 | I13: =VLOOKUP(E13,'Trial Balance'!B:B,1,0) -> Bank Fees and Charges
A14: 45807 | B14: 45808 | C14: 016AMFC251500023 ACCOUNT MAINTENANCE FEE | D14: Bank charges | E14: Bank Fees and Charges | F14: 67.3 | G14: Bank01 | I14: =VLOOKUP(E14,'Trial Balance'!B:B,1,0) -> Bank Fees and Charges
... A19: 45810 | B19: 45838 | C19: 000MOBT25150AJEP REFUND FOR PURCHASE OF SPEAKER SYSTEM NIP Transfer from ILORIN INNOVATION HUB LTD | D19: Bank charges | E19: Bank Fees and Charges | F19: 3.75 | G19: Bank01 | I19: =VLOOKUP(E19,'Trial Balance'!B:B,1,0) -> Bank Fees and Charges
A20: 45810 | B20: 45838 | C20: 000NEFI251530339 NEFT INWARD STP CR - ILORIN INNOVATION HUB (Q2 ONE-OFF I B/O IHS (NIGERIA) LIMITED | D20: IHS Payment | E20: Donations | F20: -44499369 | G20: Bank01 | H20: INV-000013 | I20: =VLOOKUP(E20,'Trial Balance'!B:B,1,0) -> Donations
A21: 45810 | B21: 45838 | C21: 000MOBT25153A588 IIH SALARY MAY 2025 NIP Transfer from ILORIN INNOVATION HUB LTD to ONUCHUKWU SINACHI GOOD | D21: Salaries and Wages | E21: Salaries and Employee Wages | F21: 249491.56 | G21: Bank01 | I21: =VLOOKUP(E21,'Trial Balance'!B:B,1,0) -> Salaries and Employee Wages
A22: 45810 | B22: 45838 | C22: 000MOBT25153A588 IIH SALARY MAY 2025 NIP Transfer from ILORIN INNOVATION HUB LTD to ONUCHUKWU SINACHI GOOD | D22: Bank charges | E22: Bank Fees and Charges | F22: 50 | G22: Bank01 | I22: =VLOOKUP(E22,'Trial Balance'!B:B,1,0) -> Bank Fees and Charges
A23: 45810 | B23: 45838 | C23: 000MOBT25153A588 IIH SALARY MAY 2025 NIP Transfer from ILORIN INNOVATION HUB LTD to ONUCHUKWU SINACHI GOOD | D23: Bank charges | E23: Bank Fees and Charges | F23: 3.75 | G23: Bank01 | I23: =VLOOKUP(E23,'Trial Balance'!B:B,1,0) -> Bank Fees and Charges
A24: 45810 | B24: 45838 | C24: 000MOBT25153A5CB IIH SALARY MAY 2025 ALLOWANCES NIP Transfer from ILORIN INNOVATION HUB LTD to ONUCHUKWU S | D24: Salaries and Wages | E24: Salaries and Employee Wages | F24: 35000 | G24: Bank01 | I24: =VLOOKUP(E24,'Trial Balance'!B:B,1,0) -> Salaries and Employee Wages
A25: 45810 | B25: 45838 | C25: 000MOBT25153A5CB IIH SALARY MAY 2025 ALLOWANCES NIP Transfer from ILORIN INNOVATION HUB LTD to ONUCHUKWU S | D25: Bank charges | E25: Bank Fees and Charges | F25: 25 | G25: Bank01 | I25: =VLOOKUP(E25,'Trial Balance'!B:B,1,0) -> Bank Fees and Charges
A26: 45810 | B26: 45838 | C26: 000MOBT25153A5CB IIH SALARY MAY 2025 ALLOWANCES NIP Transfer from ILORIN INNOVATION HUB LTD to ONUCHUKWU S | D26: Bank charges | E26: Bank Fees and Charges | F26: 1.88 | G26: Bank01 | I26: =VLOOKUP(E26,'Trial Balance'!B:B,1,0) -> Bank Fees and Charges
A27: 45810 | B27: 45838 | C27: 000MOBT25153A5D4 IIH MAY 2025 SALARY ALLOWANCES NIP Transfer from ILORIN INNOVATION HUB LTD to OLUWADAMILA | D27: Salaries and Wages | E27: Salaries and Employee Wages | F27: 284491.56 | G27: Bank01 | I27: =VLOOKUP(E27,'Trial Balance'!B:B,1,0) -> Salaries and Employee Wages
A28: 45810 | B28: 45838 | C28: 000MOBT25153A5D4 IIH MAY 2025 SALARY ALLOWANCES NIP Transfer from ILORIN INNOVATION HUB LTD to OLUWADAMILA | D28: Bank charges | E28: Bank Fees and Charges | F28: 50 | G28: Bank01 | I28: =VLOOKUP(E28,'Trial Balance'!B:B,1,0) -> Bank Fees and Charges
A29: 45810 | B29: 45838 | C29: 000MOBT25153A5D4 IIH MAY 2025 SALARY ALLOWANCES NIP Transfer from ILORIN INNOVATION HUB LTD to OLUWADAMILA | D29: Bank charges | E29: Bank Fees and Charges | F29: 3.75 | G29: Bank01 | I29: =VLOOKUP(E29,'Trial Balance'!B:B,1,0) -> Bank Fees and Charges
A30: 45810 | B30: 45838 | C30: 000MOBT25153A5G3 IIH SALARY MAY 2025 ALLOWANCES NIP Transfer from ILORIN INNOVATION HUB LTD to TEMILOLUWA | D30: Salaries and Wages | E30: Salaries and Employee Wages | F30: 3570659.4 | G30: Bank01 | I30: =VLOOKUP(E30,'Trial Balance'!B:B,1,0) -> Salaries and Employee Wages
A31: 45810 | B31: 45838 | C31: 000MOBT25153A5G3 IIH SALARY MAY 2025 ALLOWANCES NIP Transfer from ILORIN INNOVATION HUB LTD to TEMILOLUWA | D31: Bank charges | E31: Bank Fees and Charges | F31: 50 | G31: Bank01 | I31: =VLOOKUP(E31,'Trial Balance'!B:B,1,0) -> Bank Fees and Charges
A32: 45810 | B32: 45838 | C32: 000MOBT25153A5G3 IIH SALARY MAY 2025 ALLOWANCES NIP Transfer from ILORIN INNOVATION HUB LTD to TEMILOLUWA | D32: Bank charges | E32: Bank Fees and Charges | F32: 3.75 | G32: Bank01 | I32: =VLOOKUP(E32,'Trial Balance'!B:B,1,0) -> Bank Fees and Charges
... A51: 45811 | B51: 45838 | C51: 000MOBT251541459 MAY SALARY ALLOWANCES NIP Transfer from ILORIN INNOVATION HUB LTD to AKANDE | D51: Bank charges | E51: Bank Fees and Charges | F51: 3.75 | G51: Bank01 | I51: =VLOOKUP(E51,'Trial Balance'!B:B,1,0) -> Bank Fees and Charges
A52: 45811 | B52: 45838 | C52: 000NEFI251540263 NEFT INWARD STP CR - ILORIN INNOVATION HUB OPERATIONAL C B/O IHS (NIGERIA) LIMITED | D52: IHS Payment | E52: Donations | F52: -6935800 | G52: Bank01 | H52: INV-000014 | I52: =VLOOKUP(E52,'Trial Balance'!B:B,1,0) -> Donations
A53: 45811 | B53: 45838 | C53: 000NEFI251540264 NEFT INWARD STP CR - ILORIN INNOVATION HUB (Q2 RECURRENT B/O IHS (NIGERIA) LIMITED | D53: IHS Payment | E53: Donations | F53: -94692772 | G53: Bank01 | H53: INV-000011 | I53: =VLOOKUP(E53,'Trial Balance'!B:B,1,0) -> Donations
A54: 45811 | B54: 45838 | C54: 000MOBT25154A0ED IIH DEPOSIT REFUND FOR BITKWA EVENT NIP Transfer from ILORIN INNOVATION HUB LTD to AYOBAMI | D54: Deposit refund | E54: Refundable security deposit | F54: 100000 | G54: Bank01 | H54: INV-000015 | I54: =VLOOKUP(E54,'Trial Balance'!B:B,1,0) -> Refundable security deposit
A55: 45811 | B55: 45838 | C55: 000MOBT25154A0ED IIH DEPOSIT REFUND FOR BITKWA EVENT NIP Transfer from ILORIN INNOVATION HUB LTD to AYOBAMI | D55: Bank charges | E55: Bank Fees and Charges | F55: 50 | G55: Bank01 | I55: =VLOOKUP(E55,'Trial Balance'!B:B,1,0) -> Bank Fees and Charges
A56: 45811 | B56: 45838 | C56: 000MOBT25154A0ED IIH DEPOSIT REFUND FOR BITKWA EVENT NIP Transfer from ILORIN INNOVATION HUB LTD to AYOBAMI | D56: Bank charges | E56: Bank Fees and Charges | F56: 3.75 | G56: Bank01 | I56: =VLOOKUP(E56,'Trial Balance'!B:B,1,0) -> Bank Fees and Charges
A57: 45811 | B57: 45838 | C57: 000MOBT25154A0F7 JUNE OFFICE SUPPLIES NIP Transfer from ILORIN INNOVATION HUB LTD to MAUREEN DANIEL OKEY | D57: Stationery and Office Supplies | E57: Office Supplies | F57: 150000 | G57: Bank01 | I57: =VLOOKUP(E57,'Trial Balance'!B:B,1,0) -> Office Supplies
A58: 45811 | B58: 45838 | C58: 000MOBT25154A0F7 JUNE OFFICE SUPPLIES NIP Transfer from ILORIN INNOVATION HUB LTD to MAUREEN DANIEL OKEY | D58: Bank charges | E58: Bank Fees and Charges | F58: 50 | G58: Bank01 | I58: =VLOOKUP(E58,'Trial Balance'!B:B,1,0) -> Bank Fees and Charges
A59: 45811 | B59: 45838 | C59: 000MOBT25154A0F7 JUNE OFFICE SUPPLIES NIP Transfer from ILORIN INNOVATION HUB LTD to MAUREEN DANIEL OKEY | D59: Bank charges | E59: Bank Fees and Charges | F59: 3.75 | G59: Bank01 | I59: =VLOOKUP(E59,'Trial Balance'!B:B,1,0) -> Bank Fees and Charges
A60: 45811 | B60: 45838 | C60: 000MOBT25154A15G 50 JANITORIAL CLEANING NIP Transfer from ILORIN INNOVATION HUB LTD to SIII MULTIPURPOSE | D60: Cleaning expenses | E60: Janitorial Expense | F60: 650000 | G60: Bank01 | I60: =VLOOKUP(E60,'Trial Balance'!B:B,1,0) -> Janitorial Expense
A61: 45811 | B61: 45838 | C61: 000MOBT25154A15G 50 JANITORIAL CLEANING NIP Transfer from ILORIN INNOVATION HUB LTD to SIII MULTIPURPOSE | D61: Bank charges | E61: Bank Fees and Charges | F61: 50 | G61: Bank01 | I61: =VLOOKUP(E61,'Trial Balance'!B:B,1,0) -> Bank Fees and Charges
A62: 45811 | B62: 45838 | C62: 000MOBT25154A15G 50 JANITORIAL CLEANING NIP Transfer from ILORIN INNOVATION HUB LTD to SIII MULTIPURPOSE | D62: Bank charges | E62: Bank Fees and Charges | F62: 3.75 | G62: Bank01 | I62: =VLOOKUP(E62,'Trial Balance'!B:B,1,0) -> Bank Fees and Charges
...

Sheet Recon
B2: Sterling bank
B3: Bal as at Aug | C3: ='MoM Transactions'!D27+'MoM Transactions'!E27 -> 2427592.5
B4: Inflow | C4: =-GL_Transactions!F1444 -> 372500
B5: Inflow | C5: =-GL_Transactions!F1445 -> 422500
B6: outflow | C6: =-GL_Transactions!F1446 -> 200000
B7: Expected bal before closure | C7: =SUM(C3:C6) -> 3422592.5
B8: Balance withdrawn | C8: =GL_Transactions!F1448 -> -3422590
B9: Variance noted | C9: =C8+C7 -> 2.5
D2032: 50 | F2032: 547690.81 | G2032: Bank01
F2033: 547687.06 | G2033: Bank01
C2034: 000MOBT25307AIF8 PAYMENT OF SEPT OFFICE SUPPLIES NIP Transfer from ILORIN INNOVATION HUB LTD to MAUREEN DAN | F2034: 3.75 | G2034: Bank01
C2035: 000MOBT25307AJVZ PAYMENT FOR STARLINK INTERNET OCT NOV NIP Transfer from ILORIN INNOVATION HUB LTD to OLUWA | F2035: 57000 | G2035: Bank01
C2036: 000MOBT25307AJVZ Charge PAYMENT FOR STARLINK INTERNET OCT NOV NIP Transfer from ILORIN INNOVATION HUB LTD to OLUWA | F2036: 50 | G2036: Bank01
C2037: 000MOBT25307AJVZ PAYMENT FOR STARLINK INTERNET OCT NOV NIP Transfer from ILORIN INNOVATION HUB LTD to OLUWA | F2037: 3.75 | G2037: Bank01
A2038: 45966 | C2038: 000MOBT253092710 PAYMENT FOR DRINKS INNOV CHALLENGE HACKATHON NIP Transfer from ILORIN INNOVATION HUB LTD t | F2038: 71200 | G2038: Bank01
A2039: 45966 | C2039: 000MOBT253092710 Charge PAYMENT FOR DRINKS INNOV CHALLENGE HACKATHON NIP Transfer from ILORIN INNOVATION HUB LTD t | F2039: 50 | G2039: Bank01
A2040: 45966 | C2040: 000MOBT253092710 PAYMENT FOR DRINKS INNOV CHALLENGE HACKATHON NIP Transfer from ILORIN INNOVATION HUB LTD t | F2040: 3.75 | G2040: Bank01
A2041: 45966 | C2041: 000MOBT253092749 PAYMENT FOR DRINKS INNOV CHALLENGE HACKATHON DAY 2 NIP Transfer from ILORIN INNOVATION HUB | D2041: Guest and entertainment | E2041: Guest entertainment | F2041: 71200 | G2041: Bank01
A2042: 45966 | C2042: 000MOBT253092749 Charge PAYMENT FOR DRINKS INNOV CHALLENGE HACKATHON DAY 2 NIP Transfer from ILORIN INNOVATION HUB | F2042: 50 | G2042: Bank01
A2043: 45966 | C2043: 000MOBT253092749 PAYMENT FOR DRINKS INNOV CHALLENGE HACKATHON DAY 2 NIP Transfer from ILORIN INNOVATION HUB | F2043: 3.75 | G2043: Bank01
A2044: 45968 | C2044: 000MOBT253115640 PAYMENT FOR DRINKS FOR TA COMMJNITY EVENT NIP Transfer from ILORIN INNOVATION HUB LTD to O | D2044: Guest and entertainment | E2044: Guest entertainment | F2044: 96800 | G2044: Bank01
A2045: 45968 | C2045: 000MOBT253115640 Charge PAYMENT FOR DRINKS FOR TA COMMJNITY EVENT NIP Transfer from ILORIN INNOVATION HUB LTD to O | D2045: Bank charges | E2045: Bank Fees and Charges | F2045: 50 | G2045: Bank01
A2046: 45968 | C2046: 000MOBT253115640 PAYMENT FOR DRINKS FOR TA COMMJNITY EVENT NIP Transfer from ILORIN INNOVATION HUB LTD to O | D2046: Bank charges | E2046: Bank Fees and Charges | F2046: 3.75 | G2046: Bank01
A2047: 45968 | C2047: 000MOBT253115677 PAYMENT FOR BREAKFAST FOR CCHUB RESIDENCY EVENT NIP Transfer from ILORIN INNOVATION HUB LT | D2047: Guest and entertainment | E2047: Guest entertainment | F2047: 76200 | G2047: Bank01
A2048: 45968 | C2048: 000MOBT253115677 Charge PAYMENT FOR BREAKFAST FOR CCHUB RESIDENCY EVENT NIP Transfer from ILORIN INNOVATION HUB LT | D2048: Bank charges | E2048: Bank Fees and Charges | F2048: 50 | G2048: Bank01
A2049: 45968 | C2049: 000MOBT253115677 PAYMENT FOR BREAKFAST FOR CCHUB RESIDENCY EVENT NIP Transfer from ILORIN INNOVATION HUB LT | D2049: Bank charges | E2049: Bank Fees and Charges | F2049: 3.75 | G2049: Bank01
A2050: 45972 | C2050: 000MOBT253150120 PAYMENT FOR FLIGHT TICKET MD DIGITAL NIGERIA ABV NIP Transfer from ILORIN INNOVATION HUB L | F2050: 262000 | G2050: Bank01
A2051: 45972 | C2051: 000MOBT253150120 Charge PAYMENT FOR FLIGHT TICKET MD DIGITAL NIGERIA ABV NIP Transfer from ILORIN INNOVATION HUB L | D2051: Bank charges | E2051: Bank Fees and Charges | F2051: 50 | G2051: Bank01
A2052: 45972 | C2052: 000MOBT253150120 PAYMENT FOR FLIGHT TICKET MD DIGITAL NIGERIA ABV NIP Transfer from ILORIN INNOVATION HUB L | D2052: Bank charges | E2052: Bank Fees and Charges | F2052: 3.75 | G2052: Bank01
A2053: 45972 | C2053: 000MOBT253154875 PAYMENT FOR CCHUB RESIDENCY SNACKS FRIENDS NIP Transfer from ILORIN INNOVATION HUB LTD to | D2053: Guest and entertainment | E2053: Guest entertainment | F2053: 59500 | G2053: Bank01
A2054: 45972 | C2054: 000MOBT253154875 Charge PAYMENT FOR CCHUB RESIDENCY SNACKS FRIENDS NIP Transfer from ILORIN INNOVATION HUB LTD to | D2054: Bank charges | E2054: Bank Fees and Charges | F2054: 50 | G2054: Bank01
A2055: 45972 | C2055: 000MOBT253154875 PAYMENT FOR CCHUB RESIDENCY SNACKS FRIENDS NIP Transfer from ILORIN INNOVATION HUB LTD to | D2055: Bank charges | E2055: Bank Fees and Charges | F2055: 3.75 | G2055: Bank01
A2056: 45972 | C2056: 000MOBT253157586 PAYMENT FOR DRINKS CCHUB RESIDENCY EVENT NIP Transfer from ILORIN INNOVATION HUB LTD to OL | D2056: Guest and entertainment | E2056: Guest entertainment | F2056: 40100 | G2056: Bank01
A2057: 45972 | C2057: 000MOBT253157586 Charge PAYMENT FOR DRINKS CCHUB RESIDENCY EVENT NIP Transfer from ILORIN INNOVATION HUB LTD to OL | D2057: Bank charges | E2057: Bank Fees and Charges | F2057: 25 | G2057: Bank01
A2058: 45972 | C2058: 000MOBT253157586 PAYMENT FOR DRINKS CCHUB RESIDENCY EVENT NIP Transfer from ILORIN INNOVATION HUB LTD to OL | D2058: Bank charges | E2058: Bank Fees and Charges | F2058: 1.88 | G2058: Bank01
A2059: 45972 | C2059: 000MOBT25315A104 PAYMENT FOR 3 ADDITIONAL STAFF EMAILS NIP Transfer from ILORIN INNOVATION HUB LTD to PAYST | F2059: 16573 | G2059: Bank01
A2060: 45972 | C2060: 000MOBT25315A104 Charge PAYMENT FOR 3 ADDITIONAL STAFF EMAILS NIP Transfer from ILORIN INNOVATION HUB LTD to PAYST | D2060: Bank charges | E2060: Bank Fees and Charges | F2060: 25 | G2060: Bank01
A2061: 45972 | C2061: 000MOBT25315A104 PAYMENT FOR 3 ADDITIONAL STAFF | D2061: Bank charges | E2061: Bank Fees and Charges | F2061: 1.88 | G2061: Bank01
A2062: 45974 | C2062: 000MOBT253176125 PAYMENT FOR SNACKS CCHUB RESIDENCY NIP Transfer from ILORIN INNOVATION HUB LTD to FRIENDS | D2062: Guest and entertainment | E2062: Guest entertainment | F2062: 59500 | G2062: Bank01
A2063: 45974 | C2063: 000MOBT253176125 Charge PAYMENT FOR SNACKS CCHUB RESIDENCY NIP Transfer from ILORIN INNOVATION HUB LTD to FRIENDS | D2063: Bank charges | E2063: Bank Fees and Charges | F2063: 50 | G2063: Bank01
...

Sheet FAR
B2: FIXED ASSET REGISTER
B3: DATE | C3: TRANSACTION DETAILS | E3: ASSET CATEGORY | F3: AMOUNT
B4: 45824 | C4: 000MOBT25167AD55 FIRMAN GENERATOR PURCHASE 3 ITEL EXTENSIONS NIP Transfer from ILORIN INNOVATION HUB LTD t | D4: Generator | E4: Furniture and Equipment | F4: 902000
B5: 45831 | C5: 000MOBT25174ALT1 1HP AC FOR MAINTENANCE OFFICE NIP Transfer from ILORIN INNOVATION HUB LTD to CYCLE | D5: AC | E5: Furniture and Equipment | F5: 465000

Sheet Sheet1
A1: Trans Date | B1: Period | C1: Transaction Details | D1: Category | E1: Category per Zoho | F1: Transactions
A2: 45895 | B2: 45900 | C2: BANKNIP From 000015250826062358000000205483 000015 PAYREF: SP33363963 SENDER: TUNMISE JOHNSON HOUSEHOLD FOUNDATIO REMARK: 1756149559014 ILORIN TECH PARK LTD Ref: 0000152508260623580000002054832 | D2: Guest and entertainment | F2: -40000

Sheet MoM Transactions
A3: Sum of Transactions | B3: Column Labels
A4: Row Labels | B4: 45808 | C4: 45838 | D4: 45869 | E4: 45900 | F4: 45901 | G4: 45931 | H4: 45962 | I4: Grand Total
A5: Advertising And Marketing | C5: 1770000 | D5: 2250000 | I5: 4020000
A6: Bank Fees and Charges | B6: 10952.99 | C6: 64623.7 | D6: 47728.38 | E6: 42842.84 | F6: 70186.28 | G6: 183683.46 | H6: 4685.22 | I6: 424702.87
A7: Clearing account | E7: -450000 | I7: -450000
A8: Employee related costs | C8: 320161.25 | I8: 320161.25
A9: Facility rentals | B9: -444000 | C9: -420000 | D9: -3557950 | E9: -734000 | F9: -3177000 | G9: -4237700 | H9: -166500 | I9: -12737150
A10: Fuel/Diesel Expenses | D10: 120000 | E10: 240100 | F10: 147610 | I10: 507710
A11: Furniture and Equipment | C11: 1367000 | H11: 4965000 | I11: 6332000
A12: IT and Internet Expenses | C12: 370000 | E12: 36116.76 | F12: 215000 | H12: 249000 | I12: 870116.76
A13: Janitorial Expense | B13: 12000 | C13: 1690000 | D13: 650000 | E13: 1300000 | F13: 2640000 | G13: 1430000 | I13: 7722000
A14: Meals and Entertainment | C14: 244400 | D14: 381876 | E14: 88500 | I14: 714776
A15: Office Supplies | B15: 40000 | C15: 1622500 | D15: 755164 | E15: 693500 | F15: 3462760.8 | I15: 6573924.8
A16: Other Expenses | B16: 15300 | C16: 232261.25 | D16: 8062.5 | I16: 255623.75
A17: Premium Trust bank | B17: 365747.01 | C17: 1.0133034e+08 | D17: -22153745 | E17: -23416247 | F17: -37665924 | G17: -17068151 | I17: 1392017.1
A18: Refundable security deposit | C18: 200000 | E18: 180000 | F18: 400000 | I18: 780000
A19: Rental expense | D19: 120000 | E19: 560000 | F19: 920000 | H19: 2300000 | I19: 3900000
A20: Repairs and Maintenance | C20: 2969025 | D20: 1719000 | E20: 720000 | F20: 3050000 | G20: 5143337.5 | H20: 2690400 | I20: 16291762
A21: Salaries and Employee Wages | C21: 24602438 | D21: 10105872 | E21: 10447815 | F21: 11246030 | G21: 11081191 | H21: 11354782 | I21: 78838128
A22: Security expense | C22: 1344300 | D22: 950000 | F22: 2118000 | G22: 950000 | H22: 0 | I22: 5362300
A23: Software expense | C23: 1241019.2 | E23: 236336.25 | F23: 119032.72 | I23: 1596388.2
A24: Staff allowances | E24: 772500 | F24: 1210000 | I24: 1982500
A25: Staff training | D25: 500000 | E25: 2218342 | F25: 16220000 | G25: 136630325 | H25: 40000000 | I25: 195568667
A26: Staff welfare | D26: 2220851 | F26: 500000 | H26: 1500000 | I26: 4220851
A27: sterling bank | D27: 1693592.5 | E27: 734000 | F27: -2427590 | I27: 2.5
A28: Telephone and Data expense | C28: 6123175.8 | D28: 87000 | E28: 30000 | F28: 114000 | G28: 580623.37 | H28: 449000 | I28: 7383799.2
A29: Travel expense - International | E29: 5147471.8 | F29: 2295088 | G29: 5403921 | I29: 12846481
A30: Travel expense - Local | C30: 835600 | D30: 1607958 | E30: 1143300 | F30: 2448600 | G30: 1419000 | I30: 7454458
A31: zenith bank | D31: 2276688.8 | E31: -268826.07 | F31: 5903054.4 | G31: 71607858 | I31: 79518775
A32: Donations | C32: -1.4612794e+08 | F32: -20220000 | G32: -2.1282e+08 | I32: -3.7916794e+08
A33: Guest entertainment (Income) | C33: -201300 | D33: -1865250 | E33: -318000 | G33: -3567000 | H33: -3584600 | I33: -9536150
A34: Guest entertainment | C34: 422400 | D34: 1852600 | E34: 826800 | F34: -501708.75 | G34: 2980000 | H34: 5131200 | I34: 10711291
A35: Staff pension | F35: 9595004.5 | I35: 9595004.5
A36: Staff NHF | F36: 1317857 | G36: 282911.25 | I36: 1600768.3
A37: Photography and Videography | H37: 120000 | I37: 120000
A38: Training & Mentorship | H38: 1600000 | I38: 1600000
A39: Grand Total | B39: 0 | C39: 0 | D39: -230551.76 | E39: 230551.76 | F39: -7.0314854e-08 | G39: 0 | H39: 66612967 | I39: 66612967
F40: =F31+F27+F17 -> -34190460

Sheet Chart of Accounts
A1: Account ID | B1: Account Name | C1: Account Code | D1: Description | E1: Account Type | F1: FSLI - Added | G1: Mileage Rate | H1: Mileage Unit | I1: IsMileage | J1: Account # | K1: Account Status | L1: Currency | M1: Parent Account
A2: 6104627000000010001 | B2: Other Charges | D2: Miscellaneous charges like adjustments made to the invoice can be recorded in this account. | E2: Income | F2: Income | G2: 0.000 | I2: false | K2: Active | L2: NGN
A3: 6104627000000032023 | B3: Lodging | D3: Any expense related to putting up at motels etc while on business travel can be entered here. | E3: Expense | F3: Administrative expenses | G3: 0.000 | I3: false | K3: Active | L3: NGN
A4: 6104627000000000358 | B4: Undeposited Funds | D4: Record funds received by your company yet to be deposited in a bank as undeposited funds and group them as a current asset in your balance sheet. | E4: Cash | F4: Current Asset | G4: 0.000 | I4: false | K4: Active | L4: NGN
A5: 6104627000000000361 | B5: Petty Cash | D5: It is a small amount of cash that is used to pay your minor or casual expenses rather than writing a check. | E5: Cash | F5: Current Asset | G5: 0.000 | I5: false | K5: Active | L5: NGN
A6: 6104627000000000364 | B6: Accounts Receivable | D6: The money that customers owe you becomes the accounts receivable. A good example of this is a payment expected from an invoice sent to your customer. | E6: Accounts Receivable | F6: Current Asset | G6: 0.000 | I6: false | K6: Active | L6: NGN
A7: 6104627000000000367 | B7: Furniture and Equipment | D7: Purchases of furniture and equipment for your office that can be used for a long period of time usually exceeding one year can be tracked with this account. | E7: Fixed Asset | F7: Non-current asset | G7: 0.000 | I7: false | K7: Active | L7: NGN
A8: 6104627000000000370 | B8: Advance Tax | D8: Any tax which is paid in advance is recorded into the advance tax account. This advance tax payment could be a quarterly, half yearly or yearly payment. | E8: Other Current Asset | F8: Current Asset | G8: 0.000 | I8: false | K8: Active | L8: NGN
A9: 6104627000000000373 | B9: Accounts Payable | D9: This is an account of all the money which you owe to others like a pending bill payment to a vendor,etc. | E9: Accounts Payable | F9: Current Liabilities | G9: 0.000 | I9: false | K9: Active | L9: NGN
A10: 6104627000000000376 | B10: Tax Payable | D10: The amount of money which you owe to your tax authority is recorded under the tax payable account. This amount is a sum of your outstanding in taxes and the tax charged on sales. | E10: Other Current Liability | F10: Current Liabilities | G10: 0.000 | I10: false | K10: Active | L10: NGN
A11: 6104627000000000379 | B11: Retained Earnings | D11: The earnings of your company which are not distributed among the share holders is accounted as retained earnings. | E11: Equity | F11: Accumulated funds | G11: 0.000 | I11: false | K11: Active | L11: NGN
A12: 6104627000000000382 | B12: Owner's Equity | D12: The owners rights to the assets of a company can be quantified in the owner''s equity account. | E12: Equity | F12: Accumulated funds | G12: 0.000 | I12: false | K12: Active | L12: NGN
A13: 6104627000000000385 | B13: Opening Balance Offset | D13: This is an account where you can record the balance from your previous years earning or the amount set aside for some activities. It is like a buffer account for your funds. | E13: Equity | F13: Accumulated funds | G13: 0.000 | I13: false | K13: Active | L13: NGN
... A52: 6104627000000091204 | B52: Parking | D52: The parking fares you pay while on business trips can be recorded under this expense category. | E52: Expense | F52: Administrative expenses | G52: 0.000 | I52: false | K52: Active | L52: NGN
A53: 6104627000000114013 | B53: Ilorin Innovation Hub Ltd | E53: Bank | F53: Current Asset | G53: 0.000 | I53: false | J53: 0040117676 | K53: Active | L53: NGN
A54: ***Added*** | B54: Zenith bank | D54: Bank transactions in the stated bank account | E54: Bank | F54: Current Asset
A55: ***Added*** | B55: Premium Trust bank | D55: Bank transactions in the stated bank account | E55: Bank | F55: Current Asset
A56: ***Added*** | B56: Sterling bank | D56: Bank transactions in the stated bank account | E56: Bank | F56: Current Asset
A57: ***Added*** | B57: Donations | D57: Donation received from IHS or Kwara state for day to day running of the business | E57: Income | F57: Income
A58: ***Added*** | B58: Refundable security deposit | D58: Security deposit charged to the host and refunded after event | E58: Accounts Payable | F58: Current Liabilities
A59: ***Added*** | B59: Telephone and Data expense | D59: The expenses on your telephone, data, voice mobile and fax usage | E59: Expense | F59: Administrative expenses
A60: ***Added*** | B60: Software expense | D60: Software related expenses from the use of Zoho or other software related expenses | E60: Expense | F60: Administrative expenses
A61: ***Added*** | B61: Guest entertainment | D61: Expenses on food and entertainment for Guests are recorded into this account directly related to income | E61: Expense | F61: Cost of sales
A62: ***Added*** | B62: Facility rentals | D62: Income from renting facilities to Host | E62: Income | F62: Income
A63: ***Added*** | B63: Guest entertainment (Income) | D63: Income from providing food and drinks to Host | E63: Income | F63: Income
A64: ***Added*** | B64: Fuel/Diesel Expenses | D64: Relates to all fuel and diesel related expenses | E64: Expense | F64: Administrative expenses
A65: ***Added*** | B65: Employee related costs | D65: Contrubutions relating to employees | E65: Expense | F65: Administrative expenses
... A75: ***Added*** | B75: Surplus/Deficit | D75: The surplus or deficit from each year | E75: Surplus/Deficit | F75: Accumulated funds
A76: ***Added*** | B76: Accumulated funds | E76: Accumulated funds | F76: Accumulated funds
A77: ***Added*** | B77: Reserves | E77: Reserves | F77: Accumulated funds
A78: ***Added*** | B78: Staff NHF | E78: Expense | F78: Administrative expenses
A79: ***Added*** | B79: Staff pension | D79: Employee and employer monthly pension contribution | E79: Expense | F79: Administrative expenses
A80: ***Added*** | B80: Photography and Videography | D80: Corporate Comms and PR | E80: Expense | F80: Administrative expenses
A81: ***Added*** | B81: Training & Mentorship | D81: Innovation and Support | E81: Expense | F81: Administrative expenses

Sheet Breakdown of MD reimbu
B3: Description | C3: Amount
B4: Pebbles sim consult (Cleaning services ) | C4: 1040000
B5: Bubble drinks (drinks and snacks ) | C5: 68000
B6: Star link Invoice | C6: 57000
B7: Zoho invoice | C7: 11610 | D7: =C7+C8+C10 -> 122550
B8: Zoho invoice | C8: 11610
B10: Zoho invoice | C10: 99330
B11: Staff lunch | C11: 40000 | D11: =C11+C12 -> 70000
B12: VIP refreshment (Coffee, water) | C12: 30000
B13: TOTAL | C13: =SUM(C4:C12) -> 1357550

Sheet invoice_details
A1: Ilorin Innovation Hub Invoice Details From 01 Mar 2025 To 30 Sep 2025
A2: invoice_id | B2: status | C2: date | D2: txn_posting_date | E2: due_date | F2: invoice_number | G2: reference_number | H2: customer_name | I2: bcy_total | J2: bcy_balance | K2: salesperson_id | L2: tax_amount | M2: paid_amount | N2: project_names | O2: currency_code | P2: currency_id | Q2: customer_id | R2: price_precision | S2: is_emailed | T2: reminders_sent | U2: exchange_rate
A3: 6104627000000094051 | B3: overdue | C3: 2025-04-23 | E3: 2025-04-23 | F3: INV-000011 | H3: IHS Nigeria | I3: 95767544 | J3: 1074771.4 | L3: 4030392.6 | M3: 94692772 | O3: NGN | P3: 6104627000000091085 | Q3: 6104627000000094027 | R3: 2 | S3: false | T3: 0 | U3: 1
A4: 6104627000000094099 | B4: overdue | C4: 2025-04-23 | E4: 2025-04-23 | F4: INV-000013 | H4: IHS Nigeria | I4: 45342959 | J4: 843589.94 | L4: 3163462.3 | M4: 44499369 | O4: NGN | P4: 6104627000000091085 | Q4: 6104627000000094027 | R4: 2 | S4: false | T4: 0 | U4: 1
A5: 6104627000000100229 | B5: overdue | C5: 2025-04-23 | E5: 2025-04-23 | F5: INV-000014 | H5: IHS Nigeria | I5: 6945600 | J5: 9800 | L5: 36750 | M5: 6935800 | O5: NGN | P5: 6104627000000091085 | Q5: 6104627000000094027 | R5: 2 | S5: false | T5: 0 | U5: 1
A6: 6104627000000110074 | B6: paid | C6: 2025-05-21 | E6: 2025-05-21 | F6: INV-000015 | H6: Bitkwa Initiatives | I6: 444000 | J6: 0 | L6: 24000 | M6: 444000 | O6: NGN | P6: 6104627000000091085 | Q6: 6104627000000110056 | R6: 2 | S6: true | T6: 0 | U6: 1
A7: 6104627000000111033 | B7: paid | C7: 2025-05-30 | E7: 2025-05-30 | F7: INV-000016 | H7: Co-creation Hub | I7: 135300 | J7: 0 | L7: 0 | M7: 135300 | O7: NGN | P7: 6104627000000091085 | Q7: 6104627000000111019 | R7: 2 | S7: true | T7: 0 | U7: 1
A8: 6104627000000133019 | B8: paid | C8: 2025-06-12 | E8: 2025-06-12 | F8: INV-000017 | H8: Co-creation Hub | I8: 48000 | J8: 0 | L8: 0 | M8: 48000 | O8: NGN | P8: 6104627000000091085 | Q8: 6104627000000111019 | R8: 2 | S8: true | T8: 0 | U8: 1
A9: 6104627000000136030 | B9: paid | C9: 2025-06-16 | E9: 2025-06-16 | F9: INV-000018 | H9: Kwara State Internal Revenue Service | I9: 420000 | J9: 0 | L9: 0 | M9: 420000 | O9: NGN | P9: 6104627000000091085 | Q9: 6104627000000136005 | R9: 2 | S9: true | T9: 0 | U9: 1
A10: 6104627000000145015 | B10: paid | C10: 2025-06-18 | E10: 2025-06-18 | F10: INV-000019 | H10: kwara kre8 | I10: 18000 | J10: 0 | L10: 0 | M10: 18000 | O10: NGN | P10: 6104627000000091085 | Q10: 6104627000000145001 | R10: 2 | S10: false | T10: 0 | U10: 1
A11: 6104627000000150021 | B11: draft | C11: 2025-07-01 | E11: 2025-07-01 | F11: INV-000020 | H11: Kwara State Ease of Doing Business Council | I11: 1634000 | J11: 1634000 | L11: 114000 | M11: 0 | O11: NGN | P11: 6104627000000091085 | Q11: 6104627000000150003 | R11: 2 | S11: false | T11: 0 | U11: 1
A12: 6104627000000162001 | B12: paid | C12: 2025-07-02 | E12: 2025-07-02 | F12: INV-000029 | H12: Kwara State Ease of Doing Business Council | I12: 324200 | J12: 0 | L12: 0 | M12: 324200 | O12: NGN | P12: 6104627000000091085 | Q12: 6104627000000150003 | R12: 2 | S12: false | T12: 0 | U12: 1
A13: 6104627000000160027 | B13: paid | C13: 2025-07-03 | E13: 2025-07-03 | F13: INV-000026 | H13: Kwara State Ease of Doing Business Council | I13: 234200 | J13: 0 | L13: 0 | M13: 234200 | O13: NGN | P13: 6104627000000091085 | Q13: 6104627000000150003 | R13: 2 | S13: false | T13: 0 | U13: 1
A14: 6104627000000154035 | B14: paid | C14: 2025-07-04 | E14: 2025-07-04 | F14: INV-000021 | H14: TA Community | I14: 43000 | J14: 0 | L14: 3000 | M14: 43000 | O14: NGN | P14: 6104627000000091085 | Q14: 6104627000000154017 | R14: 2 | S14: false | T14: 0 | U14: 1
... A57: 6104627000000227058 | B57: paid | C57: 2025-09-22 | E57: 2025-09-30 | F57: INV-000067 | H57: Special Assistant on Students’ Affairs, Kwara State Government. | I57: 700000 | J57: 0 | L57: 0 | M57: 700000 | O57: NGN | P57: 6104627000000091085 | Q57: 6104627000000227031 | R57: 2 | S57: false | T57: 0 | U57: 1
H60: AR | I60: SALES | L60: DEPOSIT REFUND | M60: TAX
H61: =I6 -> 444000 | I61: =H61-M61 -> 420000 | L61: 100000 | M61: =L6 -> 24000
L64: =I11-L11 -> 1520000
