Workbook

Sheet Budget
B2: Category | C2: Description | E2: 45658 | F2: 45689 | G2: 45717 | H2: 45748 | I2: 45778 | J2: 45809 | K2: 45839 | L2: 45870 | M2: 45901 | N2: 45931 | O2: 45962 | P2: 45992 | Q2: FY 2025
G4: =Q91 -> -6.1983101e+08
G5: =G4/9 -> -68870113
A6: Inflows
B7: Kwara State Government Grants | C7: Public sector funding | Q7: =SUM(E7:P7) -> 0
B8: IHS Operational Funds | C8: Corporate partnerships & sponsorships | H8: =69000000*3 -> 207000000 | K8: =H8 -> 207000000 | N8: =K8 -> 207000000 | Q8: =SUM(E8:P8) -> 621000000
B9: Membership Fees | C9: Fees from startups & researchers | E9: ='Membership Fees'!C5 -> 0 | F9: ='Membership Fees'!D5 -> 0 | Q9: =SUM(E9:P9) -> 0
B10: Consulting & Advisory Services | C10: Consulting services revenue | Q10: =SUM(E10:P10) -> 0
B11: Event Hosting & Sponsorships | C11: Revenue from events & hackathons | E11: ='Rental, Hosting & Sponsorships'!C12 -> 0 | F11: ='Rental, Hosting & Sponsorships'!D12 -> 0 | G11: ='Rental, Hosting & Sponsorships'!E12 -> 0 | H11: ='Rental, Hosting & Sponsorships'!F12 -> 0 | I11: ='Rental, Hosting & Sponsorships'!G12 -> 0 | J11: ='Rental, Hosting & Sponsorships'!H12 -> 0 | K11: ='Rental, Hosting & Sponsorships'!I12 -> 0 | L11: ='Rental, Hosting & Sponsorships'!J12 -> 0 | ... P11: ='Rental, Hosting & Sponsorships'!N12 -> 0 | Q11: =SUM(E11:P11) -> 0
B12: Facility Rentals | E12: ='Rental, Hosting & Sponsorships'!C6 -> 0 | F12: ='Rental, Hosting & Sponsorships'!D6 -> 0 | G12: ='Rental, Hosting & Sponsorships'!E6 -> 0 | H12: ='Rental, Hosting & Sponsorships'!F6 -> 0 | I12: ='Rental, Hosting & Sponsorships'!G6 -> 0 | J12: ='Rental, Hosting & Sponsorships'!H6 -> 0 | K12: ='Rental, Hosting & Sponsorships'!I6 -> 0 | L12: ='Rental, Hosting & Sponsorships'!J6 -> 0 | ... P12: ='Rental, Hosting & Sponsorships'!N6 -> 0 | Q12: =SUM(E12:P12) -> 0
B13: Other Income | C13: Miscellaneous revenue | Q13: =SUM(E13:P13) -> 0
A14: Total Revenue | E14: =SUM(E6:E13) -> 0 | F14: =SUM(F6:F13) -> 0 | G14: =SUM(G6:G13) -> 0 | H14: =SUM(H6:H13) -> 207000000 | I14: =SUM(I6:I13) -> 0 | J14: =SUM(J6:J13) -> 0 | K14: =SUM(K6:K13) -> 207000000 | L14: =SUM(L6:L13) -> 0 | ... Q14: =SUM(Q6:Q13) -> 621000000
A18: Operational Expenses
B19: Salaries & Wages | C19: Staff salaries, mentors | E19: =Salaries!F19 -> 0 | F19: =Salaries!G19 -> 0 | G19: =Salaries1!E19 -> 6418849.8 | H19: =Salaries1!F19 -> 15610314 | I19: =Salaries1!G19 -> 16040687 | J19: =Salaries1!H19 -> 16040687 | K19: =Salaries1!I19 -> 16040687 | L19: =Salaries1!J19 -> 16040687 | M19: =Salaries1!K19 -> 16040687 | N19: =Salaries1!L19 -> 16040687 | ... P19: =Salaries1!N19 -> 16040687 | Q19: =SUM(E19:P19) -> 1.5035466e+08
B23: Utilities & Maintenance | C23: Rent, utilities, internet, security
B24: Electricity | H24: 800000 | I24: 800000 | J24: 800000 | K24: 800000 | L24: 800000 | M24: 800000 | N24: 800000 | O24: 800000 | P24: 800000 | Q24: =SUM(E24:P24) -> 7200000
B25: Diesel | E25: =Diesel!C5 -> 0 | F25: =Diesel!D5 -> 0 | H25: =Diesel!F5 -> 0 | I25: =Diesel!G5 -> 921669.93 | J25: =Diesel!H5 -> 949239.34 | K25: =Diesel!I5 -> 1039804 | L25: =Diesel!J5 -> 1064298.4 | M25: =Diesel!K5 -> 1074617.7 | N25: =Diesel!L5 -> 1087452.2 | O25: =Diesel!M5 -> 1103002.1 | P25: =Diesel!N5 -> 1116730.2 | Q25: =SUM(E25:P25) -> 8356813.9
B26: Cleaning & Landscaping | G26: 500000 | H26: 1300000 | I26: 1300000 | J26: 1300000 | K26: 1300000 | L26: 1300000 | M26: 1300000 | N26: 1300000 | O26: 1300000 | P26: 1300000 | Q26: =SUM(E26:P26) -> 12200000
B27: Facility Maintenance & Repairs | H27: 833333.33 | I27: 833333.33 | J27: 833333.33 | K27: 833333.33 | L27: 833333.33 | M27: 833333.33 | N27: 833333.33 | O27: 833333.33 | P27: 833333.33 | Q27: =SUM(E27:P27) -> 7500000
B28: Security | H28: 1000000 | I28: 1000000 | J28: 1000000 | K28: 1000000 | L28: 1000000 | M28: 1000000 | N28: 1000000 | O28: 1000000 | P28: 1000000 | Q28: =SUM(E28:P28) -> 9000000
B29: HVAC, Solar, Elevator, Access Control & LED Screen Maintenance | H29: 1666666.7 | I29: 1666666.7 | J29: 1666666.7 | K29: 1666666.7 | L29: 1666666.7 | M29: 1666666.7 | N29: 1666666.7 | O29: 1666666.7 | P29: 1666666.7 | Q29: =SUM(E29:P29) -> 15000000
G30: =SUM(G24:G29) -> 500000 | H30: =SUM(H24:H29) -> 5600000 | I30: =SUM(I24:I29) -> 6521669.9 | J30: =SUM(J24:J29) -> 6549239.3 | K30: =SUM(K24:K29) -> 6639804 | L30: =SUM(L24:L29) -> 6664298.4 | M30: =SUM(M24:M29) -> 6674617.7 | N30: =SUM(N24:N29) -> 6687452.2 | ... Q30: =SUM(Q24:Q29) -> 59256814
B31: Travel & Conferences
B32: International Conference Registration | J32: 3000000 | Q32: =SUM(E32:P32) -> 3000000
B33: International Travel & Accomodation | J33: 7000000 | M33: 7000000 | P33: 7000000 | Q33: =SUM(E33:P33) -> 21000000
B34: Local Conference Registration | J34: 750000 | M34: 750000 | P34: 750000 | Q34: =SUM(E34:P34) -> 2250000
B35: Local Conference Exhibition | H35: 666666.67 | I35: 666666.67 | J35: 666666.67 | K35: 666666.67 | L35: 666666.67 | M35: 666666.67 | N35: 666666.67 | O35: 666666.67 | P35: 666666.67 | Q35: =SUM(E35:P35) -> 6000000
B36: Local Travel | G36: 1000000 | H36: 1000000 | I36: 1000000 | J36: 1000000 | K36: 1000000 | L36: 1000000 | M36: 1000000 | N36: 1000000 | O36: 1000000 | P36: 1000000 | Q36: =SUM(E36:P36) -> 10000000
G37: =SUM(G32:G36) -> 1000000 | H37: =SUM(H32:H36) -> 1666666.7 | I37: =SUM(I32:I36) -> 1666666.7 | J37: =SUM(J32:J36) -> 12416667 | K37: =SUM(K32:K36) -> 1666666.7 | L37: =SUM(L32:L36) -> 1666666.7 | M37: =SUM(M32:M36) -> 9416666.7 | N37: =SUM(N32:N36) -> 1666666.7 | ... Q37: =SUM(Q32:Q36) -> 42250000
B39: Equipment & Infrastructure | C39: Laptops, software, lab tools
B40: Cloud Servers | E40: =Others!C4 -> 0 | F40: =Others!D4 -> 0 | H40: 416666.67 | I40: 416666.67 | J40: 416666.67 | K40: 416666.67 | L40: 416666.67 | M40: 416666.67 | N40: 416666.67 | O40: 416666.67 | P40: 416666.67 | Q40: =SUM(E40:P40) -> 3750000
B41: Staff Email | E41: =Others!C5 -> 0 | F41: =Others!D5 -> 0 | G41: =Others!E5 -> 729166.67 | H41: =Others!F5 -> 0 | I41: =Others!G5 -> 0 | J41: =Others!H5 -> 729166.67 | K41: =Others!I5 -> 0 | L41: =Others!J5 -> 0 | ... P41: =Others!N5 -> 729166.67 | Q41: =SUM(E41:P41) -> 2916666.7
B42: Software Subscriptions & Licenses | E42: =Others!C6 -> 0 | F42: =Others!D6 -> 0 | G42: =Others!E6 -> 416666.67 | H42: =Others!F6 -> 0 | I42: =Others!G6 -> 0 | J42: =Others!H6 -> 416666.67 | K42: =Others!I6 -> 0 | L42: =Others!J6 -> 0 | ... P42: =Others!N6 -> 416666.67 | Q42: =SUM(E42:P42) -> 1666666.7
B43: Access Control & Hub Management Software | H43: 6500000 | Q43: =SUM(E43:P43) -> 6500000
B44: Laptops | Q44: =SUM(E44:P44) -> 0
G45: =SUM(G40:G44) -> 1145833.3 | H45: =SUM(H40:H44) -> 6916666.7 | I45: =SUM(I40:I44) -> 416666.67 | J45: =SUM(J40:J44) -> 1562500 | K45: =SUM(K40:K44) -> 416666.67 | L45: =SUM(L40:L44) -> 416666.67 | M45: =SUM(M40:M44) -> 1562500 | N45: =SUM(N40:N44) -> 416666.67 | ... Q45: =SUM(Q40:Q44) -> 14833333
B48: Corporate Comms & PR | C48: Branding, events, PR
B49: Souvenirs | H49: 833333.33 | I49: 833333.33 | J49: 833333.33 | K49: 833333.33 | L49: 833333.33 | M49: 833333.33 | N49: 833333.33 | O49: 833333.33 | P49: 833333.33 | Q49: =SUM(E49:P49) -> 7500000
B50: Guest Entertainment & Refreshments | H50: 350000 | I50: 350000 | J50: 350000 | K50: 350000 | L50: 350000 | M50: 350000 | N50: 350000 | O50: 350000 | P50: 350000 | Q50: =SUM(E50:P50) -> 3150000
B51: Banners | H51: 125000 | I51: 125000 | J51: 125000 | K51: 125000 | L51: 125000 | M51: 125000 | N51: 125000 | O51: 125000 | P51: 125000 | Q51: =SUM(E51:P51) -> 1125000
...

Sheet Salaries1
E1: Employer Cost - aligned with the Headcount Phasing
A2: S/N | B2: Grade | C2: Jan | D2: Feb | E2: Mar | F2: Apr | G2: May | H2: Jun | I2: Jul | J2: Aug | K2: Sep | L2: Oct | M2: Nov | N2: Dec | O2: Total Cost for the year 2025
A3: 1 | B3: Managing Director | C3: =(_xlfn.XLOOKUP(B3,'[1]Annual Employer Cost per Grade'!$C$2:$C$17,'[1]Annual Employer Cost per Grade'!$U$2:$U$17,0,0))*(INDEX('[1]Headcount Phasing'!$B$3:$M$18,MATCH(B3,'[1]Headcount Phasing'!$A$3:$A$18,0),MATCH($C$2,'[1]Headcount Phasing'!$B$2:$M$2,0))) -> 0 | D3: =(_xlfn.XLOOKUP(B3,'[1]Annual Employer Cost per Grade'!$C$2:$C$17,'[1]Annual Employer Cost per Grade'!$U$2:$U$17,0,0))*(INDEX('[1]Headcount Phasing'!$B$3:$M$18,MATCH(B3,'[1]Headcount Phasing'!$A$3:$A$18,0),MATCH($D$2,'[1]Headcount Phasing'!$B$2:$M$2,0))) -> 0 | E3: =(_xlfn.XLOOKUP(B3,'[1]Annual Employer Cost per Grade'!$C$2:$C$17,'[1]Annual Employer Cost per Grade'!$U$2:$U$17,0,0))*(INDEX('[1]Headcount Phasing'!$B$3:$M$18,MATCH(B3,'[1]Headcount Phasing'!$A$3:$A$18,0),MATCH($E$2,'[1]Headcount Phasing'!$B$2:$M$2,0))) -> 6187666.7 | F3: =(_xlfn.XLOOKUP(B3,'[1]Annual Employer Cost per Grade'!$C$2:$C$17,'[1]Annual Employer Cost per Grade'!$U$2:$U$17,0,0))*(INDEX('[1]Headcount Phasing'!$B$3:$M$18,MATCH(B3,'[1]Headcount Phasing'!$A$3:$A$18,0),MATCH($F$2,'[1]Headcount Phasing'!$B$2:$M$2,0))) -> 6187666.7 | G3: =(_xlfn.XLOOKUP(B3,'[1]Annual Employer Cost per Grade'!$C$2:$C$17,'[1]Annual Employer Cost per Grade'!$U$2:$U$17,0,0))*(INDEX('[1]Headcount Phasing'!$B$3:$M$18,MATCH(B3,'[1]Headcount Phasing'!$A$3:$A$18,0),MATCH($G$2,'[1]Headcount Phasing'!$B$2:$M$2,0))) -> 6187666.7 | H3: =(_xlfn.XLOOKUP(B3,'[1]Annual Employer Cost per Grade'!$C$2:$C$17,'[1]Annual Employer Cost per Grade'!$U$2:$U$17,0,0))*(INDEX('[1]Headcount Phasing'!$B$3:$M$18,MATCH(B3,'[1]Headcount Phasing'!$A$3:$A$18,0),MATCH($H$2,'[1]Headcount Phasing'!$B$2:$M$2,0))) -> 6187666.7 | I3: =(_xlfn.XLOOKUP(B3,'[1]Annual Employer Cost per Grade'!$C$2:$C$17,'[1]Annual Employer Cost per Grade'!$U$2:$U$17,0,0))*(INDEX('[1]Headcount Phasing'!$B$3:$M$18,MATCH(B3,'[1]Headcount Phasing'!$A$3:$A$18,0),MATCH($I$2,'[1]Headcount Phasing'!$B$2:$M$2,0))) -> 6187666.7 | J3: =(_xlfn.XLOOKUP(B3,'[1]Annual Employer Cost per Grade'!$C$2:$C$17,'[1]Annual Employer Cost per Grade'!$U$2:$U$17,0,0))*(INDEX('[1]Headcount Phasing'!$B$3:$M$18,MATCH(B3,'[1]Headcount Phasing'!$A$3:$A$18,0),MATCH($J$2,'[1]Headcount Phasing'!$B$2:$M$2,0))) -> 6187666.7 | K3: =(_xlfn.XLOOKUP(B3,'[1]Annual Employer Cost per Grade'!$C$2:$C$17,'[1]Annual Employer Cost per Grade'!$U$2:$U$17,0,0))*(INDEX('[1]Headcount Phasing'!$B$3:$M$18,MATCH(B3,'[1]Headcount Phasing'!$A$3:$A$18,0),MATCH($K$2,'[1]Headcount Phasing'!$B$2:$M$2,0))) -> 6187666.7 | L3: =(_xlfn.XLOOKUP(B3,'[1]Annual Employer Cost per Grade'!$C$2:$C$17,'[1]Annual Employer Cost per Grade'!$U$2:$U$17,0,0))*(INDEX('[1]Headcount Phasing'!$B$3:$M$18,MATCH(B3,'[1]Headcount Phasing'!$A$3:$A$18,0),MATCH($L$2,'[1]Headcount Phasing'!$B$2:$M$2,0))) -> 6187666.7 | M3: =(_xlfn.XLOOKUP(B3,'[1]Annual Employer Cost per Grade'!$C$2:$C$17,'[1]Annual Employer Cost per Grade'!$U$2:$U$17,0,0))*(INDEX('[1]Headcount Phasing'!$B$3:$M$18,MATCH(B3,'[1]Headcount Phasing'!$A$3:$A$18,0),MATCH($M$2,'[1]Headcount Phasing'!$B$2:$M$2,0))) -> 6187666.7 | N3: =(_xlfn.XLOOKUP(B3,'[1]Annual Employer Cost per Grade'!$C$2:$C$17,'[1]Annual Employer Cost per Grade'!$U$2:$U$17,0,0))*(INDEX('[1]Headcount Phasing'!$B$3:$M$18,MATCH(B3,'[1]Headcount Phasing'!$A$3:$A$18,0),MATCH($N$2,'[1]Headcount Phasing'!$B$2:$M$2,0))) -> 6187666.7 | O3: =SUM(C3:N3) -> 61876667
A4: =A3+1 -> 2 | B4: Director of Programs | C4: =(_xlfn.XLOOKUP(B4,'[1]Annual Employer Cost per Grade'!$C$2:$C$17,'[1]Annual Employer Cost per Grade'!$U$2:$U$17,0,0))*(INDEX('[1]Headcount Phasing'!$B$3:$M$18,MATCH(B4,'[1]Headcount Phasing'!$A$3:$A$18,0),MATCH($C$2,'[1]Headcount Phasing'!$B$2:$M$2,0))) -> 0 | D4: =(_xlfn.XLOOKUP(B4,'[1]Annual Employer Cost per Grade'!$C$2:$C$17,'[1]Annual Employer Cost per Grade'!$U$2:$U$17,0,0))*(INDEX('[1]Headcount Phasing'!$B$3:$M$18,MATCH(B4,'[1]Headcount Phasing'!$A$3:$A$18,0),MATCH($D$2,'[1]Headcount Phasing'!$B$2:$M$2,0))) -> 0 | E4: =(_xlfn.XLOOKUP(B4,'[1]Annual Employer Cost per Grade'!$C$2:$C$17,'[1]Annual Employer Cost per Grade'!$U$2:$U$17,0,0))*(INDEX('[1]Headcount Phasing'!$B$3:$M$18,MATCH(B4,'[1]Headcount Phasing'!$A$3:$A$18,0),MATCH($E$2,'[1]Headcount Phasing'!$B$2:$M$2,0))) -> 0 | F4: =(_xlfn.XLOOKUP(B4,'[1]Annual Employer Cost per Grade'!$C$2:$C$17,'[1]Annual Employer Cost per Grade'!$U$2:$U$17,0,0))*(INDEX('[1]Headcount Phasing'!$B$3:$M$18,MATCH(B4,'[1]Headcount Phasing'!$A$3:$A$18,0),MATCH($F$2,'[1]Headcount Phasing'!$B$2:$M$2,0))) -> 3555487.9 | G4: =(_xlfn.XLOOKUP(B4,'[1]Annual Employer Cost per Grade'!$C$2:$C$17,'[1]Annual Employer Cost per Grade'!$U$2:$U$17,0,0))*(INDEX('[1]Headcount Phasing'!$B$3:$M$18,MATCH(B4,'[1]Headcount Phasing'!$A$3:$A$18,0),MATCH($G$2,'[1]Headcount Phasing'!$B$2:$M$2,0))) -> 3555487.9 | H4: =(_xlfn.XLOOKUP(B4,'[1]Annual Employer Cost per Grade'!$C$2:$C$17,'[1]Annual Employer Cost per Grade'!$U$2:$U$17,0,0))*(INDEX('[1]Headcount Phasing'!$B$3:$M$18,MATCH(B4,'[1]Headcount Phasing'!$A$3:$A$18,0),MATCH($H$2,'[1]Headcount Phasing'!$B$2:$M$2,0))) -> 3555487.9 | I4: =(_xlfn.XLOOKUP(B4,'[1]Annual Employer Cost per Grade'!$C$2:$C$17,'[1]Annual Employer Cost per Grade'!$U$2:$U$17,0,0))*(INDEX('[1]Headcount Phasing'!$B$3:$M$18,MATCH(B4,'[1]Headcount Phasing'!$A$3:$A$18,0),MATCH($I$2,'[1]Headcount Phasing'!$B$2:$M$2,0))) -> 3555487.9 | J4: =(_xlfn.XLOOKUP(B4,'[1]Annual Employer Cost per Grade'!$C$2:$C$17,'[1]Annual Employer Cost per Grade'!$U$2:$U$17,0,0))*(INDEX('[1]Headcount Phasing'!$B$3:$M$18,MATCH(B4,'[1]Headcount Phasing'!$A$3:$A$18,0),MATCH($J$2,'[1]Headcount Phasing'!$B$2:$M$2,0))) -> 3555487.9 | K4: =(_xlfn.XLOOKUP(B4,'[1]Annual Employer Cost per Grade'!$C$2:$C$17,'[1]Annual Employer Cost per Grade'!$U$2:$U$17,0,0))*(INDEX('[1]Headcount Phasing'!$B$3:$M$18,MATCH(B4,'[1]Headcount Phasing'!$A$3:$A$18,0),MATCH($K$2,'[1]Headcount Phasing'!$B$2:$M$2,0))) -> 3555487.9 | L4: =(_xlfn.XLOOKUP(B4,'[1]Annual Employer Cost per Grade'!$C$2:$C$17,'[1]Annual Employer Cost per Grade'!$U$2:$U$17,0,0))*(INDEX('[1]Headcount Phasing'!$B$3:$M$18,MATCH(B4,'[1]Headcount Phasing'!$A$3:$A$18,0),MATCH($L$2,'[1]Headcount Phasing'!$B$2:$M$2,0))) -> 3555487.9 | M4: =(_xlfn.XLOOKUP(B4,'[1]Annual Employer Cost per Grade'!$C$2:$C$17,'[1]Annual Employer Cost per Grade'!$U$2:$U$17,0,0))*(INDEX('[1]Headcount Phasing'!$B$3:$M$18,MATCH(B4,'[1]Headcount Phasing'!$A$3:$A$18,0),MATCH($M$2,'[1]Headcount Phasing'!$B$2:$M$2,0))) -> 3555487.9 | N4: =(_xlfn.XLOOKUP(B4,'[1]Annual Employer Cost per Grade'!$C$2:$C$17,'[1]Annual Employer Cost per Grade'!$U$2:$U$17,0,0))*(INDEX('[1]Headcount Phasing'!$B$3:$M$18,MATCH(B4,'[1]Headcount Phasing'!$A$3:$A$18,0),MATCH($N$2,'[1]Headcount Phasing'!$B$2:$M$2,0))) -> 3555487.9 | O4: =SUM(C4:N4) -> 31999391
A5: =A4+1 -> 3 | B5: IT Manager | C5: =(_xlfn.XLOOKUP(B5,'[1]Annual Employer Cost per Grade'!$C$2:$C$17,'[1]Annual Employer Cost per Grade'!$U$2:$U$17,0,0))*(INDEX('[1]Headcount Phasing'!$B$3:$M$18,MATCH(B5,'[1]Headcount Phasing'!$A$3:$A$18,0),MATCH($C$2,'[1]Headcount Phasing'!$B$2:$M$2,0))) -> 0 | D5: =(_xlfn.XLOOKUP(B5,'[1]Annual Employer Cost per Grade'!$C$2:$C$17,'[1]Annual Employer Cost per Grade'!$U$2:$U$17,0,0))*(INDEX('[1]Headcount Phasing'!$B$3:$M$18,MATCH(B5,'[1]Headcount Phasing'!$A$3:$A$18,0),MATCH($D$2,'[1]Headcount Phasing'!$B$2:$M$2,0))) -> 0 | E5: =(_xlfn.XLOOKUP(B5,'[1]Annual Employer Cost per Grade'!$C$2:$C$17,'[1]Annual Employer Cost per Grade'!$U$2:$U$17,0,0))*(INDEX('[1]Headcount Phasing'!$B$3:$M$18,MATCH(B5,'[1]Headcount Phasing'!$A$3:$A$18,0),MATCH($E$2,'[1]Headcount Phasing'!$B$2:$M$2,0))) -> 0 | F5: =(_xlfn.XLOOKUP(B5,'[1]Annual Employer Cost per Grade'!$C$2:$C$17,'[1]Annual Employer Cost per Grade'!$U$2:$U$17,0,0))*(INDEX('[1]Headcount Phasing'!$B$3:$M$18,MATCH(B5,'[1]Headcount Phasing'!$A$3:$A$18,0),MATCH($F$2,'[1]Headcount Phasing'!$B$2:$M$2,0))) -> 779030.5 | G5: =(_xlfn.XLOOKUP(B5,'[1]Annual Employer Cost per Grade'!$C$2:$C$17,'[1]Annual Employer Cost per Grade'!$U$2:$U$17,0,0))*(INDEX('[1]Headcount Phasing'!$B$3:$M$18,MATCH(B5,'[1]Headcount Phasing'!$A$3:$A$18,0),MATCH($G$2,'[1]Headcount Phasing'!$B$2:$M$2,0))) -> 779030.5 | H5: =(_xlfn.XLOOKUP(B5,'[1]Annual Employer Cost per Grade'!$C$2:$C$17,'[1]Annual Employer Cost per Grade'!$U$2:$U$17,0,0))*(INDEX('[1]Headcount Phasing'!$B$3:$M$18,MATCH(B5,'[1]Headcount Phasing'!$A$3:$A$18,0),MATCH($H$2,'[1]Headcount Phasing'!$B$2:$M$2,0))) -> 779030.5 | I5: =(_xlfn.XLOOKUP(B5,'[1]Annual Employer Cost per Grade'!$C$2:$C$17,'[1]Annual Employer Cost per Grade'!$U$2:$U$17,0,0))*(INDEX('[1]Headcount Phasing'!$B$3:$M$18,MATCH(B5,'[1]Headcount Phasing'!$A$3:$A$18,0),MATCH($I$2,'[1]Headcount Phasing'!$B$2:$M$2,0))) -> 779030.5 | J5: =(_xlfn.XLOOKUP(B5,'[1]Annual Employer Cost per Grade'!$C$2:$C$17,'[1]Annual Employer Cost per Grade'!$U$2:$U$17,0,0))*(INDEX('[1]Headcount Phasing'!$B$3:$M$18,MATCH(B5,'[1]Headcount Phasing'!$A$3:$A$18,0),MATCH($J$2,'[1]Headcount Phasing'!$B$2:$M$2,0))) -> 779030.5 | K5: =(_xlfn.XLOOKUP(B5,'[1]Annual Employer Cost per Grade'!$C$2:$C$17,'[1]Annual Employer Cost per Grade'!$U$2:$U$17,0,0))*(INDEX('[1]Headcount Phasing'!$B$3:$M$18,MATCH(B5,'[1]Headcount Phasing'!$A$3:$A$18,0),MATCH($K$2,'[1]Headcount Phasing'!$B$2:$M$2,0))) -> 779030.5 | L5: =(_xlfn.XLOOKUP(B5,'[1]Annual Employer Cost per Grade'!$C$2:$C$17,'[1]Annual Employer Cost per Grade'!$U$2:$U$17,0,0))*(INDEX('[1]Headcount Phasing'!$B$3:$M$18,MATCH(B5,'[1]Headcount Phasing'!$A$3:$A$18,0),MATCH($L$2,'[1]Headcount Phasing'!$B$2:$M$2,0))) -> 779030.5 | M5: =(_xlfn.XLOOKUP(B5,'[1]Annual Employer Cost per Grade'!$C$2:$C$17,'[1]Annual Employer Cost per Grade'!$U$2:$U$17,0,0))*(INDEX('[1]Headcount Phasing'!$B$3:$M$18,MATCH(B5,'[1]Headcount Phasing'!$A$3:$A$18,0),MATCH($M$2,'[1]Headcount Phasing'!$B$2:$M$2,0))) -> 779030.5 | N5: =(_xlfn.XLOOKUP(B5,'[1]Annual Employer Cost per Grade'!$C$2:$C$17,'[1]Annual Employer Cost per Grade'!$U$2:$U$17,0,0))*(INDEX('[1]Headcount Phasing'!$B$3:$M$18,MATCH(B5,'[1]Headcount Phasing'!$A$3:$A$18,0),MATCH($N$2,'[1]Headcount Phasing'!$B$2:$M$2,0))) -> 779030.5 | O5: =SUM(C5:N5) -> 7011274.5
A6: =A5+1 -> 4 | B6: Community Manager | C6: =(_xlfn.XLOOKUP(B6,'[1]Annual Employer Cost per Grade'!$C$2:$C$17,'[1]Annual Employer Cost per Grade'!$U$2:$U$17,0,0))*(INDEX('[1]Headcount Phasing'!$B$3:$M$18,MATCH(B6,'[1]Headcount Phasing'!$A$3:$A$18,0),MATCH($C$2,'[1]Headcount Phasing'!$B$2:$M$2,0))) -> 0 | D6: =(_xlfn.XLOOKUP(B6,'[1]Annual Employer Cost per Grade'!$C$2:$C$17,'[1]Annual Employer Cost per Grade'!$U$2:$U$17,0,0))*(INDEX('[1]Headcount Phasing'!$B$3:$M$18,MATCH(B6,'[1]Headcount Phasing'!$A$3:$A$18,0),MATCH($D$2,'[1]Headcount Phasing'!$B$2:$M$2,0))) -> 0 | E6: =(_xlfn.XLOOKUP(B6,'[1]Annual Employer Cost per Grade'!$C$2:$C$17,'[1]Annual Employer Cost per Grade'!$U$2:$U$17,0,0))*(INDEX('[1]Headcount Phasing'!$B$3:$M$18,MATCH(B6,'[1]Headcount Phasing'!$A$3:$A$18,0),MATCH($E$2,'[1]Headcount Phasing'!$B$2:$M$2,0))) -> 0 | F6: =(_xlfn.XLOOKUP(B6,'[1]Annual Employer Cost per Grade'!$C$2:$C$17,'[1]Annual Employer Cost per Grade'!$U$2:$U$17,0,0))*(INDEX('[1]Headcount Phasing'!$B$3:$M$18,MATCH(B6,'[1]Headcount Phasing'!$A$3:$A$18,0),MATCH($F$2,'[1]Headcount Phasing'!$B$2:$M$2,0))) -> 474470.5 | G6: =(_xlfn.XLOOKUP(B6,'[1]Annual Employer Cost per Grade'!$C$2:$C$17,'[1]Annual Employer Cost per Grade'!$U$2:$U$17,0,0))*(INDEX('[1]Headcount Phasing'!$B$3:$M$18,MATCH(B6,'[1]Headcount Phasing'!$A$3:$A$18,0),MATCH($G$2,'[1]Headcount Phasing'!$B$2:$M$2,0))) -> 474470.5 | H6: =(_xlfn.XLOOKUP(B6,'[1]Annual Employer Cost per Grade'!$C$2:$C$17,'[1]Annual Employer Cost per Grade'!$U$2:$U$17,0,0))*(INDEX('[1]Headcount Phasing'!$B$3:$M$18,MATCH(B6,'[1]Headcount Phasing'!$A$3:$A$18,0),MATCH($H$2,'[1]Headcount Phasing'!$B$2:$M$2,0))) -> 474470.5 | I6: =(_xlfn.XLOOKUP(B6,'[1]Annual Employer Cost per Grade'!$C$2:$C$17,'[1]Annual Employer Cost per Grade'!$U$2:$U$17,0,0))*(INDEX('[1]Headcount Phasing'!$B$3:$M$18,MATCH(B6,'[1]Headcount Phasing'!$A$3:$A$18,0),MATCH($I$2,'[1]Headcount Phasing'!$B$2:$M$2,0))) -> 474470.5 | J6: =(_xlfn.XLOOKUP(B6,'[1]Annual Employer Cost per Grade'!$C$2:$C$17,'[1]Annual Employer Cost per Grade'!$U$2:$U$17,0,0))*(INDEX('[1]Headcount Phasing'!$B$3:$M$18,MATCH(B6,'[1]Headcount Phasing'!$A$3:$A$18,0),MATCH($J$2,'[1]Headcount Phasing'!$B$2:$M$2,0))) -> 474470.5 | K6: =(_xlfn.XLOOKUP(B6,'[1]Annual Employer Cost per Grade'!$C$2:$C$17,'[1]Annual Employer Cost per Grade'!$U$2:$U$17,0,0))*(INDEX('[1]Headcount Phasing'!$B$3:$M$18,MATCH(B6,'[1]Headcount Phasing'!$A$3:$A$18,0),MATCH($K$2,'[1]Headcount Phasing'!$B$2:$M$2,0))) -> 474470.5 | L6: =(_xlfn.XLOOKUP(B6,'[1]Annual Employer Cost per Grade'!$C$2:$C$17,'[1]Annual Employer Cost per Grade'!$U$2:$U$17,0,0))*(INDEX('[1]Headcount Phasing'!$B$3:$M$18,MATCH(B6,'[1]Headcount Phasing'!$A$3:$A$18,0),MATCH($L$2,'[1]Headcount Phasing'!$B$2:$M$2,0))) -> 474470.5 | M6: =(_xlfn.XLOOKUP(B6,'[1]Annual Employer Cost per Grade'!$C$2:$C$17,'[1]Annual Employer Cost per Grade'!$U$2:$U$17,0,0))*(INDEX('[1]Headcount Phasing'!$B$3:$M$18,MATCH(B6,'[1]Headcount Phasing'!$A$3:$A$18,0),MATCH($M$2,'[1]Headcount Phasing'!$B$2:$M$2,0))) -> 474470.5 | N6: =(_xlfn.XLOOKUP(B6,'[1]Annual Employer Cost per Grade'!$C$2:$C$17,'[1]Annual Employer Cost per Grade'!$U$2:$U$17,0,0))*(INDEX('[1]Headcount Phasing'!$B$3:$M$18,MATCH(B6,'[1]Headcount Phasing'!$A$3:$A$18,0),MATCH($N$2,'[1]Headcount Phasing'!$B$2:$M$2,0))) -> 474470.5 | O6: =SUM(C6:N6) -> 4270234.5
A7: =A6+1 -> 5 | B7: Facility Associate | C7: =(_xlfn.XLOOKUP(B7,'[1]Annual Employer Cost per Grade'!$C$2:$C$17,'[1]Annual Employer Cost per Grade'!$U$2:$U$17,0,0))*(INDEX('[1]Headcount Phasing'!$B$3:$M$18,MATCH(B7,'[1]Headcount Phasing'!$A$3:$A$18,0),MATCH($C$2,'[1]Headcount Phasing'!$B$2:$M$2,0))) -> 0 | D7: =(_xlfn.XLOOKUP(B7,'[1]Annual Employer Cost per Grade'!$C$2:$C$17,'[1]Annual Employer Cost per Grade'!$U$2:$U$17,0,0))*(INDEX('[1]Headcount Phasing'!$B$3:$M$18,MATCH(B7,'[1]Headcount Phasing'!$A$3:$A$18,0),MATCH($D$2,'[1]Headcount Phasing'!$B$2:$M$2,0))) -> 0 | E7: =(_xlfn.XLOOKUP(B7,'[1]Annual Employer Cost per Grade'!$C$2:$C$17,'[1]Annual Employer Cost per Grade'!$U$2:$U$17,0,0))*(INDEX('[1]Headcount Phasing'!$B$3:$M$18,MATCH(B7,'[1]Headcount Phasing'!$A$3:$A$18,0),MATCH($E$2,'[1]Headcount Phasing'!$B$2:$M$2,0))) -> 0 | F7: =(_xlfn.XLOOKUP(B7,'[1]Annual Employer Cost per Grade'!$C$2:$C$17,'[1]Annual Employer Cost per Grade'!$U$2:$U$17,0,0))*(INDEX('[1]Headcount Phasing'!$B$3:$M$18,MATCH(B7,'[1]Headcount Phasing'!$A$3:$A$18,0),MATCH($F$2,'[1]Headcount Phasing'!$B$2:$M$2,0))) -> 458050.88 | G7: =(_xlfn.XLOOKUP(B7,'[1]Annual Employer Cost per Grade'!$C$2:$C$17,'[1]Annual Employer Cost per Grade'!$U$2:$U$17,0,0))*(INDEX('[1]Headcount Phasing'!$B$3:$M$18,MATCH(B7,'[1]Headcount Phasing'!$A$3:$A$18,0),MATCH($G$2,'[1]Headcount Phasing'!$B$2:$M$2,0))) -> 458050.88 | H7: =(_xlfn.XLOOKUP(B7,'[1]Annual Employer Cost per Grade'!$C$2:$C$17,'[1]Annual Employer Cost per Grade'!$U$2:$U$17,0,0))*(INDEX('[1]Headcount Phasing'!$B$3:$M$18,MATCH(B7,'[1]Headcount Phasing'!$A$3:$A$18,0),MATCH($H$2,'[1]Headcount Phasing'!$B$2:$M$2,0))) -> 458050.88 | I7: =(_xlfn.XLOOKUP(B7,'[1]Annual Employer Cost per Grade'!$C$2:$C$17,'[1]Annual Employer Cost per Grade'!$U$2:$U$17,0,0))*(INDEX('[1]Headcount Phasing'!$B$3:$M$18,MATCH(B7,'[1]Headcount Phasing'!$A$3:$A$18,0),MATCH($I$2,'[1]Headcount Phasing'!$B$2:$M$2,0))) -> 458050.88 | J7: =(_xlfn.XLOOKUP(B7,'[1]Annual Employer Cost per Grade'!$C$2:$C$17,'[1]Annual Employer Cost per Grade'!$U$2:$U$17,0,0))*(INDEX('[1]Headcount Phasing'!$B$3:$M$18,MATCH(B7,'[1]Headcount Phasing'!$A$3:$A$18,0),MATCH($J$2,'[1]Headcount Phasing'!$B$2:$M$2,0))) -> 458050.88 | K7: =(_xlfn.XLOOKUP(B7,'[1]Annual Employer Cost per Grade'!$C$2:$C$17,'[1]Annual Employer Cost per Grade'!$U$2:$U$17,0,0))*(INDEX('[1]Headcount Phasing'!$B$3:$M$18,MATCH(B7,'[1]Headcount Phasing'!$A$3:$A$18,0),MATCH($K$2,'[1]Headcount Phasing'!$B$2:$M$2,0))) -> 458050.88 | L7: =(_xlfn.XLOOKUP(B7,'[1]Annual Employer Cost per Grade'!$C$2:$C$17,'[1]Annual Employer Cost per Grade'!$U$2:$U$17,0,0))*(INDEX('[1]Headcount Phasing'!$B$3:$M$18,MATCH(B7,'[1]Headcount Phasing'!$A$3:$A$18,0),MATCH($L$2,'[1]Headcount Phasing'!$B$2:$M$2,0))) -> 458050.88 | M7: =(_xlfn.XLOOKUP(B7,'[1]Annual Employer Cost per Grade'!$C$2:$C$17,'[1]Annual Employer Cost per Grade'!$U$2:$U$17,0,0))*(INDEX('[1]Headcount Phasing'!$B$3:$M$18,MATCH(B7,'[1]Headcount Phasing'!$A$3:$A$18,0),MATCH($M$2,'[1]Headcount Phasing'!$B$2:$M$2,0))) -> 458050.88 | N7: =(_xlfn.XLOOKUP(B7,'[1]Annual Employer Cost per Grade'!$C$2:$C$17,'[1]Annual Employer Cost per Grade'!$U$2:$U$17,0,0))*(INDEX('[1]Headcount Phasing'!$B$3:$M$18,MATCH(B7,'[1]Headcount Phasing'!$A$3:$A$18,0),MATCH($N$2,'[1]Headcount Phasing'!$B$2:$M$2,0))) -> 458050.88 | O7: =SUM(C7:N7) -> 4122457.9
A8: =A7+1 -> 6 | B8: Front Desk Associate (x1) | C8: =(_xlfn.XLOOKUP(B8,'[1]Annual Employer Cost per Grade'!$C$2:$C$17,'[1]Annual Employer Cost per Grade'!$U$2:$U$17,0,0))*(INDEX('[1]Headcount Phasing'!$B$3:$M$18,MATCH(B8,'[1]Headcount Phasing'!$A$3:$A$18,0),MATCH($C$2,'[1]Headcount Phasing'!$B$2:$M$2,0))) -> 0 | D8: =(_xlfn.XLOOKUP(B8,'[1]Annual Employer Cost per Grade'!$C$2:$C$17,'[1]Annual Employer Cost per Grade'!$U$2:$U$17,0,0))*(INDEX('[1]Headcount Phasing'!$B$3:$M$18,MATCH(B8,'[1]Headcount Phasing'!$A$3:$A$18,0),MATCH($D$2,'[1]Headcount Phasing'!$B$2:$M$2,0))) -> 0 | E8: =(_xlfn.XLOOKUP(B8,'[1]Annual Employer Cost per Grade'!$C$2:$C$17,'[1]Annual Employer Cost per Grade'!$U$2:$U$17,0,0))*(INDEX('[1]Headcount Phasing'!$B$3:$M$18,MATCH(B8,'[1]Headcount Phasing'!$A$3:$A$18,0),MATCH($E$2,'[1]Headcount Phasing'!$B$2:$M$2,0))) -> 0 | F8: =(_xlfn.XLOOKUP(B8,'[1]Annual Employer Cost per Grade'!$C$2:$C$17,'[1]Annual Employer Cost per Grade'!$U$2:$U$17,0,0))*(INDEX('[1]Headcount Phasing'!$B$3:$M$18,MATCH(B8,'[1]Headcount Phasing'!$A$3:$A$18,0),MATCH($F$2,'[1]Headcount Phasing'!$B$2:$M$2,0))) -> 458050.88 | G8: =(_xlfn.XLOOKUP(B8,'[1]Annual Employer Cost per Grade'!$C$2:$C$17,'[1]Annual Employer Cost per Grade'!$U$2:$U$17,0,0))*(INDEX('[1]Headcount Phasing'!$B$3:$M$18,MATCH(B8,'[1]Headcount Phasing'!$A$3:$A$18,0),MATCH($G$2,'[1]Headcount Phasing'!$B$2:$M$2,0))) -> 458050.88 | H8: =(_xlfn.XLOOKUP(B8,'[1]Annual Employer Cost per Grade'!$C$2:$C$17,'[1]Annual Employer Cost per Grade'!$U$2:$U$17,0,0))*(INDEX('[1]Headcount Phasing'!$B$3:$M$18,MATCH(B8,'[1]Headcount Phasing'!$A$3:$A$18,0),MATCH($H$2,'[1]Headcount Phasing'!$B$2:$M$2,0))) -> 458050.88 | I8: =(_xlfn.XLOOKUP(B8,'[1]Annual Employer Cost per Grade'!$C$2:$C$17,'[1]Annual Employer Cost per Grade'!$U$2:$U$17,0,0))*(INDEX('[1]Headcount Phasing'!$B$3:$M$18,MATCH(B8,'[1]Headcount Phasing'!$A$3:$A$18,0),MATCH($I$2,'[1]Headcount Phasing'!$B$2:$M$2,0))) -> 458050.88 | J8: =(_xlfn.XLOOKUP(B8,'[1]Annual Employer Cost per Grade'!$C$2:$C$17,'[1]Annual Employer Cost per Grade'!$U$2:$U$17,0,0))*(INDEX('[1]Headcount Phasing'!$B$3:$M$18,MATCH(B8,'[1]Headcount Phasing'!$A$3:$A$18,0),MATCH($J$2,'[1]Headcount Phasing'!$B$2:$M$2,0))) -> 458050.88 | K8: =(_xlfn.XLOOKUP(B8,'[1]Annual Employer Cost per Grade'!$C$2:$C$17,'[1]Annual Employer Cost per Grade'!$U$2:$U$17,0,0))*(INDEX('[1]Headcount Phasing'!$B$3:$M$18,MATCH(B8,'[1]Headcount Phasing'!$A$3:$A$18,0),MATCH($K$2,'[1]Headcount Phasing'!$B$2:$M$2,0))) -> 458050.88 | L8: =(_xlfn.XLOOKUP(B8,'[1]Annual Employer Cost per Grade'!$C$2:$C$17,'[1]Annual Employer Cost per Grade'!$U$2:$U$17,0,0))*(INDEX('[1]Headcount Phasing'!$B$3:$M$18,MATCH(B8,'[1]Headcount Phasing'!$A$3:$A$18,0),MATCH($L$2,'[1]Headcount Phasing'!$B$2:$M$2,0))) -> 458050.88 | M8: =(_xlfn.XLOOKUP(B8,'[1]Annual Employer Cost per Grade'!$C$2:$C$17,'[1]Annual Employer Cost per Grade'!$U$2:$U$17,0,0))*(INDEX('[1]Headcount Phasing'!$B$3:$M$18,MATCH(B8,'[1]Headcount Phasing'!$A$3:$A$18,0),MATCH($M$2,'[1]Headcount Phasing'!$B$2:$M$2,0))) -> 458050.88 | N8: =(_xlfn.XLOOKUP(B8,'[1]Annual Employer Cost per Grade'!$C$2:$C$17,'[1]Annual Employer Cost per Grade'!$U$2:$U$17,0,0))*(INDEX('[1]Headcount Phasing'!$B$3:$M$18,MATCH(B8,'[1]Headcount Phasing'!$A$3:$A$18,0),MATCH($N$2,'[1]Headcount Phasing'!$B$2:$M$2,0))) -> 458050.88 | O8: =SUM(C8:N8) -> 4122457.9
A9: =A8+1 -> 7 | B9: Front Desk Support | F9: =(_xlfn.XLOOKUP(B9,'[1]Annual Employer Cost per Grade'!$C$2:$C$17,'[1]Annual Employer Cost per Grade'!$U$2:$U$17,0,0))*(INDEX('[1]Headcount Phasing'!$B$3:$M$18,MATCH(B9,'[1]Headcount Phasing'!$A$3:$A$18,0),MATCH($F$2,'[1]Headcount Phasing'!$B$2:$M$2,0))) -> 231183.15 | G9: =(_xlfn.XLOOKUP(B9,'[1]Annual Employer Cost per Grade'!$C$2:$C$17,'[1]Annual Employer Cost per Grade'!$U$2:$U$17,0,0))*(INDEX('[1]Headcount Phasing'!$B$3:$M$18,MATCH(B9,'[1]Headcount Phasing'!$A$3:$A$18,0),MATCH($G$2,'[1]Headcount Phasing'!$B$2:$M$2,0))) -> 231183.15 | H9: =(_xlfn.XLOOKUP(B9,'[1]Annual Employer Cost per Grade'!$C$2:$C$17,'[1]Annual Employer Cost per Grade'!$U$2:$U$17,0,0))*(INDEX('[1]Headcount Phasing'!$B$3:$M$18,MATCH(B9,'[1]Headcount Phasing'!$A$3:$A$18,0),MATCH($H$2,'[1]Headcount Phasing'!$B$2:$M$2,0))) -> 231183.15 | I9: =(_xlfn.XLOOKUP(B9,'[1]Annual Employer Cost per Grade'!$C$2:$C$17,'[1]Annual Employer Cost per Grade'!$U$2:$U$17,0,0))*(INDEX('[1]Headcount Phasing'!$B$3:$M$18,MATCH(B9,'[1]Headcount Phasing'!$A$3:$A$18,0),MATCH($I$2,'[1]Headcount Phasing'!$B$2:$M$2,0))) -> 231183.15 | J9: =(_xlfn.XLOOKUP(B9,'[1]Annual Employer Cost per Grade'!$C$2:$C$17,'[1]Annual Employer Cost per Grade'!$U$2:$U$17,0,0))*(INDEX('[1]Headcount Phasing'!$B$3:$M$18,MATCH(B9,'[1]Headcount Phasing'!$A$3:$A$18,0),MATCH($J$2,'[1]Headcount Phasing'!$B$2:$M$2,0))) -> 231183.15 | K9: =(_xlfn.XLOOKUP(B9,'[1]Annual Employer Cost per Grade'!$C$2:$C$17,'[1]Annual Employer Cost per Grade'!$U$2:$U$17,0,0))*(INDEX('[1]Headcount Phasing'!$B$3:$M$18,MATCH(B9,'[1]Headcount Phasing'!$A$3:$A$18,0),MATCH($K$2,'[1]Headcount Phasing'!$B$2:$M$2,0))) -> 231183.15 | L9: =(_xlfn.XLOOKUP(B9,'[1]Annual Employer Cost per Grade'!$C$2:$C$17,'[1]Annual Employer Cost per Grade'!$U$2:$U$17,0,0))*(INDEX('[1]Headcount Phasing'!$B$3:$M$18,MATCH(B9,'[1]Headcount Phasing'!$A$3:$A$18,0),MATCH($L$2,'[1]Headcount Phasing'!$B$2:$M$2,0))) -> 231183.15 | M9: =(_xlfn.XLOOKUP(B9,'[1]Annual Employer Cost per Grade'!$C$2:$C$17,'[1]Annual Employer Cost per Grade'!$U$2:$U$17,0,0))*(INDEX('[1]Headcount Phasing'!$B$3:$M$18,MATCH(B9,'[1]Headcount Phasing'!$A$3:$A$18,0),MATCH($M$2,'[1]Headcount Phasing'!$B$2:$M$2,0))) -> 231183.15 | N9: =(_xlfn.XLOOKUP(B9,'[1]Annual Employer Cost per Grade'!$C$2:$C$17,'[1]Annual Employer Cost per Grade'!$U$2:$U$17,0,0))*(INDEX('[1]Headcount Phasing'!$B$3:$M$18,MATCH(B9,'[1]Headcount Phasing'!$A$3:$A$18,0),MATCH($N$2,'[1]Headcount Phasing'!$B$2:$M$2,0))) -> 231183.15 | O9: =SUM(C9:N9) -> 2080648.3
A10: =A9+1 -> 8 | B10: Finance Associate | C10: =(_xlfn.XLOOKUP(B10,'[1]Annual Employer Cost per Grade'!$C$2:$C$17,'[1]Annual Employer Cost per Grade'!$U$2:$U$17,0,0))*(INDEX('[1]Headcount Phasing'!$B$3:$M$18,MATCH(B10,'[1]Headcount Phasing'!$A$3:$A$18,0),MATCH($C$2,'[1]Headcount Phasing'!$B$2:$M$2,0))) -> 0 | D10: =(_xlfn.XLOOKUP(B10,'[1]Annual Employer Cost per Grade'!$C$2:$C$17,'[1]Annual Employer Cost per Grade'!$U$2:$U$17,0,0))*(INDEX('[1]Headcount Phasing'!$B$3:$M$18,MATCH(B10,'[1]Headcount Phasing'!$A$3:$A$18,0),MATCH($D$2,'[1]Headcount Phasing'!$B$2:$M$2,0))) -> 0 | E10: =(_xlfn.XLOOKUP(B10,'[1]Annual Employer Cost per Grade'!$C$2:$C$17,'[1]Annual Employer Cost per Grade'!$U$2:$U$17,0,0))*(INDEX('[1]Headcount Phasing'!$B$3:$M$18,MATCH(B10,'[1]Headcount Phasing'!$A$3:$A$18,0),MATCH($E$2,'[1]Headcount Phasing'!$B$2:$M$2,0))) -> 0 | F10: =(_xlfn.XLOOKUP(B10,'[1]Annual Employer Cost per Grade'!$C$2:$C$17,'[1]Annual Employer Cost per Grade'!$U$2:$U$17,0,0))*(INDEX('[1]Headcount Phasing'!$B$3:$M$18,MATCH(B10,'[1]Headcount Phasing'!$A$3:$A$18,0),MATCH($F$2,'[1]Headcount Phasing'!$B$2:$M$2,0))) -> 458050.88 | G10: =(_xlfn.XLOOKUP(B10,'[1]Annual Employer Cost per Grade'!$C$2:$C$17,'[1]Annual Employer Cost per Grade'!$U$2:$U$17,0,0))*(INDEX('[1]Headcount Phasing'!$B$3:$M$18,MATCH(B10,'[1]Headcount Phasing'!$A$3:$A$18,0),MATCH($G$2,'[1]Headcount Phasing'!$B$2:$M$2,0))) -> 458050.88 | H10: =(_xlfn.XLOOKUP(B10,'[1]Annual Employer Cost per Grade'!$C$2:$C$17,'[1]Annual Employer Cost per Grade'!$U$2:$U$17,0,0))*(INDEX('[1]Headcount Phasing'!$B$3:$M$18,MATCH(B10,'[1]Headcount Phasing'!$A$3:$A$18,0),MATCH($H$2,'[1]Headcount Phasing'!$B$2:$M$2,0))) -> 458050.88 | I10: =(_xlfn.XLOOKUP(B10,'[1]Annual Employer Cost per Grade'!$C$2:$C$17,'[1]Annual Employer Cost per Grade'!$U$2:$U$17,0,0))*(INDEX('[1]Headcount Phasing'!$B$3:$M$18,MATCH(B10,'[1]Headcount Phasing'!$A$3:$A$18,0),MATCH($I$2,'[1]Headcount Phasing'!$B$2:$M$2,0))) -> 458050.88 | J10: =(_xlfn.XLOOKUP(B10,'[1]Annual Employer Cost per Grade'!$C$2:$C$17,'[1]Annual Employer Cost per Grade'!$U$2:$U$17,0,0))*(INDEX('[1]Headcount Phasing'!$B$3:$M$18,MATCH(B10,'[1]Headcount Phasing'!$A$3:$A$18,0),MATCH($J$2,'[1]Headcount Phasing'!$B$2:$M$2,0))) -> 458050.88 | K10: =(_xlfn.XLOOKUP(B10,'[1]Annual Employer Cost per Grade'!$C$2:$C$17,'[1]Annual Employer Cost per Grade'!$U$2:$U$17,0,0))*(INDEX('[1]Headcount Phasing'!$B$3:$M$18,MATCH(B10,'[1]Headcount Phasing'!$A$3:$A$18,0),MATCH($K$2,'[1]Headcount Phasing'!$B$2:$M$2,0))) -> 458050.88 | L10: =(_xlfn.XLOOKUP(B10,'[1]Annual Employer Cost per Grade'!$C$2:$C$17,'[1]Annual Employer Cost per Grade'!$U$2:$U$17,0,0))*(INDEX('[1]Headcount Phasing'!$B$3:$M$18,MATCH(B10,'[1]Headcount Phasing'!$A$3:$A$18,0),MATCH($L$2,'[1]Headcount Phasing'!$B$2:$M$2,0))) -> 458050.88 | M10: =(_xlfn.XLOOKUP(B10,'[1]Annual Employer Cost per Grade'!$C$2:$C$17,'[1]Annual Employer Cost per Grade'!$U$2:$U$17,0,0))*(INDEX('[1]Headcount Phasing'!$B$3:$M$18,MATCH(B10,'[1]Headcount Phasing'!$A$3:$A$18,0),MATCH($M$2,'[1]Headcount Phasing'!$B$2:$M$2,0))) -> 458050.88 | N10: =(_xlfn.XLOOKUP(B10,'[1]Annual Employer Cost per Grade'!$C$2:$C$17,'[1]Annual Employer Cost per Grade'!$U$2:$U$17,0,0))*(INDEX('[1]Headcount Phasing'!$B$3:$M$18,MATCH(B10,'[1]Headcount Phasing'!$A$3:$A$18,0),MATCH($N$2,'[1]Headcount Phasing'!$B$2:$M$2,0))) -> 458050.88 | O10: =SUM(C10:N10) -> 4122457.9
A11: =A10+1 -> 9 | B11: Admin & HR Associate | C11: =(_xlfn.XLOOKUP(B11,'[1]Annual Employer Cost per Grade'!$C$2:$C$17,'[1]Annual Employer Cost per Grade'!$U$2:$U$17,0,0))*(INDEX('[1]Headcount Phasing'!$B$3:$M$18,MATCH(B11,'[1]Headcount Phasing'!$A$3:$A$18,0),MATCH($C$2,'[1]Headcount Phasing'!$B$2:$M$2,0))) -> 0 | D11: =(_xlfn.XLOOKUP(B11,'[1]Annual Employer Cost per Grade'!$C$2:$C$17,'[1]Annual Employer Cost per Grade'!$U$2:$U$17,0,0))*(INDEX('[1]Headcount Phasing'!$B$3:$M$18,MATCH(B11,'[1]Headcount Phasing'!$A$3:$A$18,0),MATCH($D$2,'[1]Headcount Phasing'!$B$2:$M$2,0))) -> 0 | E11: =(_xlfn.XLOOKUP(B11,'[1]Annual Employer Cost per Grade'!$C$2:$C$17,'[1]Annual Employer Cost per Grade'!$U$2:$U$17,0,0))*(INDEX('[1]Headcount Phasing'!$B$3:$M$18,MATCH(B11,'[1]Headcount Phasing'!$A$3:$A$18,0),MATCH($E$2,'[1]Headcount Phasing'!$B$2:$M$2,0))) -> 0 | F11: =(_xlfn.XLOOKUP(B11,'[1]Annual Employer Cost per Grade'!$C$2:$C$17,'[1]Annual Employer Cost per Grade'!$U$2:$U$17,0,0))*(INDEX('[1]Headcount Phasing'!$B$3:$M$18,MATCH(B11,'[1]Headcount Phasing'!$A$3:$A$18,0),MATCH($F$2,'[1]Headcount Phasing'!$B$2:$M$2,0))) -> 458050.88 | G11: =(_xlfn.XLOOKUP(B11,'[1]Annual Employer Cost per Grade'!$C$2:$C$17,'[1]Annual Employer Cost per Grade'!$U$2:$U$17,0,0))*(INDEX('[1]Headcount Phasing'!$B$3:$M$18,MATCH(B11,'[1]Headcount Phasing'!$A$3:$A$18,0),MATCH($G$2,'[1]Headcount Phasing'!$B$2:$M$2,0))) -> 458050.88 | H11: =(_xlfn.XLOOKUP(B11,'[1]Annual Employer Cost per Grade'!$C$2:$C$17,'[1]Annual Employer Cost per Grade'!$U$2:$U$17,0,0))*(INDEX('[1]Headcount Phasing'!$B$3:$M$18,MATCH(B11,'[1]Headcount Phasing'!$A$3:$A$18,0),MATCH($H$2,'[1]Headcount Phasing'!$B$2:$M$2,0))) -> 458050.88 | I11: =(_xlfn.XLOOKUP(B11,'[1]Annual Employer Cost per Grade'!$C$2:$C$17,'[1]Annual Employer Cost per Grade'!$U$2:$U$17,0,0))*(INDEX('[1]Headcount Phasing'!$B$3:$M$18,MATCH(B11,'[1]Headcount Phasing'!$A$3:$A$18,0),MATCH($I$2,'[1]Headcount Phasing'!$B$2:$M$2,0))) -> 458050.88 | J11: =(_xlfn.XLOOKUP(B11,'[1]Annual Employer Cost per Grade'!$C$2:$C$17,'[1]Annual Employer Cost per Grade'!$U$2:$U$17,0,0))*(INDEX('[1]Headcount Phasing'!$B$3:$M$18,MATCH(B11,'[1]Headcount Phasing'!$A$3:$A$18,0),MATCH($J$2,'[1]Headcount Phasing'!$B$2:$M$2,0))) -> 458050.88 | K11: =(_xlfn.XLOOKUP(B11,'[1]Annual Employer Cost per Grade'!$C$2:$C$17,'[1]Annual Employer Cost per Grade'!$U$2:$U$17,0,0))*(INDEX('[1]Headcount Phasing'!$B$3:$M$18,MATCH(B11,'[1]Headcount Phasing'!$A$3:$A$18,0),MATCH($K$2,'[1]Headcount Phasing'!$B$2:$M$2,0))) -> 458050.88 | L11: =(_xlfn.XLOOKUP(B11,'[1]Annual Employer Cost per Grade'!$C$2:$C$17,'[1]Annual Employer Cost per Grade'!$U$2:$U$17,0,0))*(INDEX('[1]Headcount Phasing'!$B$3:$M$18,MATCH(B11,'[1]Headcount Phasing'!$A$3:$A$18,0),MATCH($L$2,'[1]Headcount Phasing'!$B$2:$M$2,0))) -> 458050.88 | M11: =(_xlfn.XLOOKUP(B11,'[1]Annual Employer Cost per Grade'!$C$2:$C$17,'[1]Annual Employer Cost per Grade'!$U$2:$U$17,0,0))*(INDEX('[1]Headcount Phasing'!$B$3:$M$18,MATCH(B11,'[1]Headcount Phasing'!$A$3:$A$18,0),MATCH($M$2,'[1]Headcount Phasing'!$B$2:$M$2,0))) -> 458050.88 | N11: =(_xlfn.XLOOKUP(B11,'[1]Annual Employer Cost per Grade'!$C$2:$C$17,'[1]Annual Employer Cost per Grade'!$U$2:$U$17,0,0))*(INDEX('[1]Headcount Phasing'!$B$3:$M$18,MATCH(B11,'[1]Headcount Phasing'!$A$3:$A$18,0),MATCH($N$2,'[1]Headcount Phasing'!$B$2:$M$2,0))) -> 458050.88 | O11: =SUM(C11:N11) -> 4122457.9
A12: =A11+1 -> 10 | B12: IT Support Associate (x2) | C12: =(_xlfn.XLOOKUP(B12,'[1]Annual Employer Cost per Grade'!$C$2:$C$17,'[1]Annual Employer Cost per Grade'!$U$2:$U$17,0,0))*(INDEX('[1]Headcount Phasing'!$B$3:$M$18,MATCH(B12,'[1]Headcount Phasing'!$A$3:$A$18,0),MATCH($C$2,'[1]Headcount Phasing'!$B$2:$M$2,0))) -> 0 | D12: =(_xlfn.XLOOKUP(B12,'[1]Annual Employer Cost per Grade'!$C$2:$C$17,'[1]Annual Employer Cost per Grade'!$U$2:$U$17,0,0))*(INDEX('[1]Headcount Phasing'!$B$3:$M$18,MATCH(B12,'[1]Headcount Phasing'!$A$3:$A$18,0),MATCH($D$2,'[1]Headcount Phasing'!$B$2:$M$2,0))) -> 0 | E12: =(_xlfn.XLOOKUP(B12,'[1]Annual Employer Cost per Grade'!$C$2:$C$17,'[1]Annual Employer Cost per Grade'!$U$2:$U$17,0,0))*(INDEX('[1]Headcount Phasing'!$B$3:$M$18,MATCH(B12,'[1]Headcount Phasing'!$A$3:$A$18,0),MATCH($E$2,'[1]Headcount Phasing'!$B$2:$M$2,0))) -> 0 | F12: =(_xlfn.XLOOKUP(B12,'[1]Annual Employer Cost per Grade'!$C$2:$C$17,'[1]Annual Employer Cost per Grade'!$U$2:$U$17,0,0))*(INDEX('[1]Headcount Phasing'!$B$3:$M$18,MATCH(B12,'[1]Headcount Phasing'!$A$3:$A$18,0),MATCH($F$2,'[1]Headcount Phasing'!$B$2:$M$2,0))) -> 916101.75 | G12: =(_xlfn.XLOOKUP(B12,'[1]Annual Employer Cost per Grade'!$C$2:$C$17,'[1]Annual Employer Cost per Grade'!$U$2:$U$17,0,0))*(INDEX('[1]Headcount Phasing'!$B$3:$M$18,MATCH(B12,'[1]Headcount Phasing'!$A$3:$A$18,0),MATCH($G$2,'[1]Headcount Phasing'!$B$2:$M$2,0))) -> 916101.75 | H12: =(_xlfn.XLOOKUP(B12,'[1]Annual Employer Cost per Grade'!$C$2:$C$17,'[1]Annual Employer Cost per Grade'!$U$2:$U$17,0,0))*(INDEX('[1]Headcount Phasing'!$B$3:$M$18,MATCH(B12,'[1]Headcount Phasing'!$A$3:$A$18,0),MATCH($H$2,'[1]Headcount Phasing'!$B$2:$M$2,0))) -> 916101.75 | I12: =(_xlfn.XLOOKUP(B12,'[1]Annual Employer Cost per Grade'!$C$2:$C$17,'[1]Annual Employer Cost per Grade'!$U$2:$U$17,0,0))*(INDEX('[1]Headcount Phasing'!$B$3:$M$18,MATCH(B12,'[1]Headcount Phasing'!$A$3:$A$18,0),MATCH($I$2,'[1]Headcount Phasing'!$B$2:$M$2,0))) -> 916101.75 | J12: =(_xlfn.XLOOKUP(B12,'[1]Annual Employer Cost per Grade'!$C$2:$C$17,'[1]Annual Employer Cost per Grade'!$U$2:$U$17,0,0))*(INDEX('[1]Headcount Phasing'!$B$3:$M$18,MATCH(B12,'[1]Headcount Phasing'!$A$3:$A$18,0),MATCH($J$2,'[1]Headcount Phasing'!$B$2:$M$2,0))) -> 916101.75 | K12: =(_xlfn.XLOOKUP(B12,'[1]Annual Employer Cost per Grade'!$C$2:$C$17,'[1]Annual Employer Cost per Grade'!$U$2:$U$17,0,0))*(INDEX('[1]Headcount Phasing'!$B$3:$M$18,MATCH(B12,'[1]Headcount Phasing'!$A$3:$A$18,0),MATCH($K$2,'[1]Headcount Phasing'!$B$2:$M$2,0))) -> 916101.75 | L12: =(_xlfn.XLOOKUP(B12,'[1]Annual Employer Cost per Grade'!$C$2:$C$17,'[1]Annual Employer Cost per Grade'!$U$2:$U$17,0,0))*(INDEX('[1]Headcount Phasing'!$B$3:$M$18,MATCH(B12,'[1]Headcount Phasing'!$A$3:$A$18,0),MATCH($L$2,'[1]Headcount Phasing'!$B$2:$M$2,0))) -> 916101.75 | M12: =(_xlfn.XLOOKUP(B12,'[1]Annual Employer Cost per Grade'!$C$2:$C$17,'[1]Annual Employer Cost per Grade'!$U$2:$U$17,0,0))*(INDEX('[1]Headcount Phasing'!$B$3:$M$18,MATCH(B12,'[1]Headcount Phasing'!$A$3:$A$18,0),MATCH($M$2,'[1]Headcount Phasing'!$B$2:$M$2,0))) -> 916101.75 | N12: =(_xlfn.XLOOKUP(B12,'[1]Annual Employer Cost per Grade'!$C$2:$C$17,'[1]Annual Employer Cost per Grade'!$U$2:$U$17,0,0))*(INDEX('[1]Headcount Phasing'!$B$3:$M$18,MATCH(B12,'[1]Headcount Phasing'!$A$3:$A$18,0),MATCH($N$2,'[1]Headcount Phasing'!$B$2:$M$2,0))) -> 916101.75 | O12: =SUM(C12:N12) -> 8244915.8
A13: =A12+1 -> 11 | B13: Content & Digital Marketing Lead | C13: =(_xlfn.XLOOKUP(B13,'[1]Annual Employer Cost per Grade'!$C$2:$C$17,'[1]Annual Employer Cost per Grade'!$U$2:$U$17,0,0))*(INDEX('[1]Headcount Phasing'!$B$3:$M$18,MATCH(B13,'[1]Headcount Phasing'!$A$3:$A$18,0),MATCH($C$2,'[1]Headcount Phasing'!$B$2:$M$2,0))) -> 0 | D13: =(_xlfn.XLOOKUP(B13,'[1]Annual Employer Cost per Grade'!$C$2:$C$17,'[1]Annual Employer Cost per Grade'!$U$2:$U$17,0,0))*(INDEX('[1]Headcount Phasing'!$B$3:$M$18,MATCH(B13,'[1]Headcount Phasing'!$A$3:$A$18,0),MATCH($D$2,'[1]Headcount Phasing'!$B$2:$M$2,0))) -> 0 | E13: =(_xlfn.XLOOKUP(B13,'[1]Annual Employer Cost per Grade'!$C$2:$C$17,'[1]Annual Employer Cost per Grade'!$U$2:$U$17,0,0))*(INDEX('[1]Headcount Phasing'!$B$3:$M$18,MATCH(B13,'[1]Headcount Phasing'!$A$3:$A$18,0),MATCH($E$2,'[1]Headcount Phasing'!$B$2:$M$2,0))) -> 0 | F13: =(_xlfn.XLOOKUP(B13,'[1]Annual Employer Cost per Grade'!$C$2:$C$17,'[1]Annual Employer Cost per Grade'!$U$2:$U$17,0,0))*(INDEX('[1]Headcount Phasing'!$B$3:$M$18,MATCH(B13,'[1]Headcount Phasing'!$A$3:$A$18,0),MATCH($F$2,'[1]Headcount Phasing'!$B$2:$M$2,0))) -> 465550.88 | G13: =(_xlfn.XLOOKUP(B13,'[1]Annual Employer Cost per Grade'!$C$2:$C$17,'[1]Annual Employer Cost per Grade'!$U$2:$U$17,0,0))*(INDEX('[1]Headcount Phasing'!$B$3:$M$18,MATCH(B13,'[1]Headcount Phasing'!$A$3:$A$18,0),MATCH($G$2,'[1]Headcount Phasing'!$B$2:$M$2,0))) -> 465550.88 | H13: =(_xlfn.XLOOKUP(B13,'[1]Annual Employer Cost per Grade'!$C$2:$C$17,'[1]Annual Employer Cost per Grade'!$U$2:$U$17,0,0))*(INDEX('[1]Headcount Phasing'!$B$3:$M$18,MATCH(B13,'[1]Headcount Phasing'!$A$3:$A$18,0),MATCH($H$2,'[1]Headcount Phasing'!$B$2:$M$2,0))) -> 465550.88 | I13: =(_xlfn.XLOOKUP(B13,'[1]Annual Employer Cost per Grade'!$C$2:$C$17,'[1]Annual Employer Cost per Grade'!$U$2:$U$17,0,0))*(INDEX('[1]Headcount Phasing'!$B$3:$M$18,MATCH(B13,'[1]Headcount Phasing'!$A$3:$A$18,0),MATCH($I$2,'[1]Headcount Phasing'!$B$2:$M$2,0))) -> 465550.88 | J13: =(_xlfn.XLOOKUP(B13,'[1]Annual Employer Cost per Grade'!$C$2:$C$17,'[1]Annual Employer Cost per Grade'!$U$2:$U$17,0,0))*(INDEX('[1]Headcount Phasing'!$B$3:$M$18,MATCH(B13,'[1]Headcount Phasing'!$A$3:$A$18,0),MATCH($J$2,'[1]Headcount Phasing'!$B$2:$M$2,0))) -> 465550.88 | K13: =(_xlfn.XLOOKUP(B13,'[1]Annual Employer Cost per Grade'!$C$2:$C$17,'[1]Annual Employer Cost per Grade'!$U$2:$U$17,0,0))*(INDEX('[1]Headcount Phasing'!$B$3:$M$18,MATCH(B13,'[1]Headcount Phasing'!$A$3:$A$18,0),MATCH($K$2,'[1]Headcount Phasing'!$B$2:$M$2,0))) -> 465550.88 | L13: =(_xlfn.XLOOKUP(B13,'[1]Annual Employer Cost per Grade'!$C$2:$C$17,'[1]Annual Employer Cost per Grade'!$U$2:$U$17,0,0))*(INDEX('[1]Headcount Phasing'!$B$3:$M$18,MATCH(B13,'[1]Headcount Phasing'!$A$3:$A$18,0),MATCH($L$2,'[1]Headcount Phasing'!$B$2:$M$2,0))) -> 465550.88 | M13: =(_xlfn.XLOOKUP(B13,'[1]Annual Employer Cost per Grade'!$C$2:$C$17,'[1]Annual Employer Cost per Grade'!$U$2:$U$17,0,0))*(INDEX('[1]Headcount Phasing'!$B$3:$M$18,MATCH(B13,'[1]Headcount Phasing'!$A$3:$A$18,0),MATCH($M$2,'[1]Headcount Phasing'!$B$2:$M$2,0))) -> 465550.88 | N13: =(_xlfn.XLOOKUP(B13,'[1]Annual Employer Cost per Grade'!$C$2:$C$17,'[1]Annual Employer Cost per Grade'!$U$2:$U$17,0,0))*(INDEX('[1]Headcount Phasing'!$B$3:$M$18,MATCH(B13,'[1]Headcount Phasing'!$A$3:$A$18,0),MATCH($N$2,'[1]Headcount Phasing'!$B$2:$M$2,0))) -> 465550.88 | O13: =SUM(C13:N13) -> 4189957.9
A14: =A13+1 -> 12 | B14: Graphic & Multimedia Associate | C14: =(_xlfn.XLOOKUP(B14,'[1]Annual Employer Cost per Grade'!$C$2:$C$17,'[1]Annual Employer Cost per Grade'!$U$2:$U$17,0,0))*(INDEX('[1]Headcount Phasing'!$B$3:$M$18,MATCH(B14,'[1]Headcount Phasing'!$A$3:$A$18,0),MATCH($C$2,'[1]Headcount Phasing'!$B$2:$M$2,0))) -> 0 | D14: =(_xlfn.XLOOKUP(B14,'[1]Annual Employer Cost per Grade'!$C$2:$C$17,'[1]Annual Employer Cost per Grade'!$U$2:$U$17,0,0))*(INDEX('[1]Headcount Phasing'!$B$3:$M$18,MATCH(B14,'[1]Headcount Phasing'!$A$3:$A$18,0),MATCH($D$2,'[1]Headcount Phasing'!$B$2:$M$2,0))) -> 0 | E14: =(_xlfn.XLOOKUP(B14,'[1]Annual Employer Cost per Grade'!$C$2:$C$17,'[1]Annual Employer Cost per Grade'!$U$2:$U$17,0,0))*(INDEX('[1]Headcount Phasing'!$B$3:$M$18,MATCH(B14,'[1]Headcount Phasing'!$A$3:$A$18,0),MATCH($E$2,'[1]Headcount Phasing'!$B$2:$M$2,0))) -> 0 | F14: =(_xlfn.XLOOKUP(B14,'[1]Annual Employer Cost per Grade'!$C$2:$C$17,'[1]Annual Employer Cost per Grade'!$U$2:$U$17,0,0))*(INDEX('[1]Headcount Phasing'!$B$3:$M$18,MATCH(B14,'[1]Headcount Phasing'!$A$3:$A$18,0),MATCH($F$2,'[1]Headcount Phasing'!$B$2:$M$2,0))) -> 465550.88 | G14: =(_xlfn.XLOOKUP(B14,'[1]Annual Employer Cost per Grade'!$C$2:$C$17,'[1]Annual Employer Cost per Grade'!$U$2:$U$17,0,0))*(INDEX('[1]Headcount Phasing'!$B$3:$M$18,MATCH(B14,'[1]Headcount Phasing'!$A$3:$A$18,0),MATCH($G$2,'[1]Headcount Phasing'!$B$2:$M$2,0))) -> 465550.88 | H14: =(_xlfn.XLOOKUP(B14,'[1]Annual Employer Cost per Grade'!$C$2:$C$17,'[1]Annual Employer Cost per Grade'!$U$2:$U$17,0,0))*(INDEX('[1]Headcount Phasing'!$B$3:$M$18,MATCH(B14,'[1]Headcount Phasing'!$A$3:$A$18,0),MATCH($H$2,'[1]Headcount Phasing'!$B$2:$M$2,0))) -> 465550.88 | I14: =(_xlfn.XLOOKUP(B14,'[1]Annual Employer Cost per Grade'!$C$2:$C$17,'[1]Annual Employer Cost per Grade'!$U$2:$U$17,0,0))*(INDEX('[1]Headcount Phasing'!$B$3:$M$18,MATCH(B14,'[1]Headcount Phasing'!$A$3:$A$18,0),MATCH($I$2,'[1]Headcount Phasing'!$B$2:$M$2,0))) -> 465550.88 | J14: =(_xlfn.XLOOKUP(B14,'[1]Annual Employer Cost per Grade'!$C$2:$C$17,'[1]Annual Employer Cost per Grade'!$U$2:$U$17,0,0))*(INDEX('[1]Headcount Phasing'!$B$3:$M$18,MATCH(B14,'[1]Headcount Phasing'!$A$3:$A$18,0),MATCH($J$2,'[1]Headcount Phasing'!$B$2:$M$2,0))) -> 465550.88 | K14: =(_xlfn.XLOOKUP(B14,'[1]Annual Employer Cost per Grade'!$C$2:$C$17,'[1]Annual Employer Cost per Grade'!$U$2:$U$17,0,0))*(INDEX('[1]Headcount Phasing'!$B$3:$M$18,MATCH(B14,'[1]Headcount Phasing'!$A$3:$A$18,0),MATCH($K$2,'[1]Headcount Phasing'!$B$2:$M$2,0))) -> 465550.88 | L14: =(_xlfn.XLOOKUP(B14,'[1]Annual Employer Cost per Grade'!$C$2:$C$17,'[1]Annual Employer Cost per Grade'!$U$2:$U$17,0,0))*(INDEX('[1]Headcount Phasing'!$B$3:$M$18,MATCH(B14,'[1]Headcount Phasing'!$A$3:$A$18,0),MATCH($L$2,'[1]Headcount Phasing'!$B$2:$M$2,0))) -> 465550.88 | M14: =(_xlfn.XLOOKUP(B14,'[1]Annual Employer Cost per Grade'!$C$2:$C$17,'[1]Annual Employer Cost per Grade'!$U$2:$U$17,0,0))*(INDEX('[1]Headcount Phasing'!$B$3:$M$18,MATCH(B14,'[1]Headcount Phasing'!$A$3:$A$18,0),MATCH($M$2,'[1]Headcount Phasing'!$B$2:$M$2,0))) -> 465550.88 | N14: =(_xlfn.XLOOKUP(B14,'[1]Annual Employer Cost per Grade'!$C$2:$C$17,'[1]Annual Employer Cost per Grade'!$U$2:$U$17,0,0))*(INDEX('[1]Headcount Phasing'!$B$3:$M$18,MATCH(B14,'[1]Headcount Phasing'!$A$3:$A$18,0),MATCH($N$2,'[1]Headcount Phasing'!$B$2:$M$2,0))) -> 465550.88 | O14: =SUM(C14:N14) -> 4189957.9
A15: =A14+1 -> 13 | B15: Facility Technician (x3) | C15: =(_xlfn.XLOOKUP(B15,'[1]Annual Employer Cost per Grade'!$C$2:$C$17,'[1]Annual Employer Cost per Grade'!$U$2:$U$17,0,0))*(INDEX('[1]Headcount Phasing'!$B$3:$M$18,MATCH(B15,'[1]Headcount Phasing'!$A$3:$A$18,0),MATCH($C$2,'[1]Headcount Phasing'!$B$2:$M$2,0))) -> 0 | D15: =(_xlfn.XLOOKUP(B15,'[1]Annual Employer Cost per Grade'!$C$2:$C$17,'[1]Annual Employer Cost per Grade'!$U$2:$U$17,0,0))*(INDEX('[1]Headcount Phasing'!$B$3:$M$18,MATCH(B15,'[1]Headcount Phasing'!$A$3:$A$18,0),MATCH($D$2,'[1]Headcount Phasing'!$B$2:$M$2,0))) -> 0 | E15: =(_xlfn.XLOOKUP(B15,'[1]Annual Employer Cost per Grade'!$C$2:$C$17,'[1]Annual Employer Cost per Grade'!$U$2:$U$17,0,0))*(INDEX('[1]Headcount Phasing'!$B$3:$M$18,MATCH(B15,'[1]Headcount Phasing'!$A$3:$A$18,0),MATCH($E$2,'[1]Headcount Phasing'!$B$2:$M$2,0))) -> 0 | F15: =(_xlfn.XLOOKUP(B15,'[1]Annual Employer Cost per Grade'!$C$2:$C$17,'[1]Annual Employer Cost per Grade'!$U$2:$U$17,0,0))*(INDEX('[1]Headcount Phasing'!$B$3:$M$18,MATCH(B15,'[1]Headcount Phasing'!$A$3:$A$18,0),MATCH($F$2,'[1]Headcount Phasing'!$B$2:$M$2,0))) -> 231183.15 | G15: =(_xlfn.XLOOKUP(B15,'[1]Annual Employer Cost per Grade'!$C$2:$C$17,'[1]Annual Employer Cost per Grade'!$U$2:$U$17,0,0))*(INDEX('[1]Headcount Phasing'!$B$3:$M$18,MATCH(B15,'[1]Headcount Phasing'!$A$3:$A$18,0),MATCH($G$2,'[1]Headcount Phasing'!$B$2:$M$2,0))) -> 231183.15 | H15: =(_xlfn.XLOOKUP(B15,'[1]Annual Employer Cost per Grade'!$C$2:$C$17,'[1]Annual Employer Cost per Grade'!$U$2:$U$17,0,0))*(INDEX('[1]Headcount Phasing'!$B$3:$M$18,MATCH(B15,'[1]Headcount Phasing'!$A$3:$A$18,0),MATCH($H$2,'[1]Headcount Phasing'!$B$2:$M$2,0))) -> 231183.15 | I15: =(_xlfn.XLOOKUP(B15,'[1]Annual Employer Cost per Grade'!$C$2:$C$17,'[1]Annual Employer Cost per Grade'!$U$2:$U$17,0,0))*(INDEX('[1]Headcount Phasing'!$B$3:$M$18,MATCH(B15,'[1]Headcount Phasing'!$A$3:$A$18,0),MATCH($I$2,'[1]Headcount Phasing'!$B$2:$M$2,0))) -> 231183.15 | J15: =(_xlfn.XLOOKUP(B15,'[1]Annual Employer Cost per Grade'!$C$2:$C$17,'[1]Annual Employer Cost per Grade'!$U$2:$U$17,0,0))*(INDEX('[1]Headcount Phasing'!$B$3:$M$18,MATCH(B15,'[1]Headcount Phasing'!$A$3:$A$18,0),MATCH($J$2,'[1]Headcount Phasing'!$B$2:$M$2,0))) -> 231183.15 | K15: =(_xlfn.XLOOKUP(B15,'[1]Annual Employer Cost per Grade'!$C$2:$C$17,'[1]Annual Employer Cost per Grade'!$U$2:$U$17,0,0))*(INDEX('[1]Headcount Phasing'!$B$3:$M$18,MATCH(B15,'[1]Headcount Phasing'!$A$3:$A$18,0),MATCH($K$2,'[1]Headcount Phasing'!$B$2:$M$2,0))) -> 231183.15 | L15: =(_xlfn.XLOOKUP(B15,'[1]Annual Employer Cost per Grade'!$C$2:$C$17,'[1]Annual Employer Cost per Grade'!$U$2:$U$17,0,0))*(INDEX('[1]Headcount Phasing'!$B$3:$M$18,MATCH(B15,'[1]Headcount Phasing'!$A$3:$A$18,0),MATCH($L$2,'[1]Headcount Phasing'!$B$2:$M$2,0))) -> 231183.15 | M15: =(_xlfn.XLOOKUP(B15,'[1]Annual Employer Cost per Grade'!$C$2:$C$17,'[1]Annual Employer Cost per Grade'!$U$2:$U$17,0,0))*(INDEX('[1]Headcount Phasing'!$B$3:$M$18,MATCH(B15,'[1]Headcount Phasing'!$A$3:$A$18,0),MATCH($M$2,'[1]Headcount Phasing'!$B$2:$M$2,0))) -> 231183.15 | N15: =(_xlfn.XLOOKUP(B15,'[1]Annual Employer Cost per Grade'!$C$2:$C$17,'[1]Annual Employer Cost per Grade'!$U$2:$U$17,0,0))*(INDEX('[1]Headcount Phasing'!$B$3:$M$18,MATCH(B15,'[1]Headcount Phasing'!$A$3:$A$18,0),MATCH($N$2,'[1]Headcount Phasing'!$B$2:$M$2,0))) -> 231183.15 | O15: =SUM(C15:N15) -> 2080648.3
A16: =A15+1 -> 14 | B16: Driver | C16: =(_xlfn.XLOOKUP(B16,'[1]Annual Employer Cost per Grade'!$C$2:$C$17,'[1]Annual Employer Cost per Grade'!$U$2:$U$17,0,0))*(INDEX('[1]Headcount Phasing'!$B$3:$M$18,MATCH(B16,'[1]Headcount Phasing'!$A$3:$A$18,0),MATCH($C$2,'[1]Headcount Phasing'!$B$2:$M$2,0))) -> 0 | D16: =(_xlfn.XLOOKUP(B16,'[1]Annual Employer Cost per Grade'!$C$2:$C$17,'[1]Annual Employer Cost per Grade'!$U$2:$U$17,0,0))*(INDEX('[1]Headcount Phasing'!$B$3:$M$18,MATCH(B16,'[1]Headcount Phasing'!$A$3:$A$18,0),MATCH($D$2,'[1]Headcount Phasing'!$B$2:$M$2,0))) -> 0 | E16: =(_xlfn.XLOOKUP(B16,'[1]Annual Employer Cost per Grade'!$C$2:$C$17,'[1]Annual Employer Cost per Grade'!$U$2:$U$17,0,0))*(INDEX('[1]Headcount Phasing'!$B$3:$M$18,MATCH(B16,'[1]Headcount Phasing'!$A$3:$A$18,0),MATCH($E$2,'[1]Headcount Phasing'!$B$2:$M$2,0))) -> 231183.15 | F16: =(_xlfn.XLOOKUP(B16,'[1]Annual Employer Cost per Grade'!$C$2:$C$17,'[1]Annual Employer Cost per Grade'!$U$2:$U$17,0,0))*(INDEX('[1]Headcount Phasing'!$B$3:$M$18,MATCH(B16,'[1]Headcount Phasing'!$A$3:$A$18,0),MATCH($F$2,'[1]Headcount Phasing'!$B$2:$M$2,0))) -> 231183.15 | G16: =(_xlfn.XLOOKUP(B16,'[1]Annual Employer Cost per Grade'!$C$2:$C$17,'[1]Annual Employer Cost per Grade'!$U$2:$U$17,0,0))*(INDEX('[1]Headcount Phasing'!$B$3:$M$18,MATCH(B16,'[1]Headcount Phasing'!$A$3:$A$18,0),MATCH($G$2,'[1]Headcount Phasing'!$B$2:$M$2,0))) -> 462366.29 | H16: =(_xlfn.XLOOKUP(B16,'[1]Annual Employer Cost per Grade'!$C$2:$C$17,'[1]Annual Employer Cost per Grade'!$U$2:$U$17,0,0))*(INDEX('[1]Headcount Phasing'!$B$3:$M$18,MATCH(B16,'[1]Headcount Phasing'!$A$3:$A$18,0),MATCH($H$2,'[1]Headcount Phasing'!$B$2:$M$2,0))) -> 462366.29 | I16: =(_xlfn.XLOOKUP(B16,'[1]Annual Employer Cost per Grade'!$C$2:$C$17,'[1]Annual Employer Cost per Grade'!$U$2:$U$17,0,0))*(INDEX('[1]Headcount Phasing'!$B$3:$M$18,MATCH(B16,'[1]Headcount Phasing'!$A$3:$A$18,0),MATCH($I$2,'[1]Headcount Phasing'!$B$2:$M$2,0))) -> 462366.29 | J16: =(_xlfn.XLOOKUP(B16,'[1]Annual Employer Cost per Grade'!$C$2:$C$17,'[1]Annual Employer Cost per Grade'!$U$2:$U$17,0,0))*(INDEX('[1]Headcount Phasing'!$B$3:$M$18,MATCH(B16,'[1]Headcount Phasing'!$A$3:$A$18,0),MATCH($J$2,'[1]Headcount Phasing'!$B$2:$M$2,0))) -> 462366.29 | K16: =(_xlfn.XLOOKUP(B16,'[1]Annual Employer Cost per Grade'!$C$2:$C$17,'[1]Annual Employer Cost per Grade'!$U$2:$U$17,0,0))*(INDEX('[1]Headcount Phasing'!$B$3:$M$18,MATCH(B16,'[1]Headcount Phasing'!$A$3:$A$18,0),MATCH($K$2,'[1]Headcount Phasing'!$B$2:$M$2,0))) -> 462366.29 | L16: =(_xlfn.XLOOKUP(B16,'[1]Annual Employer Cost per Grade'!$C$2:$C$17,'[1]Annual Employer Cost per Grade'!$U$2:$U$17,0,0))*(INDEX('[1]Headcount Phasing'!$B$3:$M$18,MATCH(B16,'[1]Headcount Phasing'!$A$3:$A$18,0),MATCH($L$2,'[1]Headcount Phasing'!$B$2:$M$2,0))) -> 462366.29 | M16: =(_xlfn.XLOOKUP(B16,'[1]Annual Employer Cost per Grade'!$C$2:$C$17,'[1]Annual Employer Cost per Grade'!$U$2:$U$17,0,0))*(INDEX('[1]Headcount Phasing'!$B$3:$M$18,MATCH(B16,'[1]Headcount Phasing'!$A$3:$A$18,0),MATCH($M$2,'[1]Headcount Phasing'!$B$2:$M$2,0))) -> 462366.29 | N16: =(_xlfn.XLOOKUP(B16,'[1]Annual Employer Cost per Grade'!$C$2:$C$17,'[1]Annual Employer Cost per Grade'!$U$2:$U$17,0,0))*(INDEX('[1]Headcount Phasing'!$B$3:$M$18,MATCH(B16,'[1]Headcount Phasing'!$A$3:$A$18,0),MATCH($N$2,'[1]Headcount Phasing'!$B$2:$M$2,0))) -> 462366.29 | O16: =SUM(C16:N16) -> 4161296.6
A17: =A16+1 -> 15 | B17: NYSC Intern (x3) | C17: =(_xlfn.XLOOKUP(B17,'[1]Annual Employer Cost per Grade'!$C$2:$C$17,'[1]Annual Employer Cost per Grade'!$U$2:$U$17,0,0))*(INDEX('[1]Headcount Phasing'!$B$3:$M$18,MATCH(B17,'[1]Headcount Phasing'!$A$3:$A$18,0),MATCH($C$2,'[1]Headcount Phasing'!$B$2:$M$2,0))) -> 0 | D17: =(_xlfn.XLOOKUP(B17,'[1]Annual Employer Cost per Grade'!$C$2:$C$17,'[1]Annual Employer Cost per Grade'!$U$2:$U$17,0,0))*(INDEX('[1]Headcount Phasing'!$B$3:$M$18,MATCH(B17,'[1]Headcount Phasing'!$A$3:$A$18,0),MATCH($D$2,'[1]Headcount Phasing'!$B$2:$M$2,0))) -> 0 | E17: =(_xlfn.XLOOKUP(B17,'[1]Annual Employer Cost per Grade'!$C$2:$C$17,'[1]Annual Employer Cost per Grade'!$U$2:$U$17,0,0))*(INDEX('[1]Headcount Phasing'!$B$3:$M$18,MATCH(B17,'[1]Headcount Phasing'!$A$3:$A$18,0),MATCH($E$2,'[1]Headcount Phasing'!$B$2:$M$2,0))) -> 0 | F17: =(_xlfn.XLOOKUP(B17,'[1]Annual Employer Cost per Grade'!$C$2:$C$17,'[1]Annual Employer Cost per Grade'!$U$2:$U$17,0,0))*(INDEX('[1]Headcount Phasing'!$B$3:$M$18,MATCH(B17,'[1]Headcount Phasing'!$A$3:$A$18,0),MATCH($F$2,'[1]Headcount Phasing'!$B$2:$M$2,0))) -> 0 | G17: =(_xlfn.XLOOKUP(B17,'[1]Annual Employer Cost per Grade'!$C$2:$C$17,'[1]Annual Employer Cost per Grade'!$U$2:$U$17,0,0))*(INDEX('[1]Headcount Phasing'!$B$3:$M$18,MATCH(B17,'[1]Headcount Phasing'!$A$3:$A$18,0),MATCH($G$2,'[1]Headcount Phasing'!$B$2:$M$2,0))) -> 199189.62 | H17: =(_xlfn.XLOOKUP(B17,'[1]Annual Employer Cost per Grade'!$C$2:$C$17,'[1]Annual Employer Cost per Grade'!$U$2:$U$17,0,0))*(INDEX('[1]Headcount Phasing'!$B$3:$M$18,MATCH(B17,'[1]Headcount Phasing'!$A$3:$A$18,0),MATCH($H$2,'[1]Headcount Phasing'!$B$2:$M$2,0))) -> 199189.62 | I17: =(_xlfn.XLOOKUP(B17,'[1]Annual Employer Cost per Grade'!$C$2:$C$17,'[1]Annual Employer Cost per Grade'!$U$2:$U$17,0,0))*(INDEX('[1]Headcount Phasing'!$B$3:$M$18,MATCH(B17,'[1]Headcount Phasing'!$A$3:$A$18,0),MATCH($I$2,'[1]Headcount Phasing'!$B$2:$M$2,0))) -> 199189.62 | J17: =(_xlfn.XLOOKUP(B17,'[1]Annual Employer Cost per Grade'!$C$2:$C$17,'[1]Annual Employer Cost per Grade'!$U$2:$U$17,0,0))*(INDEX('[1]Headcount Phasing'!$B$3:$M$18,MATCH(B17,'[1]Headcount Phasing'!$A$3:$A$18,0),MATCH($J$2,'[1]Headcount Phasing'!$B$2:$M$2,0))) -> 199189.62 | K17: =(_xlfn.XLOOKUP(B17,'[1]Annual Employer Cost per Grade'!$C$2:$C$17,'[1]Annual Employer Cost per Grade'!$U$2:$U$17,0,0))*(INDEX('[1]Headcount Phasing'!$B$3:$M$18,MATCH(B17,'[1]Headcount Phasing'!$A$3:$A$18,0),MATCH($K$2,'[1]Headcount Phasing'!$B$2:$M$2,0))) -> 199189.62 | L17: =(_xlfn.XLOOKUP(B17,'[1]Annual Employer Cost per Grade'!$C$2:$C$17,'[1]Annual Employer Cost per Grade'!$U$2:$U$17,0,0))*(INDEX('[1]Headcount Phasing'!$B$3:$M$18,MATCH(B17,'[1]Headcount Phasing'!$A$3:$A$18,0),MATCH($L$2,'[1]Headcount Phasing'!$B$2:$M$2,0))) -> 199189.62 | M17: =(_xlfn.XLOOKUP(B17,'[1]Annual Employer Cost per Grade'!$C$2:$C$17,'[1]Annual Employer Cost per Grade'!$U$2:$U$17,0,0))*(INDEX('[1]Headcount Phasing'!$B$3:$M$18,MATCH(B17,'[1]Headcount Phasing'!$A$3:$A$18,0),MATCH($M$2,'[1]Headcount Phasing'!$B$2:$M$2,0))) -> 199189.62 | N17: =(_xlfn.XLOOKUP(B17,'[1]Annual Employer Cost per Grade'!$C$2:$C$17,'[1]Annual Employer Cost per Grade'!$U$2:$U$17,0,0))*(INDEX('[1]Headcount Phasing'!$B$3:$M$18,MATCH(B17,'[1]Headcount Phasing'!$A$3:$A$18,0),MATCH($N$2,'[1]Headcount Phasing'!$B$2:$M$2,0))) -> 199189.62 | O17: =SUM(C17:N17) -> 1593517
